Workbook

Sheet FCIc ESTIMACIONES RESUMEN
B2: PREMISAS DEL MODELO | G2: 2026 | H2: 2027 | I2: 2028 | J2: 2029 | K2: 2030
B3: PLAZO (meses) | C3: TASA ANUAL | D3: DISTRIBUCIÓN | F3: VENTA (CAPTACIÓN) | G3: 3000000 | H3: 5000000 | I3: 5000000 | J3: 7000000 | K3: 10000000
B4: 1 | C4: 0.105 | D4: 0.1 | F4: Ingresos del año anterior | G4: 0 | H4: =G47 -> 304478.62 | I4: =H47 -> 897185.65 | J4: =I47 -> 1484065.2 | K4: =J47 -> 2382270.7
B5: 2 | C5: 0.115 | D5: 0.25 | F5: STOCK DE CAPITAL | G5: =G3 -> 3000000 | H5: =H3+G5+H4 -> 8304478.6 | I5: =I3+H5+I4 -> 14201664 | J5: =J3+I5+J4 -> 22685729 | K5: =K3+J5+K4 -> 35068000 | L5: Esto genera interés todo el año
B6: 3 | C6: 0.125 | D6: 0.4 | F6: =CONCATENATE("CREDITOS (",C17," USD)") -> CREDITOS (30000 USD) | G6: =G3/$C$17 -> 100 | H6: =H3/$C$17 -> 166.66667 | I6: =I3/$C$17 -> 166.66667 | J6: =J3/$C$17 -> 233.33333 | K6: =K3/$C$17 -> 333.33333
B7: 4 | C7: 0.135 | D7: 0.15 | F7: Capital Liberado por Amortización | G7: =G5*$C$12*$C$16 -> 931034.48 | H7: =H5*$C$12*$C$16 -> 2577252 | I7: =I5*$C$12*$C$16 -> 4407413 | J7: =J5*$C$12*$C$16 -> 7040398.8 | K7: =K5*$C$12*$C$16 -> 10883172 | L7: Esto genera Upfront fee y mantiene duration
B8: 5 | C8: 0.145 | D8: 0.1 | F8: Nuevos CREDITOS POR AMORTIZACIÓN | G8: =G7/$C$17 -> 31.034483 | H8: =H7/$C$17 -> 85.908399 | I8: =I7/$C$17 -> 146.91377 | J8: =J7/$C$17 -> 234.67996 | K8: =K7/$C$17 -> 362.77241
B9: WAL | C9: =(B4*D4)+(B5*D5)+(B6*D6)+(B7*D7)+(B8*D8) -> 2.9
B10: TASA MEDIA Pond | C10: =(C4*D4)+(C5*D5)+(C6*D6)+(C7*D7)+(C8*D8) -> 0.124 | F10: =CONCATENATE("OPERACIONES (",C17," USD)") -> OPERACIONES (30000 USD) | G10: =G6+G8 -> 131.03448 | H10: =H6+H8 -> 252.57507 | I10: =I6+I8 -> 313.58043 | J10: =J6+J8 -> 468.01329 | K10: =K6+K8 -> 696.10575 | L10: Total créditos otorgados
B11: TASA STOCK CAP | C11: =C10*D18 -> 0.11625
B12: ROTACIÓN ANUAL | C12: =1/C9 -> 0.34482759 | F12: UPFRONT FEE | G12: =((G$3+G$7+G4)/(1+$C$13))*$C$13 -> 181478.51 | H12: =((H$3+H$7+H4)/(1+$C$13))*$C$13 -> 363864.71 | I12: =((I$3+I$7+I4)/(1+$C$13))*$C$13 -> 475717.83 | J12: =((J$3+J$7+J4)/(1+$C$13))*$C$13 -> 716695.97 | K12: =((K$3+K$7+K4)/(1+$C$13))*$C$13 -> 1074062.8 | L12: =CONCATENATE(C14*100,"% sobre el volumen total otorgado.") -> 4% sobre el volumen total otorgado.
B13: UPFRONT FEE BTO | C13: =D13+C14 -> 0.0484 | D13: =C14*0.21 -> 0.0084 | F13: INTERES GANADO | G13: =$C$10*G5 -> 372000 | H13: =$C$10*H5 -> 1029755.3 | I13: =$C$10*I5 -> 1761006.4 | J13: =$C$10*J5 -> 2813030.5 | K13: =$C$10*K5 -> 4348432
B14: UPFRONT FEE NETO | C14: 0.04
F15: OTROS INGRESOS (TBD)
B16: Rotación imperfecta: | C16: 0.9 | F16: INGRESOS | G16: =G12+G13 -> 553478.51 | H16: =H12+H13 -> 1393620.1 | I16: =I12+I13 -> 2236724.2 | J16: =J12+J13 -> 3529726.4 | K16: =K12+K13 -> 5422494.8
B17: Ticket Prom. Est | C17: 30000 | G17: =G16/G5 -> 0.18449284 | H17: =H16/H5 -> 0.16781548 | I17: =I16/I5 -> 0.15749733 | J17: =J16/J5 -> 0.15559237 | K17: =K16/K5 -> 0.154628
B18: TTM Originación | C18: 1.5 | D18: =(12-(C18/2))/12 -> 0.9375 | L18: Ver si aplican estos impuestos en FCI cerrado
E19: 0 | F19: IIBB | G19: =$E19*G13 -> 0 | H19: =$E19*H13 -> 0 | I19: =$E19*I13 -> 0 | J19: =$E19*J13 -> 0 | K19: =$E19*K13 -> 0 | L19: https://www.argentina.gob.ar/sites/default/files/pdf_cafci.pdf
E20: 0.21 | F20: IVA | G20: =((G$3+G$7)/(1+$D$13))*$D$13 -> 32745.626 | H20: =((H$3+H$7)/(1+$D$13))*$D$13 -> 63118.719 | I20: =((I$3+I$7)/(1+$D$13))*$D$13 -> 78364.012 | J20: =((J$3+J$7)/(1+$D$13))*$D$13 -> 116956.91 | K20: =((K$3+K$7)/(1+$D$13))*$D$13 -> 173957.41 | L20: Le descuento el IVA del upfront y en principio para vivienda única no aplicaría y si aplica se trasladaría al tomador del crédito
E21: 0.01 | F21: Impuesto a Sellos | G21: =$E21*(G$3+G$7) -> 39310.345 | H21: =$E21*(H$3+H$7) -> 75772.52 | I21: =$E21*(I$3+I$7) -> 94074.13 | J21: =$E21*(J$3+J$7) -> 140403.99 | K21: =$E21*(K$3+K$7) -> 208831.72 | L21: Caba 0, ver resto | M21: https://www.ambito.com/real-estate/comprar-vivienda-caba-costara-menos-baja-del-impuesto-los-sellos-2026-que-cambia-y-quien-beneficia-n6224787
E22: 0 | F22: Imp. Ley 25413 | G22: =$E22*(G$3+G$7) -> 0 | H22: =$E$22*(H3+H7) -> 0 | I22: =$E$22*(I3+I7) -> 0 | J22: =$E$22*(J3+J7) -> 0 | K22: =$E$22*(K3+K7) -> 0 | L22: Hay que ver cómo eficientizar en este punto. hay opciones.
E24: 0.054 | F24: TOPE OPER | G24: =$E24*G$26 -> 176943.92 | H24: =$E24*H26 -> 486069.59 | I24: =$E24*I26 -> 827281.42 | J24: =$E24*J26 -> 1320332 | K24: =$E24*K26 -> 2040079.4
F25: FCIcerrado
D26: TOPE: 5.4% | F26: PN | G26: =G5+((G12+G13)/2) -> 3276739.3 | H26: =H5+((H12+H13)/2) -> 9001288.6 | I26: =I5+((I12+I13)/2) -> 15320026 | J26: =J5+((J12+J13)/2) -> 24450593 | K26: =K5+((K12+K13)/2) -> 37779248 | L26: PN calculado sin distribución de capital no intereses a los inversores
E27: 0.012 | F27: Honorarios Sociedad Gerente | G27: =(G$26)*$E27 -> 39320.871 | H27: =(H$26)*$E27 -> 108015.46 | I27: =(I$26)*$E27 -> 183840.32 | J27: =(J$26)*$E27 -> 293407.11 | K27: =(K$26)*$E27 -> 453350.97
E28: 0.0015 | F28: Honorarios Sociedad Depositaria | G28: =IF((G$26)*$E28<6000,6000,G$26*$E28) -> 6000 | H28: =IF((H$26)*$E28<6000,6000,(H$26)*$E28) -> 13501.933 | I28: =IF((I$26)*$E28<6000,6000,(I$26)*$E28) -> 22980.04 | J28: =IF((J$26)*$E28<6000,6000,(J$26)*$E28) -> 36675.889 | K28: =IF((K$26)*$E28<6000,6000,(K$26)*$E28) -> 56668.871
E29: 0.02 | F29: Honorarios Asesor de Inversión | G29: =(G$26)*$E29 -> 65534.785 | H29: =(H$26)*$E29 -> 180025.77 | I29: =(I$26)*$E29 -> 306400.53 | J29: =(J$26)*$E29 -> 489011.85 | K29: =(K$26)*$E29 -> 755584.95
F30: Mázimo de gastos a abosrver por FCCI | G30: =G24-G29-G28-G27 -> 66088.264 | H30: =H24-H29-H28-H27 -> 184526.42 | I30: =I24-I29-I28-I27 -> 314060.54 | J30: =J24-J29-J28-J27 -> 501237.15 | K30: =K24-K29-K28-K27 -> 774474.57
E31: 0.054 | F31: MAX GASTO POR Reglamento | G31: =$E31*G$26 -> 176943.92 | H31: =$E31*H$26 -> 486069.59 | I31: =$E31*I$26 -> 827281.42 | J31: =$E31*J$26 -> 1320332 | K31: =$E31*K$26 -> 2040079.4 | L31: Este tope es el que pusieron en lendar y alaria en base a los máximos
G32: 0 | H32: 0 | I32: 0 | J32: 0 | K32: 0
E34: Estimaciones | F34: Auditoría externa | G34: 12000 | H34: 12000 | I34: 12000 | J34: 12000 | K34: 12000 | L34: Los costos son estimados.
F35: Asesoría legal | G35: 12000 | H35: 12000 | I35: 15000 | J35: 15000 | K35: 15000
F36: SET UP ABOGADOS | G36: 20000 | H36: 0 | I36: 0 | J36: 0 | K36: 0
F37: Asesoría contable / impositiva | G37: 12000 | H37: 12000 | I37: 12000 | J37: 12000 | K37: 12000
F38: Valuadores independientes | G38: 6000 | H38: 6000 | I38: 8000 | J38: 12000 | K38: 12000
F39: Gastos bancarios operativos | G39: 6000 | H39: 8000 | I39: 12000 | J39: 12000 | K39: 12000
F40: Custodia documental de créditos | G40: 6000 | H40: 6000 | I40: 8000 | J40: 8000 | K40: 8000
G41: =SUM(G34:G40) -> 74000 | H41: =SUM(H34:H40) -> 56000 | I41: =SUM(I34:I40) -> 67000 | J41: =SUM(J34:J40) -> 71000 | K41: =SUM(K34:K40) -> 71000
F43: TOTAL INGRESOS | G43: =G16 -> 553478.51 | H43: =H16 -> 1393620.1 | I43: =I16 -> 2236724.2 | J43: =J16 -> 3529726.4 | K43: =K16 -> 5422494.8
F44: TOTAL COSTOS | G44: =IF(G50<0,G31,G41+G27+G28+G29) -> 176943.92 | H44: =IF(H50<0,H31,H41+H27+H28+H29) -> 357543.17 | I44: =IF(I50<0,I31,I41+I27+I28+I29) -> 580220.88 | J44: =IF(J50<0,J31,J41+J27+J28+J29) -> 890094.85 | K44: =IF(K50<0,K31,K41+K27+K28+K29) -> 1336604.8
...

Sheet CUOTAS TOMADOR
A1: TU CASA +CERCA | CUOTAS POR TOMADOR — Amortización Francesa
B2: 12 | C2: 12 MESES — PLAZO | K2: Lendar | L2: Lendar: | N2: Período | O2: Saldo Inicial | P2: Interés | Q2: Capital | R2: Cuota | S2: Saldo Final | T2: Saldo Final
C3: Tomador | L3: 12 | M3: 0.095 | O3: 1 | P3: =H4 -> 31815 | Q3: =P3*(H$5/H$6) -> 278.38125 | R3: =S3-Q3 -> 2526.0666 | S3: =$H$7 -> 2804.4478 | T3: =P3-R3 -> 29288.933
C4: Pide | D4: ='FCIc ESTIMACIONES RESUMEN'!$C$17 -> 30000 | E4: Estos va a pagar el depto | G4: Capital | H4: =D5 -> 31815 | L4: 24 | M4: 0.105 | O4: 2 | P4: =T3 -> 29288.933 | Q4: =P4*(H$5/H$6) -> 256.27817 | R4: =S4-Q4 -> 2548.1696 | S4: =$H$7 -> 2804.4478 | T4: =P4-R4 -> 26740.764
C5: Toma | D5: =D4*(1+(E8*(1+E7))) -> 31815 | G5: Interés | H5: ='FCIc ESTIMACIONES RESUMEN'!C$4 -> 0.105 | L5: 36 | M5: 0.115 | O5: 3 | P5: =T4 -> 26740.764 | Q5: =P5*(H$5/H$6) -> 233.98168 | R5: =S5-Q5 -> 2570.4661 | S5: =$H$7 -> 2804.4478 | T5: =P5-R5 -> 24170.298
C6: Upfront | D6: =D5-D4 -> 1815 | G6: Plazo | H6: =B2 -> 12 | L6: 48 | M6: 0.125 | O6: 4 | P6: =T5 -> 24170.298 | Q6: =P6*(H$5/H$6) -> 211.4901 | R6: =S6-Q6 -> 2592.9577 | S6: =$H$7 -> 2804.4478 | T6: =P6-R6 -> 21577.34
C7: IVA | D7: =D6-D8 -> 315 | E7: 0.21 | G7: Cuota Neta | H7: =-PMT((H5/12),H6,H4) -> 2804.4478 | L7: 60 | M7: 0.135 | O7: 5 | P7: =T6 -> 21577.34 | Q7: =P7*(H$5/H$6) -> 188.80173 | R7: =S7-Q7 -> 2615.6461 | S7: =$H$7 -> 2804.4478 | T7: =P7-R7 -> 18961.694
C8: NETO | D8: =D6/(1+E7) -> 1500 | E8: 0.05 | O8: 6 | P8: =T7 -> 18961.694 | Q8: =P8*(H$5/H$6) -> 165.91482 | R8: =S8-Q8 -> 2638.533 | S8: =$H$7 -> 2804.4478 | T8: =P8-R8 -> 16323.161
G9: TOTAL | H9: =H7*B2 -> 33653.374 | O9: 7 | P9: =T8 -> 16323.161 | Q9: =P9*(H$5/H$6) -> 142.82766 | R9: =S9-Q9 -> 2661.6201 | S9: =$H$7 -> 2804.4478 | T9: =P9-R9 -> 13661.541
G10: TDirecta | H10: =H9/D4-1 -> 0.12177912 | O10: 8 | P10: =T9 -> 13661.541 | Q10: =P10*(H$5/H$6) -> 119.53848 | R10: =S10-Q10 -> 2684.9093 | S10: =$H$7 -> 2804.4478 | T10: =P10-R10 -> 10976.631
G11: TNA | H11: =((1+H10)^(12/B2))-1 -> 0.12177912 | O11: 9 | P11: =T10 -> 10976.631 | Q11: =P11*(H$5/H$6) -> 96.045525 | R11: =S11-Q11 -> 2708.4023 | S11: =$H$7 -> 2804.4478 | T11: =P11-R11 -> 8268.2292
O12: 10 | P12: =T11 -> 8268.2292 | Q12: =P12*(H$5/H$6) -> 72.347006 | R12: =S12-Q12 -> 2732.1008 | S12: =$H$7 -> 2804.4478 | T12: =P12-R12 -> 5536.1284
B13: 24 | C13: 24 MESES — PLAZO | O13: 11 | P13: =T12 -> 5536.1284 | Q13: =P13*(H$5/H$6) -> 48.441124 | R13: =S13-Q13 -> 2756.0067 | S13: =$H$7 -> 2804.4478 | T13: =P13-R13 -> 2780.1217
C14: Tomador | O14: 12 | P14: =T13 -> 2780.1217 | Q14: =P14*(H$5/H$6) -> 24.326065 | R14: =S14-Q14 -> 2780.1217 | S14: =$H$7 -> 2804.4478 | T14: =P14-R14 -> 0
C15: Pide | D15: ='FCIc ESTIMACIONES RESUMEN'!$C$17 -> 30000 | E15: Estos va a pagar el depto | G15: Capital | H15: =D16 -> 31815 | O15: TOTALES | Q15: =SUM(Q3:Q14) -> 1838.3736 | R15: =SUM(R3:R14) -> 31815 | S15: =SUM(S3:S14) -> 33653.374
C16: Toma | D16: =D15*(1+(E19*(1+E18))) -> 31815 | G16: Interés | H16: ='FCIc ESTIMACIONES RESUMEN'!C$5 -> 0.115
C17: Upfront | D17: =D16-D15 -> 1815 | G17: Plazo | H17: =B13 -> 24 | P17: Total Int Nom/30k | Q17: =Q15/D4 -> 0.06127912
C18: IVA | D18: =D17-D19 -> 315 | E18: 0.21 | G18: Cuota Neta | H18: =-PMT((H16/12),H17,H15) -> 1490.2246 | P18: Upfront Fee + IVA | Q18: =E8*1.21 -> 0.0605
C19: NETO | D19: =D17/(1+E18) -> 1500 | E19: 0.05 | P19: Tasa Directa | Q19: =Q18+Q17 -> 0.12177912
G20: TOTAL | H20: =H18*B13 -> 35765.391
G21: TDirecta | H21: =H20/D15-1 -> 0.1921797
G22: TNA | H22: =((1+H21)^(12/B13))-1 -> 0.091869821
B24: 36 | C24: 36 MESES — PLAZO
C25: Tomador
C26: Pide | D26: ='FCIc ESTIMACIONES RESUMEN'!$C$17 -> 30000 | E26: Estos va a pagar el depto | G26: Capital | H26: =D27 -> 31815
C27: Toma | D27: =D26*(1+(E30*(1+E29))) -> 31815 | G27: Interés | H27: ='FCIc ESTIMACIONES RESUMEN'!C$6 -> 0.125
C28: Upfront | D28: =D27-D26 -> 1815 | G28: Plazo | H28: =B24 -> 36
C29: IVA | D29: =D28-D30 -> 315 | E29: 0.21 | G29: Cuota Neta | H29: =-PMT((H27/12),H28,H26) -> 1064.3271
C30: NETO | D30: =D28/(1+E29) -> 1500 | E30: 0.05
G31: TOTAL | H31: =H29*B24 -> 38315.776
G32: TDirecta | H32: =H31/D26-1 -> 0.27719252
G33: TNA | H33: =((1+H32)^(12/B24))-1 -> 0.084972645
B35: 48 | C35: 48 MESES — PLAZO
C36: Tomador
C37: Pide | D37: ='FCIc ESTIMACIONES RESUMEN'!$C$17 -> 30000 | E37: Estos va a pagar el depto | G37: Capital | H37: =D38 -> 31815
C38: Toma | D38: =D37*(1+(E41*(1+E40))) -> 31815 | G38: Interés | H38: ='FCIc ESTIMACIONES RESUMEN'!C$7 -> 0.135
C39: Upfront | D39: =D38-D37 -> 1815 | G39: Plazo | H39: =B35 -> 48
C40: IVA | D40: =D39-D41 -> 315 | E40: 0.21 | G40: Cuota Neta | H40: =-PMT((H38/12),H39,H37) -> 861.43321
C41: NETO | D41: =D39/(1+E40) -> 1500 | E41: 0.05
G42: TOTAL | H42: =H40*B35 -> 41348.794
...
