Workbook

Sheet Mapa Oficinas
A1: Mapeo Oficinas CB → Zona → Localidad
A4: Referencia del PDF oficial Oficinas-CB-ARG-UY-PY.pdf
A6: Oficina | B6: Zona CB | C6: Localidad CB | D6: Operaciones en dataset
A7: Seniority | B7: CABA | C7: Barrio Parque
A8: Ser | B8: CABA | C8: Belgrano
A9: Space BA | B9: CABA | C9: Belgrano
A10: Desiderio | B10: CABA | C10: Caballito
A11: Goyena | B11: CABA | C11: Caballito
A12: Database | B12: CABA | C12: Núñez
A13: Haka | B13: CABA | C13: Núñez
A14: Horizon Group | B14: CABA | C14: Núñez
A15: Wings | B15: CABA | C15: Núñez
A16: Livello | B16: CABA | C16: Palermo
A17: Niceto | B17: CABA | C17: Palermo
A18: Notable | B18: CABA | C18: Palermo
... A46: Golden Team | B46: Zona Sur (GBA) | C46: La Plata

Sheet Operaciones Venta
A1: Fecha | B1: Ref # | C1: Unificador | D1: Publicación | E1: Estado | F1: Portal | G1: Precio Publicación | H1: Precio Cierre Total | I1: Moneda Cierre | J1: Moneda Publicación | K1: Dirección | L1: Ubicación | M1: Tipo Propiedad | N1: Lados | O1: Oficina | P1: Tipo Operación | Q1: Operación | R1: Zona CB | S1: Localidad CB
A2: 45658 | B2: CLA6158186 | C2: 1 | D2: ¡Terreno para desarrollar en pleno Florida! ¡701 mts construíbles! | E2: Realizado | F2: AR MercadoLibre | G2: 320000 | H2: 282000 | I2: Dólares | J2: Dólares | K2: Laprida al 2000 | L2: Argentina | G.B.A. Zona Norte | Vicente López | Florida | M2: Terreno | N2: 2 | O2: Concept | P2: Propia (Único Asesor) | Q2: Venta | R2: =VLOOKUP($O2,'Mapa Oficinas'!$A$7:$C$46,2,FALSE) -> Zona Norte (GBA) | S2: =VLOOKUP($O2,'Mapa Oficinas'!$A$7:$C$46,3,FALSE) -> Tigre
A3: 45658 | B3: ZP-ZP-M-43773962 | C3: 1 | D3: Hermosa casa con piscina en Barrio privado San Francisco - Tigre | E3: Realizado | F3: AR MercadoLibre | G3: 315000 | H3: 308000 | I3: Dólares | J3: Dólares | K3: Aristóbulo del Valle al 5100 | L3: Argentina | G.B.A. Zona Norte | Tigre | Countries/B.Cerrado (Tigre) | Villanueva | San Francisco | M3: Casa | N3: 2 | O3: Concept | P3: Propia (Único Asesor) | Q3: Venta | R3: =VLOOKUP($O3,'Mapa Oficinas'!$A$7:$C$46,2,FALSE) -> Zona Norte (GBA) | S3: =VLOOKUP($O3,'Mapa Oficinas'!$A$7:$C$46,3,FALSE) -> Tigre
A4: 45659 | B4: CHO5264010 | C4: 1 | D4: CASA EN VENTA, 3 AMBIENTES, SAN SEBASTIAN, AREA 12 | E4: Realizado | F4: AR ZonaProp | G4: 125000 | H4: 115000 | I4: Dólares | J4: Dólares | K4: Hermosa Casa en San Sebastián, área 12 | L4: Argentina | G.B.A. Zona Norte | Pilar | Countries/B.Cerrado (Pilar) | San Sebastian | M4: Casa | N4: 2 | O4: Haka | P4: Propia (Único Asesor) | Q4: Venta | R4: =VLOOKUP($O4,'Mapa Oficinas'!$A$7:$C$46,2,FALSE) -> CABA | S4: =VLOOKUP($O4,'Mapa Oficinas'!$A$7:$C$46,3,FALSE) -> Núñez
A5: 45659 | B5: CAP6363861 | D5: Venta Departamento 3 Ambientes en Complejo Al Río c/ cochera - baulera - balcón | E5: Realizado | F5: AR ZonaProp | G5: 420000 | H5: 405000 | I5: Dólares | J5: Dólares | K5: Juan Carlos Cruz 100 | L5: Argentina | G.B.A. Zona Norte | Vicente López | Libertador al Río | M5: Departamento | N5: 1 | O5: Seniority Plus | P5: Compartida Fuera de la Red Búsqueda | Q5: Venta | R5: =VLOOKUP($O5,'Mapa Oficinas'!$A$7:$C$46,2,FALSE) -> CABA | S5: =VLOOKUP($O5,'Mapa Oficinas'!$A$7:$C$46,3,FALSE) -> Palermo
A6: 45659 | B6: OP 85 | D6: Gelly y Obes 2243 5 | E6: Realizado | F6: AR ZonaProp | G6: 900000 | H6: 900000 | I6: Dólares | J6: Dólares | K6: Gelly y Obes 2243 5 | L6: Argentina | Capital Federal | Recoleta | M6: Departamento | N6: 1 | O6: Seniority Plus | P6: Compartida Fuera de la Red Búsqueda | Q6: Venta | R6: =VLOOKUP($O6,'Mapa Oficinas'!$A$7:$C$46,2,FALSE) -> CABA | S6: =VLOOKUP($O6,'Mapa Oficinas'!$A$7:$C$46,3,FALSE) -> Palermo
A7: 45660 | B7: JLO5618192 | C7: 1 | D7: VENTA LOCAL LOMAS DE ZAMORA | E7: Realizado | F7: AR ZonaProp | G7: 49900 | H7: 42000 | I7: Dólares | J7: Dólares | K7: General Carlos María de Alvear al 600 | L7: Argentina | G.B.A. Zona Sur | Lomas De Zamora (Partido) | Lomas De Zamora | M7: Local Comercial | N7: 2 | O7: Lion Team Norte | P7: Propia (Único Asesor) | Q7: Venta | R7: =VLOOKUP($O7,'Mapa Oficinas'!$A$7:$C$46,2,FALSE) -> Zona Norte (GBA) | S7: =VLOOKUP($O7,'Mapa Oficinas'!$A$7:$C$46,3,FALSE) -> Vicente López
A8: 45660 | B8: CPH5611863 | C8: 1 | D8: PH reciclado Parque Chacabuco | E8: Realizado | F8: AR ZonaProp | G8: 120000 | H8: 110000 | I8: Dólares | J8: Dólares | K8: Av Cobo al 700 | L8: Argentina | Capital Federal | Parque Chacabuco | M8: PH | N8: 2 | O8: Lion Team | P8: Propia (Único Asesor) | Q8: Venta | R8: =VLOOKUP($O8,'Mapa Oficinas'!$A$7:$C$46,2,FALSE) -> CABA | S8: =VLOOKUP($O8,'Mapa Oficinas'!$A$7:$C$46,3,FALSE) -> Villa Urquiza
A9: 45660 | B9: CAP6333484 | C9: 1 | D9: VENTA DEPARTAMENTO 3 AMBIENTES con gran patio EN PALERMO | E9: Realizado | F9: AR ZonaProp | G9: 139000 | H9: 115000 | I9: Dólares | J9: Dólares | K9: ARAOZ 2400 | L9: Argentina | Capital Federal | Palermo | M9: Departamento | N9: 2 | O9: Seniority | P9: Propia (Único Asesor) | Q9: Venta | R9: =VLOOKUP($O9,'Mapa Oficinas'!$A$7:$C$46,2,FALSE) -> CABA | S9: =VLOOKUP($O9,'Mapa Oficinas'!$A$7:$C$46,3,FALSE) -> Barrio Parque
A10: 45663 | B10: CAP6452531 | C10: 1 | D10: Departamento en Junin 530 | E10: Realizado | F10: Facebook | G10: 58000 | H10: 63000 | I10: Dólares | J10: Dólares | K10: Junin 530 | L10: Argentina | Salta | Capital | Salta | Zona Centro | M10: Departamento | N10: 2 | O10: Realty Group | P10: Propia (Único Asesor) | Q10: Venta | R10: =VLOOKUP($O10,'Mapa Oficinas'!$A$7:$C$46,2,FALSE) -> Interior - Salta | S10: =VLOOKUP($O10,'Mapa Oficinas'!$A$7:$C$46,3,FALSE) -> San Lorenzo Chico
A11: 45663 | B11: CCM54953 LO5934597 | D11: Local en Porto San Lorenzo chico | E11: Realizado | F11: Referido | G11: 167000 | H11: 68000 | I11: Dólares | J11: Dólares | K11: san Lorenzo chico | L11: Argentina | Salta | Capital | M11: Local Comercial | N11: 2 | O11: Realty Group | P11: Compartida en Oficina (Dos Asesores) | Q11: Venta | R11: =VLOOKUP($O11,'Mapa Oficinas'!$A$7:$C$46,2,FALSE) -> Interior - Salta | S11: =VLOOKUP($O11,'Mapa Oficinas'!$A$7:$C$46,3,FALSE) -> San Lorenzo Chico
A12: 45663 | C12: 1 | D12: VENTA Monoambiente 39,94m2 - UF 50, pozo, Paseo Retamas, Villa la Angostura, Villa la Angostura | E12: Realizado | F12: Conocido | G12: 71793 | H12: 71793 | I12: Dólares | J12: Dólares | K12: Retamas 200 | L12: Argentina | Neuquen | Villa La Angostura | Centro | M12: Departamento | N12: 2 | O12: Patagonia Lakes VLA | P12: Propia (Único Asesor) | Q12: Venta | R12: =VLOOKUP($O12,'Mapa Oficinas'!$A$7:$C$46,2,FALSE) -> Interior - Neuquén | S12: =VLOOKUP($O12,'Mapa Oficinas'!$A$7:$C$46,3,FALSE) -> Villa La Angostura
A13: 45663 | B13: CBU59337 AP6535062 | C13: 1 | D13: VENTA Monoambiente 43,72m2 - UF 51, pozo, Paseo Retamas, Villa la Angostura, Villa la Angostura | E13: Realizado | F13: Conocido | G13: 74784 | H13: 74184 | I13: Dólares | J13: Dólares | K13: Retamas al 300 | L13: Argentina | Neuquen | Villa La Angostura | Centro | M13: Departamento | N13: 2 | O13: Patagonia Lakes VLA | P13: Propia (Único Asesor) | Q13: Venta | R13: =VLOOKUP($O13,'Mapa Oficinas'!$A$7:$C$46,2,FALSE) -> Interior - Neuquén | S13: =VLOOKUP($O13,'Mapa Oficinas'!$A$7:$C$46,3,FALSE) -> Villa La Angostura
A14: 45663 | B14: CAP6454429 | C14: 1 | D14: VENTA Departamento 2 ambientes A estrenar Balcón al Frente Villa Urquiza | E14: Realizado | F14: AR ArgenProp | G14: 102000 | H14: 100250 | I14: Dólares | J14: Dólares | K14: Bauness al 1100 | L14: Argentina | Capital Federal | Villa Urquiza | M14: Departamento | N14: 2 | O14: Lion Team | P14: Propia (Único Asesor) | Q14: Venta | R14: =VLOOKUP($O14,'Mapa Oficinas'!$A$7:$C$46,2,FALSE) -> CABA | S14: =VLOOKUP($O14,'Mapa Oficinas'!$A$7:$C$46,3,FALSE) -> Villa Urquiza
A15: 45663 | B15: CBU49671 AP6414032 | C15: 1 | D15: Departamento Monoambiente divisible A Estrenar con Balcon Piso 1 - Villa Urquiza VENTA | E15: Realizado | F15: AR ArgenProp | G15: 90000 | H15: 100250 | I15: Dólares | J15: Dólares | K15: Bauness al 1100 | L15: Argentina | Capital Federal | Villa Urquiza | M15: Departamento | N15: 2 | O15: Lion Team | P15: Propia (Único Asesor) | Q15: Venta | R15: =VLOOKUP($O15,'Mapa Oficinas'!$A$7:$C$46,2,FALSE) -> CABA | S15: =VLOOKUP($O15,'Mapa Oficinas'!$A$7:$C$46,3,FALSE) -> Villa Urquiza
A16: 45663 | B16: CBU59337 AP6535088 | D16: VENTA Departamento céntrico 2 amb 59,64m2 UF 73 - en pozo, Paseo Retamas, El Cruce, Las Retamas 300, Villa la Angostura | E16: Realizado | F16: Repetido | G16: 104158 | H16: 104000 | I16: Dólares | J16: Dólares | K16: Retamas al 300 | L16: Argentina | Neuquen | Villa La Angostura | Centro | M16: Departamento | N16: 2 | O16: Patagonia Lakes VLA | P16: Compartida en Oficina (Dos Asesores) | Q16: Venta | R16: =VLOOKUP($O16,'Mapa Oficinas'!$A$7:$C$46,2,FALSE) -> Interior - Neuquén | S16: =VLOOKUP($O16,'Mapa Oficinas'!$A$7:$C$46,3,FALSE) -> Villa La Angostura
A17: 45663 | B17: CPH6635419 | D17: PH duplex | E17: Realizado | F17: Teléfono | G17: 114000 | H17: 114000 | I17: Dólares | J17: Dólares | K17: ph duplex 139 50 y139 50 y 52 52 | L17: Argentina | G.B.A. Zona Sur | La Plata | La Plata | M17: PH | N17: 1 | O17: Golden Team | P17: Compartida Fuera de la Red Búsqueda | Q17: Venta | R17: =VLOOKUP($O17,'Mapa Oficinas'!$A$7:$C$46,2,FALSE) -> Zona Sur (GBA) | S17: =VLOOKUP($O17,'Mapa Oficinas'!$A$7:$C$46,3,FALSE) -> La Plata
A18: 45663 | B18: 10257 | D18: Ecuador 1182 5A | E18: Realizado | F18: AR ZonaProp | G18: 0 | H18: 163000 | I18: Dólares | J18: Dólares | L18: Argentina | Capital Federal | Almagro | M18: Departamento | N18: 1 | O18: Seniority | P18: Compartida Fuera de la Red Búsqueda | Q18: Venta | R18: =VLOOKUP($O18,'Mapa Oficinas'!$A$7:$C$46,2,FALSE) -> CABA | S18: =VLOOKUP($O18,'Mapa Oficinas'!$A$7:$C$46,3,FALSE) -> Barrio Parque
A19: 45664 | B19: VCO60746 AP6653300 | C19: 1 | D19: Departamento 2 ambientes a estrenar con amenities | E19: Realizado | F19: AR ZonaProp | G19: 99900 | H19: 85000 | I19: Dólares | J19: Dólares | K19: Guiraldes 400 | L19: Argentina | G.B.A. Zona Norte | Tigre | Don Torcuato | Ibanez | M19: Departamento | N19: 2 | O19: Puerto Norte | P19: Propia (Único Asesor) | Q19: Venta | R19: =VLOOKUP($O19,'Mapa Oficinas'!$A$7:$C$46,2,FALSE) -> Zona Norte (GBA) | S19: =VLOOKUP($O19,'Mapa Oficinas'!$A$7:$C$46,3,FALSE) -> Nordelta
A20: 45664 | B20: GRANADEROS CABA | C20: 1 | D20: DPTO GRANADEROS | E20: Realizado | F20: AR ZonaProp | G20: 95000 | H20: 95000 | I20: Dólares | J20: Dólares | K20: GRANADERO 467 | L20: Argentina | Capital Federal | Flores | M20: Departamento | N20: 2 | O20: Puerto Norte | P20: Propia (Único Asesor) | Q20: Venta | R20: =VLOOKUP($O20,'Mapa Oficinas'!$A$7:$C$46,2,FALSE) -> Zona Norte (GBA) | S20: =VLOOKUP($O20,'Mapa Oficinas'!$A$7:$C$46,3,FALSE) -> Nordelta
A21: 45664 | B21: Bartolomé Hidalgo 3056 | C21: 1 | D21: Bartolomé Hidalgo 3056 | E21: Realizado | F21: AR MercadoLibre | G21: 218000 | H21: 218000 | I21: Dólares | J21: Dólares | K21: Bartolomé Hidalgo 3056 | L21: Argentina | Capital Federal | Capital Federal | M21: Casa | N21: 2 | O21: Lion Team | P21: Propia (Único Asesor) | Q21: Venta | R21: =VLOOKUP($O21,'Mapa Oficinas'!$A$7:$C$46,2,FALSE) -> CABA | S21: =VLOOKUP($O21,'Mapa Oficinas'!$A$7:$C$46,3,FALSE) -> Villa Urquiza
A22: 45665 | B22: TerrenoLomasdelCauquen | D22: Terreno Monte Moro N°541 | E22: Realizado | F22: Salón | G22: 0 | H22: 52500 | I22: Dólares | J22: Dólares | L22: Argentina | Rio Negro | Bariloche | San Carlos De Bariloche | M22: Terreno | N22: 1 | O22: Patagonia Lakes BRC | P22: (Interior) Compartida Fuera de la Red Búsqueda | Q22: Venta | R22: =VLOOKUP($O22,'Mapa Oficinas'!$A$7:$C$46,2,FALSE) -> Interior - Río Negro | S22: =VLOOKUP($O22,'Mapa Oficinas'!$A$7:$C$46,3,FALSE) -> Bariloche
A23: 45665 | B23: CAP6492529 | D23: venta - Departamento dos ambientes - villa urquiza - balcon - amenities | E23: Realizado | F23: AR ZonaProp | G23: 125000 | H23: 120000 | I23: Dólares | J23: Dólares | K23: Pedro Ignacio Rivera al 4700 | L23: Argentina | Capital Federal | Villa Urquiza | M23: Departamento | N23: 2 | O23: Lion Team | P23: Compartida en Oficina (Dos Asesores) | Q23: Venta | R23: =VLOOKUP($O23,'Mapa Oficinas'!$A$7:$C$46,2,FALSE) -> CABA | S23: =VLOOKUP($O23,'Mapa Oficinas'!$A$7:$C$46,3,FALSE) -> Villa Urquiza
A24: 45666 | B24: CHO6440273 | C24: 1 | D24: VENTA Casa 2 ambientes 60m² dos plantas Terreno 200m² B° Los Manzanos, San Martín de los Andes | E24: Realizado | F24: Teléfono | G24: 42000 | H24: 42000 | I24: Dólares | J24: Dólares | K24: Lote 3, mza E | L24: Argentina | Neuquen | Lacar | San Martin De Los Andes | Chacra 28 | M24: Casa | N24: 2 | O24: Patagonia Lakes SMA | P24: Propia (Único Asesor) | Q24: Venta | R24: =VLOOKUP($O24,'Mapa Oficinas'!$A$7:$C$46,2,FALSE) -> Interior - Neuquén | S24: =VLOOKUP($O24,'Mapa Oficinas'!$A$7:$C$46,3,FALSE) -> San Martín de los Andes
A25: 45666 | B25: CGL6038938 | C25: 1 | D25: Galpón en Sarandi | E25: Realizado | F25: AR ZonaProp | G25: 75000 | H25: 45000 | I25: Dólares | J25: Dólares | K25: Helguera al 2500 | L25: Argentina | G.B.A. Zona Sur | Avellaneda | Sarandi | N25: 2 | O25: Destino | P25: Propia (Único Asesor) | Q25: Venta | R25: =VLOOKUP($O25,'Mapa Oficinas'!$A$7:$C$46,2,FALSE) -> CABA | S25: =VLOOKUP($O25,'Mapa Oficinas'!$A$7:$C$46,3,FALSE) -> Recoleta
A26: 45666 | B26: CBU49671 AP6414022 | C26: 1 | D26: Departamento Monoambiente dividido A Estrenar Balcon frente Villa Urquiza VENTA | E26: Realizado | F26: AR MercadoLibre | G26: 79000 | H26: 80000 | I26: Dólares | J26: Dólares | K26: Bauness al 1100 | L26: Argentina | Capital Federal | Villa Urquiza | M26: Departamento | N26: 2 | O26: Lion Team | P26: Propia (Único Asesor) | Q26: Venta | R26: =VLOOKUP($O26,'Mapa Oficinas'!$A$7:$C$46,2,FALSE) -> CABA | S26: =VLOOKUP($O26,'Mapa Oficinas'!$A$7:$C$46,3,FALSE) -> Villa Urquiza
A27: 45666 | B27: CAP6674303 | D27: pujol 1095 7A | E27: Realizado | F27: AR ZonaProp | G27: 110000 | H27: 110000 | I27: Dólares | J27: Dólares | K27: Pujol 1095 7A | L27: Argentina | Capital Federal | Caballito | M27: Departamento | N27: 1 | O27: Notable | P27: Compartida Fuera de la Red Búsqueda | Q27: Venta | R27: =VLOOKUP($O27,'Mapa Oficinas'!$A$7:$C$46,2,FALSE) -> CABA | S27: =VLOOKUP($O27,'Mapa Oficinas'!$A$7:$C$46,3,FALSE) -> Palermo
A28: 45666 | D28: Departamento 2 ambientes de 58,97 m2? - UF 58, parte del Edificio Nº 2 más su unidad complementaria (cochera) N° 2, conforme croquis adjunto en el ANEXO III, ubicado en calle Las Retamas y Las Mutisias, que será parte del Fideicomiso Retamas, emprendimie | E28: Realizado | F28: Teléfono | G28: 118402 | H28: 118402 | I28: Dólares | J28: Dólares | K28: Retamas 200 | L28: Argentina | Neuquen | Villa La Angostura | Centro | M28: Departamento | N28: 2 | O28: Patagonia Lakes VLA | P28: Compartida en Oficina (Dos Asesores) | Q28: Venta | R28: =VLOOKUP($O28,'Mapa Oficinas'!$A$7:$C$46,2,FALSE) -> Interior - Neuquén | S28: =VLOOKUP($O28,'Mapa Oficinas'!$A$7:$C$46,3,FALSE) -> Villa La Angostura
A29: 45667 | B29: CAP6403040 | D29: DEPARTAMENTO en 1 y 57 LA PLATA | E29: Realizado | F29: Referido | G29: 45000 | H29: 40000 | I29: Dólares | J29: Dólares | K29: DEPARTAMENTO 1 dormitorio en 1 y 57 | L29: Argentina | G.B.A. Zona Sur | La Plata | La Plata | M29: Departamento | N29: 2 | O29: Golden Team | P29: Propia (Único Asesor) | Q29: Venta | R29: =VLOOKUP($O29,'Mapa Oficinas'!$A$7:$C$46,2,FALSE) -> Zona Sur (GBA) | S29: =VLOOKUP($O29,'Mapa Oficinas'!$A$7:$C$46,3,FALSE) -> La Plata
A30: 45667 | B30: CBU60695 AP6633713 | D30: Departamento en Venta en Lujan de Cuyo - Mendoza | E30: Realizado | F30: Conocido | G30: 45000 | H30: 45000 | I30: Dólares | J30: Dólares | K30: Azcuenaga s/n | L30: Argentina | Mendoza | Lujan De Cuyo | M30: Departamento | N30: 1 | O30: Cuyo Real | P30: (Interior) Compartida Fuera de la Red Captación Propia | Q30: Venta | R30: =VLOOKUP($O30,'Mapa Oficinas'!$A$7:$C$46,2,FALSE) -> Interior - Mendoza | S30: =VLOOKUP($O30,'Mapa Oficinas'!$A$7:$C$46,3,FALSE) -> Capital Mendoza
A31: 45667 | B31: CLA5824535 | D31: Oportunidad de inversión! Terreno en Tres Cerritos con hermosas vistas de la ciudad. | E31: Realizado | F31: Facebook | G31: 45000 | H31: 45000 | I31: Dólares | J31: Dólares | K31: Los Parrales al 800 | L31: Argentina | Salta | Capital | Salta | Bo.Tres Cerritos | M31: Terreno | N31: 2 | O31: Realty Group | P31: Propia (Único Asesor) | Q31: Venta | R31: =VLOOKUP($O31,'Mapa Oficinas'!$A$7:$C$46,2,FALSE) -> Interior - Salta | S31: =VLOOKUP($O31,'Mapa Oficinas'!$A$7:$C$46,3,FALSE) -> San Lorenzo Chico
A32: 45667 | B32: CHO6149910 | D32: Casa en Venta para reciclar - Tupungato - Mendoza | E32: Realizado | F32: AR ZonaProp | G32: 70000 | H32: 55000 | I32: Dólares | J32: Dólares | K32: Calle Irigoyen al 200 | L32: Argentina | Mendoza | Tupungato | San Jose De Tupungato | M32: Casa | N32: 2 | O32: Cuyo Real | P32: Propia (Único Asesor) | Q32: Venta | R32: =VLOOKUP($O32,'Mapa Oficinas'!$A$7:$C$46,2,FALSE) -> Interior - Mendoza | S32: =VLOOKUP($O32,'Mapa Oficinas'!$A$7:$C$46,3,FALSE) -> Capital Mendoza
A33: 45667 | D33: PARANA 3296 | E33: Realizado | F33: AR ZonaProp | G33: 88000 | H33: 88000 | I33: Dólares | J33: Dólares | K33: PARANA 3296 | L33: Argentina | G.B.A. Zona Norte | Vicente López | Olivos | M33: Casa | N33: 2 | O33: Lion Team Norte | P33: Propia (Único Asesor) | Q33: Venta | R33: =VLOOKUP($O33,'Mapa Oficinas'!$A$7:$C$46,2,FALSE) -> Zona Norte (GBA) | S33: =VLOOKUP($O33,'Mapa Oficinas'!$A$7:$C$46,3,FALSE) -> Vicente López
A34: 45667 | B34: CHO6571935 | D34: Casa en barrio Sto. Cabral- Santa Fe | E34: Realizado | F34: AR ZonaProp | G34: 115000 | H34: 105000 | I34: Dólares | J34: Dólares | K34: Pje Madeo al 4400 | L34: Argentina | Santa Fe | La Capital | Santa Fe | Sargento Cabral | M34: Casa | N34: 1 | O34: De la Veracruz | P34: (Interior) Compartida Fuera de la Red Captación Propia | Q34: Venta | R34: =VLOOKUP($O34,'Mapa Oficinas'!$A$7:$C$46,2,FALSE) -> Interior - Santa Fe | S34: =VLOOKUP($O34,'Mapa Oficinas'!$A$7:$C$46,3,FALSE) -> Capital Santa Fe
A35: 45667 | B35: Búsqueda | D35: Búsqueda | E35: Realizado | F35: AR ZonaProp | G35: 163000 | H35: 163000 | I35: Dólares | J35: Dólares | K35: Tinogasta 3128 5° "A" CABA | M35: Departamento | N35: 1 | O35: Ser | P35: Compartida Fuera de la Red Búsqueda | Q35: Venta | R35: =VLOOKUP($O35,'Mapa Oficinas'!$A$7:$C$46,2,FALSE) -> CABA | S35: =VLOOKUP($O35,'Mapa Oficinas'!$A$7:$C$46,3,FALSE) -> Belgrano
A36: 45667 | B36: CPH6286814 | D36: PH EN MARTINEZ CON COCHERA CUBIERTA JARDIN INTRADA INDIVIDUAL TIPO CHALET | E36: Realizado | F36: AR ZonaProp | G36: 175000 | H36: 165000 | I36: Dólares | J36: Dólares | K36: VELEZ SARSFIELD 800 | L36: Argentina | G.B.A. Zona Norte | San Isidro | Martinez | M36: PH | N36: 2 | O36: Lion Team Norte | P36: Propia (Único Asesor) | Q36: Venta | R36: =VLOOKUP($O36,'Mapa Oficinas'!$A$7:$C$46,2,FALSE) -> Zona Norte (GBA) | S36: =VLOOKUP($O36,'Mapa Oficinas'!$A$7:$C$46,3,FALSE) -> Vicente López
A37: 45667 | B37: CAP6092043 | D37: Departamento en Villa Santa Rita | E37: Realizado | F37: AR ZonaProp | G37: 179000 | H37: 170000 | I37: Dólares | J37: Dólares | K37: Camarones al 3100 | L37: Argentina | Capital Federal | Villa del Parque | M37: Departamento | N37: 2 | O37: Ser | P37: Propia (Único Asesor) | Q37: Venta | R37: =VLOOKUP($O37,'Mapa Oficinas'!$A$7:$C$46,2,FALSE) -> CABA | S37: =VLOOKUP($O37,'Mapa Oficinas'!$A$7:$C$46,3,FALSE) -> Belgrano
A38: 45667 | B38: CPH6260765 | D38: Duplex a Estrenar de 3 Dormitorios en Venta en Confluencia | E38: Realizado | F38: AR ZonaProp | G38: 170000 | H38: 170000 | I38: Dólares | J38: Dólares | K38: granaderos al 500 | L38: Argentina | Neuquen | Capital | Confluencia Urbana | M38: PH | N38: 2 | O38: Sensus | P38: Propia (Único Asesor) | Q38: Venta | R38: =VLOOKUP($O38,'Mapa Oficinas'!$A$7:$C$46,2,FALSE) -> Interior - Neuquén | S38: =VLOOKUP($O38,'Mapa Oficinas'!$A$7:$C$46,3,FALSE) -> Capital Neuquén
A39: 45667 | B39: CAP6280063 | D39: Venta 3 ambientes con patio propio reciclado mas cochera! | E39: Realizado | F39: AR ZonaProp | G39: 215000 | H39: 200000 | I39: Dólares | J39: Dólares | K39: Avenida Pueyrredon al 2100 | L39: Argentina | Capital Federal | Recoleta | M39: Departamento | N39: 2 | O39: Destino | P39: Propia (Único Asesor) | Q39: Venta | R39: =VLOOKUP($O39,'Mapa Oficinas'!$A$7:$C$46,2,FALSE) -> CABA | S39: =VLOOKUP($O39,'Mapa Oficinas'!$A$7:$C$46,3,FALSE) -> Recoleta
A40: 45669 | B40: VAP6500846 | D40: Departamento en venta !! OPORTUNIDAD | E40: Realizado | F40: AR ZonaProp | G40: 105000 | H40: 105000 | I40: Dólares | J40: Dólares | K40: Cramer 1660 al 1600 | L40: Argentina | Capital Federal | Belgrano | M40: Departamento | N40: 2 | O40: Puerto Norte | P40: Compartida en Oficina (Dos Asesores) | Q40: Venta | R40: =VLOOKUP($O40,'Mapa Oficinas'!$A$7:$C$46,2,FALSE) -> Zona Norte (GBA) | S40: =VLOOKUP($O40,'Mapa Oficinas'!$A$7:$C$46,3,FALSE) -> Nordelta
...

Sheet DESCARTADO
A2: 45943 | B2: 9102025 | D2: Reserva Venta Flor Lote Dos Valles A25 | E2: Realizado | F2: Teléfono | G2: 43000 | H2: 750 | I2: Dólares | J2: Dólares | L2: Argentina | Rio Negro | Bariloche | San Carlos De Bariloche | M2: Terreno | N2: 1 | O2: Patagonia Lakes BRC | P2: Master | Q2: Venta
A3: 45798 | B3: VCO59064 AP6619653 | D3: Departamento en Altos de Maschwitz - 2 AMB con Jardín | E3: Realizado | F3: AR ZonaProp | G3: 102194 | H3: 1000 | I3: Dólares | J3: Dólares | K3: Departamento en Altos de Maschwitz - 2 AMB con Jardín | L3: Argentina | G.B.A. Zona Norte | Escobar | Ingeniero Maschwitz | Altos de Maschwitz | M3: Departamento | N3: 2 | O3: Puerto Norte | P3: Compartida en Oficina (Dos Asesores) | Q3: Venta
A4: 45992 | B4: CAP7356426 | D4: Departamento en Las Heras | E4: Realizado | F4: AR ZonaProp | G4: 31900 | H4: 2000 | I4: Dólares | J4: Local | K4: Adolfo Calle y Bombal | L4: Argentina | Mendoza | Las Heras | M4: Departamento | N4: 2 | O4: Cuyo Real | P4: Propia (Único Asesor) | Q4: Venta
A5: 45706 | B5: VAP6607532 | D5: Departamento 3 AMB en Alquiler en Infinity Nordelta | E5: Realizado | F5: AR ZonaProp | G5: 800 | H5: 3000 | I5: Dólares | J5: Dólares | K5: Departamento 3 AMB en Alquiler en Infinity Nordelta | L5: Argentina | G.B.A. Zona Norte | Tigre | Countries/B.Cerrado (Tigre) | Nordelta | El Palmar | Infinity Residences | M5: Departamento | N5: 2 | O5: Puerto Norte | P5: Propia (Único Asesor) | Q5: Venta
A6: 45758 | B6: CLA6354054 | D6: LOTES en Barrio Estancia Kingsbroock - 122 y 612 | E6: Realizado | F6: AR ZonaProp | G6: 5200 | H6: 4500 | I6: Dólares | J6: Dólares | K6: LOTES en Barrio Estancia Kingsbroock - 122 y 612 | L6: Argentina | G.B.A. Zona Sur | La Plata | Villa Elvira | M6: Terreno | N6: 2 | O6: Golden Team | P6: Propia (Único Asesor) | Q6: Venta
A7: 45721 | B7: CLA6354054 | D7: LOTES en Barrio Estancia Kingsbroock - 122 y 612 | E7: Realizado | F7: Referido | G7: 5300 | H7: 4774 | I7: Dólares | J7: Dólares | K7: LOTES en Barrio Estancia Kingsbroock - 122 y 612 | L7: Argentina | G.B.A. Zona Sur | La Plata | Villa Elvira | M7: Terreno | N7: 2 | O7: Golden Team | P7: Propia (Único Asesor) | Q7: Venta
A8: 45992 | B8: CHO7100411 | D8: Casa en Las Heras | E8: Realizado | F8: AR ZonaProp | G8: 48000 | H8: 4840 | I8: Dólares | J8: Dólares | K8: 3 de febrero al 500 | L8: Argentina | Mendoza | Las Heras | M8: Casa | N8: 2 | O8: Cuyo Real | P8: Propia (Único Asesor) | Q8: Venta
A9: 45952 | B9: CGA7289163 | D9: Cochera en Mendoza | E9: Realizado | F9: Facebook | G9: 4900 | H9: 4900 | I9: Dólares | J9: Dólares | K9: Garibaldi al 100 | L9: Argentina | Mendoza | Capital | Mendoza | M9: Garage | N9: 2 | O9: Cuyo Real | P9: Propia (Único Asesor) | Q9: Venta
A10: 45992 | B10: CHO6734839 | D10: CASA EN VENTA VISTALBA LOTEO DON CARLOS | E10: Realizado | F10: AR ZonaProp | G10: 140000 | H10: 5000 | I10: Dólares | J10: Dólares | K10: LOTEO DON CARLOS LOS TILOS LOTE K | L10: Argentina | Mendoza | Lujan De Cuyo | Vistalba | M10: Casa | N10: 1 | O10: Cuyo Real | P10: (Interior) Compartida Fuera de la Red Búsqueda | Q10: Venta
A11: 45777 | B11: CGA6673233 | D11: Venta Cochera en Almagro | E11: Realizado | F11: AR ZonaProp | G11: 7000 | H11: 5000 | I11: Dólares | J11: Dólares | K11: Corrientes al 3800 | L11: Argentina | Capital Federal | Almagro | M11: Garage | N11: 2 | O11: Seniority | P11: Propia (Único Asesor) | Q11: Venta
A12: 45951 | B12: CAP7331334 | D12: Departamento 2 AMB en Alquiler - Marinas del Portezuelo | E12: Realizado | F12: AR MercadoLibre | G12: 650 | H12: 5200 | I12: Dólares | J12: Dólares | K12: Departamento 2 AMB en Alquiler - Marinas del Portezuelo | L12: Argentina | G.B.A. Zona Norte | Tigre | Countries/B.Cerrado (Tigre) | Nordelta | Portezuelo | Marinas del Portezuelo | M12: Departamento | N12: 2 | O12: Puerto Norte | P12: Propia (Único Asesor) | Q12: Venta
A13: 45842 | B13: CLA6354054 | D13: LOTES en Barrio Estancia Kingsbroock - 122 y 612 | E13: Realizado | F13: AR ZonaProp | G13: 5200 | H13: 5200 | I13: Dólares | J13: Dólares | K13: LOTES en Barrio Estancia Kingsbroock - 122 y 612 | L13: Argentina | G.B.A. Zona Sur | La Plata | Villa Elvira | M13: Terreno | N13: 2 | O13: Golden Team | P13: Propia (Único Asesor) | Q13: Venta
A14: 45954 | B14: CHO7300194 | D14: Casa en alquiler permanente en Bariloche | E14: Realizado | F14: Teléfono | G14: 2800 | H14: 5600 | I14: Dólares | J14: Dólares | K14: Centro, San Carlos de Bariloche | L14: Argentina | Rio Negro | Bariloche | M14: Casa | N14: 2 | O14: Patagonia Lakes BRC | P14: Master | Q14: Venta
... A27: 45929 | B27: CHO5031458 | D27: ALQUILER TURÍSTICO - Casa categoria impresionante vista al lago en barrio cerrado Villa la Angostura | E27: Realizado | F27: Referido | G27: 700 | H27: 8400 | I27: Dólares | J27: Dólares | K27: Barrio cerrado Dos Lagos, Villa La Angostura | L27: Argentina | Neuquen | Villa La Angostura | Countries/ B. Cerrado (V. La Angostura) | M27: Casa | N27: 2 | O27: Patagonia Lakes VLA | P27: Propia (Único Asesor) | Q27: Venta
A28: 45992 | B28: Casa C/ Remax Follow | D28: Casa c/ remax follow | E28: Realizado | F28: AR ZonaProp | G28: 34000 | H28: 8450 | I28: Dólares | J28: Dólares | L28: Argentina | Mendoza | Guaymallen | M28: Casa | N28: 1 | O28: Cuyo Real | P28: (Interior) Compartida Fuera de la Red Búsqueda | Q28: Venta
A29: 46077 | B29: CLA7827009 | D29: Terreno en Lujan | E29: Realizado | F29: Repetido | G29: 8500 | H29: 8500 | I29: Dólares | J29: Dólares | K29: BARRIO SANTA IRENE RUTA 6 KM 155.5 LUJAN 30 | L29: Argentina | G.B.A. Zona Oeste | Lujan | M29: Terreno | N29: 2 | O29: Audacity | P29: Propia (Único Asesor) | Q29: Venta
A30: 46066 | B30: CLA6250455 | D30: Terreno en Venta, Santo Tome, Santa Fe | E30: Realizado | F30: Conocido | G30: 10000 | H30: 8500 | I30: Dólares | J30: Dólares | K30: Terreno en Venta, Santo Tome, Santa Fe | L30: Argentina | Santa Fe | La Capital | Santo Tome | M30: Terreno | N30: 2 | O30: De la Veracruz | P30: Compartida en Oficina (Dos Asesores) | Q30: Venta
A31: 46066 | B31: CLA6250311 | D31: Terreno en Venta, Santo Tome, Santa Fe | E31: Realizado | F31: Conocido | G31: 10000 | H31: 8500 | I31: Dólares | J31: Dólares | K31: Terreno en Venta, Santo Tome, Santa Fe | L31: Argentina | Santa Fe | La Capital | Santo Tome | M31: Terreno | N31: 2 | O31: De la Veracruz | P31: Compartida en Oficina (Dos Asesores) | Q31: Venta
A32: 46066 | B32: CLA6250352 | D32: Terreno en Venta, Santo Tome, Santa Fe | E32: Realizado | F32: Conocido | G32: 10000 | H32: 8500 | I32: Dólares | J32: Dólares | K32: Terreno en Venta, Santo Tome, Santa Fe | L32: Argentina | Santa Fe | La Capital | Santo Tome | M32: Terreno | N32: 2 | O32: De la Veracruz | P32: Compartida en Oficina (Dos Asesores) | Q32: Venta
A33: 46059 | B33: CLA6250391 | D33: Terreno en Venta, Santo Tome, Santa Fe | E33: Realizado | F33: Conocido | G33: 10000 | H33: 8500 | I33: Dólares | J33: Dólares | K33: Terreno en Venta, Santo Tome, Santa Fe | L33: Argentina | Santa Fe | La Capital | Santo Tome | M33: Terreno | N33: 2 | O33: De la Veracruz | P33: Compartida en Oficina (Dos Asesores) | Q33: Venta
A34: 46059 | B34: CLA6250401 | D34: Terreno en Venta, Santo Tome, Santa Fe | E34: Realizado | F34: Conocido | G34: 10000 | H34: 8500 | I34: Dólares | J34: Dólares | K34: Terreno en Venta, Santo Tome, Santa Fe | L34: Argentina | Santa Fe | La Capital | Santo Tome | M34: Terreno | N34: 2 | O34: De la Veracruz | P34: Compartida en Oficina (Dos Asesores) | Q34: Venta
A35: 45816 | B35: CLA6687636 | D35: Terreno en venta Pucara | E35: Realizado | F35: Facebook | G35: 8600 | H35: 8600 | I35: Dólares | J35: Dólares | K35: PUCARA | L35: Argentina | Salta | Capital | Salta | Zona Oeste | M35: Terreno | N35: 2 | O35: Realty Group | P35: Compartida en Oficina (Dos Asesores) | Q35: Venta
A36: 45973 | B36: CLA6250455 | D36: Terreno en Venta, Santo Tome, Santa Fe | E36: Realizado | F36: Facebook | G36: 10000 | H36: 9000 | I36: Dólares | J36: Dólares | K36: Terreno en Venta, Santo Tome, Santa Fe | L36: Argentina | Santa Fe | La Capital | Santo Tome | M36: Terreno | N36: 2 | O36: De la Veracruz | P36: Compartida en Oficina (Dos Asesores) | Q36: Venta
A37: 45926 | B37: CAP7128288 | D37: Departamento en alquiler 2amb con balcón | E37: Realizado | F37: AR MercadoLibre | G37: 450000 | H37: 9000 | I37: Dólares | J37: Local | K37: Bonifacini al 3800 | L37: Argentina | G.B.A. Zona Oeste | Tres De Febrero | Santos Lugares | M37: Departamento | N37: 2 | O37: Lion Team | P37: Propia (Único Asesor) | Q37: Venta
A38: 45897 | B38: CLA7070818 | D38: Terreno en Jardines del valle (Cerrillos) | E38: Realizado | F38: Facebook | G38: 11000 | H38: 9000 | I38: Dólares | J38: Dólares | K38: RUTA 68 cerrillos | L38: Argentina | Salta | Cerrillos | M38: Terreno | N38: 2 | O38: Realty Group | P38: Propia (Único Asesor) | Q38: Venta
A39: 45780 | B39: CPN57379 LA6447276 | D39: Terreno - Los Hornos | E39: Realizado | F39: Teléfono | G39: 9000 | H39: 9000 | I39: Dólares | J39: Dólares | K39: Terreno en VENTA, Barrio PRIVADO, Solares, Calle 83 y 139 | L39: Argentina | G.B.A. Zona Sur | La Plata | Los Hornos | M39: Terreno | N39: 2 | O39: Golden Team | P39: Propia (Único Asesor) | Q39: Venta
A40: 45780 | B40: CPN57379 LA6447276 | D40: Terreno - Los Hornos | E40: Realizado | F40: Conocido | G40: 9000 | H40: 9000 | I40: Dólares | J40: Dólares | K40: Terreno en VENTA, Barrio PRIVADO, Solares, Calle 83 y 139 | L40: Argentina | G.B.A. Zona Sur | La Plata | Los Hornos | M40: Terreno | N40: 2 | O40: Golden Team | P40: Propia (Único Asesor) | Q40: Venta
A41: 46094 | B41: Corralitos terreno | D41: Terreno en venta en corralitos | E41: Realizado | F41: AR ZonaProp | G41: 0 | H41: 9500 | I41: Dólares | J41: Dólares | L41: Argentina | Mendoza | Guaymallen | Los Corralitos | M41: Terreno | N41: 1 | O41: Cuyo Real | P41: (Interior) Compartida Fuera de la Red Búsqueda | Q41: Venta
A42: 45841 | B42: CGA6814291 | D42: Venta Cochera céntrica Bariloche OPORTUNIDAD Permuta | E42: Realizado | F42: Teléfono | G42: 10000 | H42: 9500 | I42: Dólares | J42: Dólares | K42: Centro, San Carlos de Bariloche | L42: Argentina | Rio Negro | Bariloche | San Carlos De Bariloche | Centro | M42: Garage | N42: 2 | O42: Patagonia Lakes BRC | P42: Propia (Único Asesor) | Q42: Venta
A43: 45761 | B43: CLA6730114 | D43: Terreno en venta nuevo alisos | E43: Realizado | F43: Conocido | G43: 10500 | H43: 9551 | I43: Dólares | J43: Dólares | K43: nuevo alisos manzana 8 lote 1 | L43: Argentina | Jujuy | San Antonio | Los Alisos | M43: Terreno | N43: 2 | O43: Plaza | P43: Compartida en Oficina (Dos Asesores) | Q43: Venta
A44: 45854 | B44: CLA6758657 | D44: Terreno en venta en Valle Alegre | E44: Realizado | F44: Referido | G44: 9600 | H44: 9600 | I44: Dólares | J44: Dólares | K44: VALLE ALEGRE | L44: Argentina | Salta | La Caldera | M44: Terreno | N44: 2 | O44: Realty Group | P44: Compartida en Oficina (Dos Asesores) | Q44: Venta
A45: 46065 | B45: CLA7690260 | D45: Terreno en venta Loteo Pucara | E45: Realizado | F45: Facebook | G45: 10500 | H45: 9965 | I45: Dólares | J45: Dólares | K45: LOTEO PUCARA | L45: Argentina | Salta | Capital | Salta | Zona Oeste | M45: Terreno | N45: 2 | O45: Realty Group | P45: Propia (Único Asesor) | Q45: Venta
A46: 46063 | B46: CLA7484087 | D46: Terreno en venta ubicado en Potreros de Quijano - Salta | E46: Realizado | F46: AR ZonaProp | G46: 10000 | H46: 10000 | I46: Dólares | J46: Dólares | K46: Potreros de Quijano | L46: Argentina | Salta | Rosario De Lerma | Campo Quijano | M46: Terreno | N46: 2 | O46: Realty Group | P46: Propia (Único Asesor) | Q46: Venta
A47: 46056 | B47: CLA7320742 | D47: Terreno en venta ubicado en Loteo Pucara - Salta | E47: Realizado | F47: Facebook | G47: 10500 | H47: 10000 | I47: Dólares | J47: Dólares | K47: Loteo Pucara | L47: Argentina | Salta | Capital | Salta | Zona Sur | M47: Terreno | N47: 2 | O47: Realty Group | P47: Propia (Único Asesor) | Q47: Venta
A48: 46036 | B48: CPN57379 LA6447276 | D48: Terreno - Los Hornos | E48: Realizado | F48: AR ZonaProp | G48: 10000 | H48: 10000 | I48: Dólares | J48: Dólares | K48: Terreno en VENTA, Barrio PRIVADO, Solares, Calle 83 y 139 | L48: Argentina | G.B.A. Zona Sur | La Plata | Los Hornos | M48: Terreno | N48: 2 | O48: Golden Team | P48: Propia (Único Asesor) | Q48: Venta
A49: 46028 | B49: CLA6752890 | D49: Terreno en Barrio Santa Rita | E49: Realizado | F49: Facebook | G49: 12000 | H49: 10000 | I49: Dólares | J49: Dólares | K49: TERRENO BARRIO SANTA RITA | L49: Argentina | Santa Fe | La Capital | Santa Fe | M49: Terreno | N49: 2 | O49: De la Veracruz | P49: Propia (Único Asesor) | Q49: Venta
A50: 45992 | B50: CHO6728128 | D50: Venta casa 3 habitaciones barrio privado maipu | E50: Realizado | F50: AR ZonaProp | G50: 115000 | H50: 10000 | I50: Dólares | J50: Dólares | K50: Videla Castillo | L50: Argentina | Mendoza | Maipu | M50: Casa | N50: 1 | O50: Cuyo Real | P50: (Interior) Compartida Fuera de la Red Búsqueda | Q50: Venta
A51: 45981 | B51: CLA6948853 | D51: VENTA TERRENO DE 1132 M2 EN AREA 60, LA VICTORIA POLO COUNTRY ¡OFERTA INCREIBLE! | E51: Realizado | F51: AR ZonaProp | G51: 13000 | H51: 10000 | I51: Dólares | J51: Dólares | K51: Club de campo La Victoria, Area 60, Lote 160 | L51: Argentina | Interior Buenos Aires | Coronel Brandsen | Area 60 | M51: Terreno | N51: 2 | O51: Destino II | P51: Propia (Único Asesor) | Q51: Venta
A52: 45965 | B52: CLA7384505 | D52: CB VENDE - TERRENO - BOSQUE DEL CEIBAL I | E52: Realizado | F52: Conocido | G52: 10500 | H52: 10000 | I52: Dólares | J52: Dólares | K52: Calle Lapacho al 800 | L52: Argentina | Jujuy | San Antonio | M52: Terreno | N52: 2 | O52: Plaza | P52: Propia (Único Asesor) | Q52: Venta
A53: 45938 | B53: CLA7263283 | D53: Terreno en los Domingos sauce viejo | E53: Realizado | F53: Conocido | G53: 13000 | H53: 10000 | I53: Dólares | J53: Dólares | K53: Lote en los Domingos, sauce Viejo | L53: Argentina | Santa Fe | La Capital | Sauce Viejo | M53: Terreno | N53: 2 | O53: De la Veracruz | P53: Propia (Único Asesor) | Q53: Venta
...
