Workbook

Sheet Hoja2
B4: Todas las ventas | D4: Ene25 - Mar26 | G4: PROM MES
B5: TOTAL | C5: USD | D5: 399136299 | E5: =D5/D$5 -> 1 | G5: =D5/15 -> 26609087
B6: TOTAL | C6: TRX | D6: 2695 | E6: =D6/D$6 -> 1 | G6: =D6/15 -> 179.66667
B7: TOTAL | C7: TICK PROM | D7: =D5/D6 -> 148102.52 | E7: =D7/D$7 -> 1 | G7: =G5/G6 -> 148102.52
B8: Exluye ventas compartidas con otra RED
B9: CB | C9: USD | D9: 261332623 | E9: =D9/D$5 -> 0.65474532 | G9: =D9/15 -> 17422175
B10: CB | C10: TRX | D10: 1852 | E10: =D10/D$6 -> 0.68719852 | G10: =D10/15 -> 123.46667
B11: CB | C11: TICK PROM | D11: =D9/D10 -> 141108.33 | E11: =D11/D$7 -> 0.95277464 | G11: =G9/G10 -> 141108.33
B14: CABA + GBA | C14: USD | D14: 201806790 | E14: =D14/D$5 -> 0.50560871 | G14: =D14/15 -> 13453786
B15: CABA + GBA | C15: TRX | D15: 1357 | E15: =D15/D$6 -> 0.50352505 | G15: =D15/15 -> 90.466667
B16: CABA + GBA | C16: TICK PROM | D16: =D14/D15 -> 148715.39 | E16: =D16/D$7 -> 1.0041382 | G16: =G14/G15 -> 148715.39
B18: Sólo Casa, Departamento, Oficina y PH - Excl: Terreno, Storage, Hotel, Garage
B19: CABA + GBA | C19: USD | D19: 185256641 | E19: =D19/D$5 -> 0.46414381 | G19: =D19/15 -> 12350443
B20: CABA + GBA | C20: TRX | D20: 1255 | E20: =D20/D$6 -> 0.46567718 | G20: =D20/15 -> 83.666667
B21: CABA + GBA | C21: TICK PROM | D21: =D19/D20 -> 147614.85 | E21: =D21/D$7 -> 0.99670722 | G21: =G19/G20 -> 147614.85
B23: =CONCATENATE("Con Rango de Precio > ",'Mapa Oficinas'!I21," y < ",'Mapa Oficinas'!I20) -> Con Rango de Precio > 69999 y < 1000000
B24: CABA + GBA | C24: USD | D24: =DINAMICA!BL50 -> 170271805 | E24: =D24/D$5 -> 0.42660065 | G24: =D24/15 -> 11351454
B25: CABA + GBA | C25: TRX | D25: =DINAMICA!BL58 -> 1016 | E25: =D25/D$6 -> 0.37699443 | G25: =D25/15 -> 67.733333
B26: CABA + GBA | C26: TICK PROM | D26: =D24/D25 -> 167590.36 | E26: =D26/D$7 -> 1.1315834 | G26: =G24/G25 -> 167590.36
B28: Sólo CABA
B29: CABA | C29: USD | D29: =DINAMICA!BL69 -> 109991127 | E29: =D29/D$5 -> 0.27557285 | G29: =D29/15 -> 7332741.8
B30: CABA | C30: TRX | D30: =DINAMICA!BL70 -> 677 | E30: =D30/D$6 -> 0.25120594 | G30: =D30/15 -> 45.133333
B31: CABA | C31: TICK PROM | D31: =D29/D30 -> 162468.43 | E31: =D31/D$7 -> 1.0969997 | G31: =G29/G30 -> 162468.43
B35: Captación Inicial | D35: 3000000
B36: Costo captación | C36: 0.0175 | D36: =(1-C36)*D35 -> 2947500
B37: Neto a colocar | C37: 0.95 | D37: =D36*C37 -> 2800125 | E37: =D37/D24 -> 0.01644503
B38: Cantidad Operaciones | C38: 40000 | D38: =ROUND(D37/C38,0) -> 70 | E38: =D38/D25 -> 0.068897638
B40: Penetración | C40: % | D40: Ventas X Mes | G40: Meses hasta completar
B41: =B24 -> CABA + GBA | C41: 0.1 | D41: =ROUND(C41*G$25,0) -> 7 | G41: =$D$38/D41 -> 10
B42: =B25 -> CABA + GBA | C42: 0.15 | D42: =ROUND(C42*G$25,0) -> 10 | G42: =$D$38/D42 -> 7
B43: =B26 -> CABA + GBA | C43: 0.25 | D43: =ROUND(C43*G$25,0) -> 17 | G43: =$D$38/D43 -> 4.1176471
B45: =B29 -> CABA | C45: 0.1 | D45: =ROUND(C45*G$30,0) -> 5 | G45: =$D$38/D45 -> 14
B46: =B29 -> CABA | C46: 0.15 | D46: =ROUND(C46*G$30,0) -> 7 | G46: =$D$38/D46 -> 10
B47: =B30 -> CABA | C47: 0.25 | D47: =ROUND(C47*G$30,0) -> 11 | G47: =$D$38/D47 -> 6.3636364

Sheet DINAMICA
B1: Unificador | C1: (Varios elementos) | X1: Unificador | Y1: (Varios elementos) | AS1: Unificador | AT1: (Varios elementos)
B2: RANGO_TCMC | C2: (Todas) | X2: Precio Cierre Total | Y2: (Todas) | AS2: RANGO_TCMC | AT2: 1
X3: TIPO_OPERACION2 | Y3: CB | AS3: TIPO_OPERACION2 | AT3: CB
B4: Suma de Precio Cierre Total | D4: AÑO | E4: MES | Z4: 3 | AA4: 4 | AB4: 5 | AC4: 6 | AD4: 7 | AE4: 8 | AF4: 9 | AG4: 10 | AH4: 11 | AI4: 12 | AJ4: 13 | AK4: 14 | AL4: 15 | AM4: 16 | AN4: 17 | AO4: 18 | AP4: 19 | AQ4: 20 | AU4: 3 | AV4: 4 | AW4: 5 | AX4: 6 | AY4: 7 | AZ4: 8 | BA4: 9 | BB4: 10 | BC4: 11 | BD4: 12 | BE4: 13 | BF4: 14 | BG4: 15 | BH4: 16 | BI4: 17 | BJ4: 18 | BK4: 19 | BL4: 20
D5: 2025 | E5: 2025 | F5: 2025 | G5: 2025 | H5: 2025 | I5: 2025 | J5: 2025 | K5: 2025 | L5: 2025 | M5: 2025 | N5: 2025 | O5: 2025 | P5: Total 2025 | Q5: 2026 | R5: 2026 | S5: 2026 | T5: Total 2026 | U5: Total general | X5: Suma de Precio Cierre Total | Z5: AÑO | AA5: MES | AS5: Suma de Precio Cierre Total | AU5: AÑO | AV5: MES
B6: TIPO_OPERACION2 | C6: Zona CB | D6: 1 | E6: 2 | F6: 3 | G6: 4 | H6: 5 | I6: 6 | J6: 7 | K6: 8 | L6: 9 | M6: 10 | N6: 11 | O6: 12 | Q6: 1 | R6: 2 | S6: 3 | Z6: 2025 | AA6: 2025 | AB6: 2025 | AC6: 2025 | AD6: 2025 | AE6: 2025 | AF6: 2025 | AG6: 2025 | AH6: 2025 | AI6: 2025 | AJ6: 2025 | AK6: 2025 | AL6: Total 2025 | AM6: 2026 | AN6: 2026 | AO6: 2026 | AP6: Total 2026 | AQ6: Total general | AU6: 2025 | AV6: 2025 | AW6: 2025 | AX6: 2025 | AY6: 2025 | AZ6: 2025 | BA6: 2025 | BB6: 2025 | BC6: 2025 | BD6: 2025 | BE6: 2025 | BF6: 2025 | BG6: Total 2025 | BH6: 2026 | BI6: 2026 | BJ6: 2026 | BK6: Total 2026 | BL6: Total general
B7: CB | C7: CABA | D7: 5716689 | E7: 5667000 | F7: 7765900 | G7: 10044500 | H7: 9498070 | I7: 9536000 | J7: 9727250 | K7: 10229000 | L7: 8158380 | M7: 10522326 | N7: 6506466 | O7: 8897282 | P7: 102268863 | Q7: 7653250 | R7: 7308500 | S7: 11938406 | T7: 26900156 | U7: 129169019 | X7: Tipo Propiedad | Y7: Zona CB | Z7: 1 | AA7: 2 | AB7: 3 | AC7: 4 | AD7: 5 | AE7: 6 | AF7: 7 | AG7: 8 | AH7: 9 | AI7: 10 | AJ7: 11 | AK7: 12 | AM7: 1 | AN7: 2 | AO7: 3 | AS7: Tipo Propiedad | AT7: Zona CB | AU7: 1 | AV7: 2 | AW7: 3 | AX7: 4 | AY7: 5 | AZ7: 6 | BA7: 7 | BB7: 8 | BC7: 9 | BD7: 10 | BE7: 11 | BF7: 12 | BH7: 1 | BI7: 2 | BJ7: 3
B8: CB | C8: Interior - Jujuy | E8: 144000 | G8: 498900 | H8: 70000 | I8: 186000 | J8: 493350 | K8: 38000 | L8: 62000 | O8: 242500 | P8: 1734750 | Q8: 120000 | R8: 232000 | S8: 590000 | T8: 942000 | U8: 2676750 | X8: Casa | Y8: CABA | Z8: 1900000 | AA8: 523000 | AB8: 1744000 | AC8: 1803000 | AD8: 1002000 | AE8: 3093000 | AF8: 2269000 | AG8: 2111500 | AH8: 1259880 | AI8: 1682000 | AJ8: 801730 | AK8: 929000 | AL8: 19118110 | AM8: 1287000 | AN8: 970000 | AO8: 1403500 | AP8: 3660500 | AQ8: 22778610 | AS8: Casa | AT8: CABA | AU8: 1900000 | AV8: 458000 | AW8: 1744000 | AX8: 1803000 | AY8: 1002000 | AZ8: 1875000 | BA8: 2269000 | BB8: 2111500 | BC8: 1153880 | BD8: 1682000 | BE8: 746730 | BF8: 879000 | BG8: 17624110 | BH8: 1287000 | BI8: 905000 | BJ8: 1179500 | BK8: 3371500 | BL8: 20995610
B9: CB | C9: Interior - Mendoza | D9: 55000 | E9: 156000 | F9: 67800 | G9: 331900 | H9: 251000 | I9: 786500 | J9: 668000 | K9: 375000 | L9: 238000 | M9: 734000 | N9: 290000 | O9: 2525800 | P9: 6479000 | Q9: 771500 | R9: 551000 | S9: 1158000 | T9: 2480500 | U9: 8959500 | X9: Casa | Y9: Zona Norte (GBA) | Z9: 1192000 | AA9: 842000 | AB9: 1284100 | AC9: 1898400 | AD9: 1562000 | AE9: 3185000 | AF9: 3090000 | AG9: 1817000 | AH9: 1386000 | AI9: 1001000 | AJ9: 1401000 | AK9: 1078000 | AL9: 19736500 | AM9: 2254000 | AN9: 2080850 | AO9: 1632000 | AP9: 5966850 | AQ9: 25703350 | AS9: Casa | AT9: Zona Norte (GBA) | AU9: 1192000 | AV9: 842000 | AW9: 1284100 | AX9: 1898400 | AY9: 1562000 | AZ9: 3185000 | BA9: 3090000 | BB9: 1817000 | BC9: 1336000 | BD9: 1001000 | BE9: 1401000 | BF9: 1078000 | BG9: 19686500 | BH9: 2254000 | BI9: 2080850 | BJ9: 1632000 | BK9: 5966850 | BL9: 25653350
B10: CB | C10: Interior - Neuquén | D10: 1469379 | E10: 1120650 | F10: 1397800 | G10: 1514000 | H10: 4732813 | I10: 2050714 | J10: 659500 | K10: 2377000 | L10: 3757000 | M10: 1950900 | N10: 288000 | O10: 1177000 | P10: 22494756 | Q10: 1438000 | R10: 1149200 | S10: 2157583 | T10: 4744783 | U10: 27239539 | X10: Casa | Y10: Zona Oeste (GBA) | AB10: 137000 | AC10: 50000 | AD10: 256000 | AE10: 57000 | AH10: 170000 | AJ10: 42000 | AL10: 712000 | AM10: 72500 | AN10: 89000 | AO10: 195000 | AP10: 356500 | AQ10: 1068500 | AS10: Casa | AT10: Zona Oeste (GBA) | AW10: 72000 | AY10: 210000 | BC10: 115000 | BG10: 397000 | BH10: 72500 | BI10: 89000 | BJ10: 195000 | BK10: 356500 | BL10: 753500
B11: CB | C11: Interior - Río Negro | D11: 705343 | E11: 1424694 | F11: 656210 | G11: 1060959 | H11: 1688689 | I11: 455753 | J11: 1128750 | K11: 425080 | L11: 435000 | M11: 693000 | N11: 558000 | O11: 958985 | P11: 10190463 | Q11: 753125 | R11: 525700 | S11: 1342756 | T11: 2621581 | U11: 12812044 | X11: Casa | Y11: Zona Sur (GBA) | Z11: 47000 | AA11: 228000 | AC11: 158000 | AD11: 317000 | AE11: 185000 | AG11: 47000 | AI11: 160000 | AJ11: 36000 | AK11: 146500 | AL11: 1324500 | AN11: 175000 | AO11: 175000 | AP11: 350000 | AQ11: 1674500 | AS11: Casa | AT11: Zona Sur (GBA) | AV11: 112000 | AX11: 158000 | AY11: 317000 | AZ11: 185000 | BD11: 160000 | BF11: 95000 | BG11: 1027000 | BI11: 175000 | BJ11: 175000 | BK11: 350000 | BL11: 1377000
B12: CB | C12: Interior - Salta | D12: 176000 | E12: 330000 | F12: 258500 | G12: 401000 | H12: 201500 | I12: 149000 | J12: 781000 | K12: 385000 | L12: 90000 | M12: 527500 | N12: 104000 | O12: 204000 | P12: 3607500 | Q12: 47000 | R12: 120000 | S12: 343000 | T12: 510000 | U12: 4117500 | X12: Total Casa | Z12: 3139000 | AA12: 1593000 | AB12: 3165100 | AC12: 3909400 | AD12: 3137000 | AE12: 6520000 | AF12: 5359000 | AG12: 3975500 | AH12: 2815880 | AI12: 2843000 | AJ12: 2280730 | AK12: 2153500 | AL12: 40891110 | AM12: 3613500 | AN12: 3314850 | AO12: 3405500 | AP12: 10333850 | AQ12: 51224960 | AS12: Total Casa | AU12: 3092000 | AV12: 1412000 | AW12: 3100100 | AX12: 3859400 | AY12: 3091000 | AZ12: 5245000 | BA12: 5359000 | BB12: 3928500 | BC12: 2604880 | BD12: 2843000 | BE12: 2147730 | BF12: 2052000 | BG12: 38734610 | BH12: 3613500 | BI12: 3249850 | BJ12: 3181500 | BK12: 10044850 | BL12: 48779460
B13: CB | C13: Interior - San Luis | O13: 65000 | P13: 65000 | U13: 65000 | X13: Departamento | Y13: CABA | Z13: 2917689 | AA13: 4177500 | AB13: 4855900 | AC13: 6831000 | AD13: 7618570 | AE13: 4528000 | AF13: 6082000 | AG13: 6968700 | AH13: 5348000 | AI13: 7249456 | AJ13: 4316736 | AK13: 6243882 | AL13: 67137433 | AM13: 5304150 | AN13: 5660500 | AO13: 6735500 | AP13: 17700150 | AQ13: 84837583 | AS13: Departamento | AT13: CABA | AU13: 2797689 | AV13: 3892500 | AW13: 4667900 | AX13: 6315000 | AY13: 7182070 | AZ13: 4275000 | BA13: 5273000 | BB13: 6664200 | BC13: 4956500 | BD13: 6457456 | BE13: 3761500 | BF13: 4460682 | BG13: 60703497 | BH13: 4848250 | BI13: 5134500 | BJ13: 6326000 | BK13: 16308750 | BL13: 77012247
B14: CB | C14: Interior - Santa Fe | D14: 90000 | F14: 42000 | G14: 81500 | I14: 130000 | J14: 80000 | K14: 1400000 | L14: 337000 | M14: 265000 | N14: 58000 | P14: 2483500 | Q14: 252000 | R14: 380000 | S14: 540000 | T14: 1172000 | U14: 3655500 | X14: Departamento | Y14: Zona Norte (GBA) | Z14: 1127000 | AA14: 1435484 | AB14: 2765089 | AC14: 2538500 | AD14: 2096000 | AE14: 3029750 | AF14: 2778128 | AG14: 1881000 | AH14: 1376000 | AI14: 1879500 | AJ14: 1085300 | AK14: 2255000 | AL14: 24246751 | AM14: 1862500 | AN14: 1423447 | AO14: 3200000 | AP14: 6485947 | AQ14: 30732698 | AS14: Departamento | AT14: Zona Norte (GBA) | AU14: 1127000 | AV14: 1435484 | AW14: 2527589 | AX14: 2395000 | AY14: 2051000 | AZ14: 2968750 | BA14: 2362128 | BB14: 1881000 | BC14: 1312000 | BD14: 1829500 | BE14: 878300 | BF14: 2211000 | BG14: 22978751 | BH14: 1798500 | BI14: 1247447 | BJ14: 3076000 | BK14: 6121947 | BL14: 29100698
B15: CB | C15: Zona Norte (GBA) | D15: 3135830 | E15: 3151484 | F15: 4635189 | G15: 5728900 | H15: 4074540 | I15: 6926750 | J15: 6062128 | K15: 4503330 | L15: 4823650 | M15: 3014850 | N15: 3457323 | O15: 3747000 | P15: 53260974 | Q15: 4689000 | R15: 3827297 | S15: 5286000 | T15: 13802297 | U15: 67063271 | X15: Departamento | Y15: Zona Oeste (GBA) | Z15: 50000 | AB15: 69000 | AF15: 291000 | AG15: 168000 | AH15: 118500 | AI15: 48000 | AJ15: 41200 | AK15: 275500 | AL15: 1061200 | AN15: 71500 | AO15: 102000 | AP15: 173500 | AQ15: 1234700 | AS15: Departamento | AT15: Zona Oeste (GBA) | BA15: 180000 | BC15: 118500 | BF15: 275500 | BG15: 574000 | BI15: 71500 | BJ15: 102000 | BK15: 173500 | BL15: 747500
B16: CB | C16: Zona Oeste (GBA) | D16: 50000 | F16: 206000 | G16: 50000 | H16: 406000 | I16: 57000 | J16: 339500 | K16: 280000 | L16: 288500 | M16: 48000 | N16: 83200 | O16: 275500 | P16: 2083700 | Q16: 112500 | R16: 160500 | S16: 297000 | T16: 570000 | U16: 2653700 | X16: Departamento | Y16: Zona Sur (GBA) | Z16: 113400 | AD16: 62000 | AE16: 82000 | AF16: 82000 | AG16: 223400 | AH16: 235000 | AI16: 204000 | AK16: 74000 | AL16: 1075800 | AM16: 45000 | AN16: 67500 | AP16: 112500 | AQ16: 1188300 | AS16: Departamento | AT16: Zona Sur (GBA) | AU16: 73400 | BA16: 82000 | BB16: 151400 | BC16: 87500 | BD16: 140000 | BF16: 74000 | BG16: 608300 | BL16: 608300
B17: CB | C17: Zona Sur (GBA) | D17: 160400 | E17: 228000 | G17: 158000 | H17: 379000 | I17: 325000 | J17: 82000 | K17: 270400 | L17: 235000 | M17: 364000 | N17: 36000 | O17: 220500 | P17: 2458300 | Q17: 45000 | R17: 242500 | S17: 175000 | T17: 462500 | U17: 2920800 | X17: Total Departamento | Z17: 4208089 | AA17: 5612984 | AB17: 7689989 | AC17: 9369500 | AD17: 9776570 | AE17: 7639750 | AF17: 9233128 | AG17: 9241100 | AH17: 7077500 | AI17: 9380956 | AJ17: 5443236 | AK17: 8848382 | AL17: 93521184 | AM17: 7211650 | AN17: 7222947 | AO17: 10037500 | AP17: 24472097 | AQ17: 117993281 | AS17: Total Departamento | AU17: 3998089 | AV17: 5327984 | AW17: 7195489 | AX17: 8710000 | AY17: 9233070 | AZ17: 7243750 | BA17: 7897128 | BB17: 8696600 | BC17: 6474500 | BD17: 8426956 | BE17: 4639800 | BF17: 7021182 | BG17: 84864548 | BH17: 6646750 | BI17: 6453447 | BJ17: 9504000 | BK17: 22604197 | BL17: 107468745
B18: Total CB | D18: 11558641 | E18: 12221828 | F18: 15029399 | G18: 19869659 | H18: 21301612 | I18: 20602717 | J18: 20021478 | K18: 20282810 | L18: 18424530 | M18: 18119576 | N18: 11380989 | O18: 18313567 | P18: 207126806 | Q18: 15881375 | R18: 14496697 | S18: 23827745 | T18: 54205817 | U18: 261332623 | X18: Garage | Y18: CABA | AC18: 90000 | AJ18: 50000 | AL18: 140000 | AQ18: 140000 | AS18: Garage | AT18: CABA | AX18: 90000 | BG18: 90000 | BL18: 90000
B19: Otra Red Búsqueda | C19: CABA | D19: 2585000 | E19: 970000 | F19: 1084000 | G19: 1714000 | H19: 1793500 | I19: 1801000 | J19: 2084500 | K19: 3130000 | L19: 1866000 | M19: 5472400 | N19: 3576000 | O19: 4195000 | P19: 30271400 | Q19: 1666500 | R19: 2374000 | S19: 3873250 | T19: 7913750 | U19: 38185150 | X19: Total Garage | AC19: 90000 | AJ19: 50000 | AL19: 140000 | AQ19: 140000 | AS19: Total Garage | AX19: 90000 | BG19: 90000 | BL19: 90000
B20: Otra Red Búsqueda | C20: Interior - Mendoza | F20: 36500 | G20: 169000 | I20: 276000 | J20: 65000 | L20: 280000 | M20: 55000 | O20: 966500 | P20: 1848000 | R20: 73000 | S20: 752000 | T20: 825000 | U20: 2673000 | X20: Hotel | Y20: CABA | AO20: 70000 | AP20: 70000 | AQ20: 70000 | AS20: Hotel | AT20: CABA | BJ20: 70000 | BK20: 70000 | BL20: 70000
B21: Otra Red Búsqueda | C21: Interior - Neuquén | E21: 507300 | F21: 334000 | G21: 169000 | H21: 144000 | I21: 179500 | J21: 182000 | K21: 93000 | L21: 448000 | M21: 668000 | O21: 100000 | P21: 2824800 | Q21: 325000 | R21: 379000 | S21: 129200 | T21: 833200 | U21: 3658000 | X21: Total Hotel | AO21: 70000 | AP21: 70000 | AQ21: 70000 | AS21: Total Hotel | BJ21: 70000 | BK21: 70000 | BL21: 70000
B22: Otra Red Búsqueda | C22: Interior - Río Negro | D22: 52500 | E22: 122000 | F22: 129000 | G22: 255000 | H22: 218000 | I22: 518000 | J22: 796260 | K22: 784000 | L22: 220000 | N22: 746000 | O22: 565000 | P22: 4405760 | R22: 185000 | S22: 493000 | T22: 678000 | U22: 5083760 | X22: Local Comercial | Y22: CABA | Z22: 83000 | AA22: 295000 | AE22: 240000 | AF22: 125000 | AH22: 45000 | AI22: 118000 | AJ22: 180000 | AL22: 1086000 | AQ22: 1086000 | AS22: Local Comercial | AT22: CABA | AU22: 83000 | AV22: 295000 | AZ22: 240000 | BA22: 125000 | BD22: 118000 | BE22: 180000 | BG22: 1041000 | BL22: 1041000
B23: Otra Red Búsqueda | C23: Interior - Salta | D23: 47000 | F23: 66000 | H23: 440000 | J23: 190000 | O23: 134000 | P23: 877000 | U23: 877000 | X23: Local Comercial | Y23: Zona Norte (GBA) | Z23: 42000 | AC23: 37500 | AG23: 95000 | AH23: 111000 | AK23: 144000 | AL23: 429500 | AQ23: 429500 | AS23: Local Comercial | AT23: Zona Norte (GBA) | BF23: 92000 | BG23: 92000 | BL23: 92000
B24: Otra Red Búsqueda | C24: Interior - Santa Fe | D24: 145000 | F24: 49500 | G24: 100000 | I24: 98500 | J24: 285600 | K24: 353000 | L24: 259000 | M24: 373000 | N24: 591500 | O24: 263000 | P24: 2518100 | R24: 262000 | S24: 177500 | T24: 439500 | U24: 2957600 | X24: Local Comercial | Y24: Zona Oeste (GBA) | AD24: 150000 | AL24: 150000 | AQ24: 150000 | AS24: Local Comercial | AT24: Zona Oeste (GBA) | AY24: 150000 | BG24: 150000 | BL24: 150000
B25: Otra Red Búsqueda | C25: Zona Norte (GBA) | G25: 575000 | H25: 58000 | J25: 636650 | K25: 1407500 | L25: 1985000 | M25: 4158050 | N25: 1646230 | O25: 2041500 | P25: 12507930 | Q25: 728000 | R25: 1175000 | S25: 3474500 | T25: 5377500 | U25: 17885430 | X25: Total Local Comercial | Z25: 125000 | AA25: 295000 | AC25: 37500 | AD25: 150000 | AE25: 240000 | AF25: 125000 | AG25: 95000 | AH25: 156000 | AI25: 118000 | AJ25: 180000 | AK25: 144000 | AL25: 1665500 | AQ25: 1665500 | AS25: Total Local Comercial | AU25: 83000 | AV25: 295000 | AY25: 150000 | AZ25: 240000 | BA25: 125000 | BD25: 118000 | BE25: 180000 | BF25: 92000 | BG25: 1283000 | BL25: 1283000
B26: Otra Red Búsqueda | C26: Zona Oeste (GBA) | F26: 216000 | J26: 176000 | K26: 65000 | M26: 132000 | P26: 589000 | S26: 63000 | T26: 63000 | U26: 652000 | X26: Oficina | Y26: CABA | AA26: 132500 | AD26: 85000 | AF26: 105000 | AK26: 42000 | AL26: 364500 | AM26: 55500 | AO26: 320000 | AP26: 375500 | AQ26: 740000 | AS26: Oficina | AT26: CABA | AV26: 132500 | AY26: 85000 | BA26: 105000 | BG26: 322500 | BJ26: 320000 | BK26: 320000 | BL26: 642500
B27: Otra Red Búsqueda | C27: Zona Sur (GBA) | D27: 114000 | E27: 160000 | G27: 195000 | H27: 378500 | I27: 107000 | J27: 493000 | K27: 634000 | L27: 145266 | M27: 45000 | O27: 104500 | P27: 2376266 | U27: 2376266 | X27: Oficina | Y27: Zona Norte (GBA) | AG27: 88830 | AJ27: 152000 | AL27: 240830 | AM27: 89000 | AO27: 81000 | AP27: 170000 | AQ27: 410830 | AS27: Oficina | AT27: Zona Norte (GBA) | BB27: 88830 | BE27: 152000 | BG27: 240830 | BH27: 89000 | BJ27: 81000 | BK27: 170000 | BL27: 410830
B28: Total Otra Red Búsqueda | D28: 2943500 | E28: 1759300 | F28: 1915000 | G28: 3177000 | H28: 3032000 | I28: 2980000 | J28: 4909010 | K28: 6466500 | L28: 5203266 | M28: 10903450 | N28: 6559730 | O28: 8369500 | P28: 58218256 | Q28: 2719500 | R28: 4448000 | S28: 8962450 | T28: 16129950 | U28: 74348206 | X28: Total Oficina | AA28: 132500 | AD28: 85000 | AF28: 105000 | AG28: 88830 | AJ28: 152000 | AK28: 42000 | AL28: 605330 | AM28: 144500 | AO28: 401000 | AP28: 545500 | AQ28: 1150830 | AS28: Total Oficina | AV28: 132500 | AY28: 85000 | BA28: 105000 | BB28: 88830 | BE28: 152000 | BG28: 563330 | BH28: 89000 | BJ28: 401000 | BK28: 490000 | BL28: 1053330
B29: Otra Red Captación | C29: CABA | D29: 619000 | E29: 2282000 | F29: 1476500 | G29: 1630500 | H29: 2193000 | I29: 2326500 | J29: 3359500 | K29: 3443000 | L29: 4349815 | M29: 3235000 | N29: 2545000 | O29: 4134200 | P29: 31594015 | Q29: 1450500 | R29: 1745000 | S29: 2451000 | T29: 5646500 | U29: 37240515 | X29: PH | Y29: CABA | Z29: 399000 | AA29: 148000 | AB29: 446000 | AC29: 658000 | AD29: 581000 | AE29: 925000 | AF29: 529500 | AG29: 798800 | AH29: 1385000 | AI29: 1248870 | AJ29: 608000 | AK29: 1361400 | AL29: 9088570 | AM29: 331000 | AN29: 593000 | AO29: 1459500 | AP29: 2383500 | AQ29: 11472070 | AS29: PH | AT29: CABA | AU29: 399000 | AV29: 148000 | AW29: 245000 | AX29: 611000 | AY29: 581000 | AZ29: 879000 | BA29: 423000 | BB29: 573000 | BC29: 1254000 | BD29: 1119870 | BE29: 608000 | BF29: 1296400 | BG29: 8137270 | BH29: 217000 | BI29: 593000 | BJ29: 1352500 | BK29: 2162500 | BL29: 10299770
B30: Otra Red Captación | C30: Interior - Mendoza | D30: 45000 | E30: 45000 | G30: 175000 | I30: 66600 | J30: 220000 | N30: 53000 | O30: 966700 | P30: 1571300 | Q30: 67000 | R30: 278000 | S30: 155000 | T30: 500000 | U30: 2071300 | X30: PH | Y30: Zona Norte (GBA) | Z30: 201500 | AA30: 209000 | AB30: 49000 | AC30: 250000 | AD30: 195000 | AE30: 443000 | AF30: 152000 | AG30: 404500 | AH30: 356000 | AI30: 52000 | AJ30: 252000 | AK30: 270000 | AL30: 2834000 | AM30: 55000 | AN30: 118000 | AO30: 150000 | AP30: 323000 | AQ30: 3157000 | AS30: PH | AT30: Zona Norte (GBA) | AU30: 165000 | AV30: 145000 | AX30: 250000 | AY30: 130000 | AZ30: 443000 | BA30: 84000 | BB30: 354500 | BC30: 356000 | BE30: 252000 | BF30: 270000 | BG30: 2449500 | BI30: 118000 | BJ30: 103000 | BK30: 221000 | BL30: 2670500
B31: Otra Red Captación | C31: Interior - Neuquén | D31: 224000 | E31: 185000 | F31: 380000 | G31: 333000 | H31: 90000 | I31: 376000 | J31: 63000 | K31: 220000 | L31: 1104000 | O31: 162000 | P31: 3137000 | R31: 706000 | S31: 165000 | T31: 871000 | U31: 4008000 | X31: PH | Y31: Zona Oeste (GBA) | AF31: 48500 | AG31: 112000 | AL31: 160500 | AM31: 40000 | AP31: 40000 | AQ31: 200500 | AS31: Total PH | AU31: 564000 | AV31: 293000 | AW31: 245000 | AX31: 861000 | AY31: 711000 | AZ31: 1322000 | BA31: 507000 | BB31: 927500 | BC31: 1610000 | BD31: 1119870 | BE31: 860000 | BF31: 1566400 | BG31: 10586770 | BH31: 217000 | BI31: 711000 | BJ31: 1455500 | BK31: 2383500 | BL31: 12970270
B32: Otra Red Captación | C32: Interior - Río Negro | G32: 615000 | H32: 133000 | I32: 45000 | J32: 98000 | K32: 55000 | L32: 318000 | N32: 170000 | O32: 361000 | P32: 1795000 | Q32: 181000 | S32: 93000 | T32: 274000 | U32: 2069000 | X32: PH | Y32: Zona Sur (GBA) | AE32: 58000 | AL32: 58000 | AQ32: 58000 | AS32: Storage | AT32: CABA | AX32: 229000 | BA32: 190000 | BF32: 135000 | BG32: 554000 | BL32: 554000
B33: Otra Red Captación | C33: Interior - Salta | E33: 157500 | H33: 72000 | I33: 241000 | K33: 620000 | L33: 66000 | M33: 40000 | N33: 115000 | O33: 187000 | P33: 1498500 | Q33: 100000 | S33: 89000 | T33: 189000 | U33: 1687500 | X33: Total PH | Z33: 600500 | AA33: 357000 | AB33: 495000 | AC33: 908000 | AD33: 776000 | AE33: 1426000 | AF33: 730000 | AG33: 1315300 | AH33: 1741000 | AI33: 1300870 | AJ33: 860000 | AK33: 1631400 | AL33: 12141070 | AM33: 426000 | AN33: 711000 | AO33: 1609500 | AP33: 2746500 | AQ33: 14887570 | AS33: Storage | AT33: Zona Norte (GBA) | AZ33: 99000 | BG33: 99000 | BL33: 99000
B34: Otra Red Captación | C34: Interior - Santa Fe | D34: 152000 | E34: 180000 | G34: 53000 | I34: 90000 | J34: 40000 | K34: 204000 | L34: 60000 | O34: 135200 | P34: 914200 | Q34: 266000 | R34: 93000 | S34: 124500 | T34: 483500 | U34: 1397700 | X34: Storage | Y34: CABA | Z34: 45000 | AC34: 229000 | AF34: 190000 | AK34: 135000 | AL34: 599000 | AO34: 58000 | AP34: 58000 | AQ34: 657000 | AS34: Total Storage | AX34: 229000 | AZ34: 99000 | BA34: 190000 | BF34: 135000 | BG34: 653000 | BL34: 653000
B35: Otra Red Captación | C35: Zona Norte (GBA) | D35: 860200 | E35: 562000 | F35: 1622000 | G35: 2362500 | H35: 1550622 | I35: 994500 | J35: 1010733 | K35: 525500 | L35: 963000 | M35: 771000 | N35: 431000 | O35: 50000 | P35: 11703055 | Q35: 290000 | R35: 238000 | S35: 97000 | T35: 625000 | U35: 12328055 | X35: Storage | Y35: Zona Norte (GBA) | AE35: 99000 | AL35: 99000 | AQ35: 99000 | AS35: Terreno | AT35: CABA | AU35: 372000 | AV35: 327000 | AW35: 669000 | AX35: 385000 | AY35: 148000 | AZ35: 750000 | BA35: 371800 | BB35: 350000 | BC35: 71500 | BD35: 167000 | BE35: 550000 | BF35: 150000 | BG35: 4311300 | BH35: 675600 | BI35: 85000 | BJ35: 426000 | BK35: 1186600 | BL35: 5497900
B36: Otra Red Captación | C36: Zona Oeste (GBA) | F36: 150000 | K36: 172000 | N36: 335000 | O36: 131000 | P36: 788000 | S36: 69000 | T36: 69000 | U36: 857000 | X36: Total Storage | Z36: 45000 | AC36: 229000 | AE36: 99000 | AF36: 190000 | AK36: 135000 | AL36: 698000 | AO36: 58000 | AP36: 58000 | AQ36: 756000 | AS36: Terreno | AT36: Zona Norte (GBA) | AU36: 530010 | AV36: 665000 | AW36: 500000 | AX36: 915000 | AY36: 134540 | AZ36: 170000 | BB36: 160000 | BC36: 1547100 | BD36: 82350 | BE36: 508578 | BG36: 5212578 | BH36: 428500 | BI36: 205000 | BJ36: 125000 | BK36: 758500 | BL36: 5971078
B37: Otra Red Captación | C37: Zona Sur (GBA) | F37: 221000 | G37: 46500 | H37: 355000 | I37: 240500 | M37: 462500 | O37: 179000 | P37: 1504500 | R37: 36000 | S37: 255900 | T37: 291900 | U37: 1796400 | X37: Terreno | Y37: CABA | Z37: 372000 | AA37: 391000 | AB37: 720000 | AC37: 433500 | AD37: 211500 | AE37: 750000 | AF37: 426750 | AG37: 350000 | AH37: 120500 | AI37: 224000 | AJ37: 550000 | AK37: 186000 | AL37: 4735250 | AM37: 675600 | AN37: 85000 | AO37: 1891906 | AP37: 2652506 | AQ37: 7387756 | AS37: Total Terreno | AU37: 902010 | AV37: 992000 | AW37: 1169000 | AX37: 1300000 | AY37: 282540 | AZ37: 920000 | BA37: 371800 | BB37: 510000 | BC37: 1618600 | BD37: 249350 | BE37: 1058578 | BF37: 150000 | BG37: 9523878 | BH37: 1104100 | BI37: 290000 | BJ37: 551000 | BK37: 1945100 | BL37: 11468978
B38: Total Otra Red Captación | D38: 1900200 | E38: 3411500 | F38: 3849500 | G38: 5215500 | H38: 4393622 | I38: 4380100 | J38: 4791233 | K38: 5239500 | L38: 6860815 | M38: 4508500 | N38: 3649000 | O38: 6306100 | P38: 54505570 | Q38: 2354500 | R38: 3096000 | S38: 3499400 | T38: 8949900 | U38: 63455470 | X38: Terreno | Y38: Zona Norte (GBA) | Z38: 573330 | AA38: 665000 | AB38: 537000 | AC38: 1004500 | AD38: 221540 | AE38: 170000 | AF38: 42000 | AG38: 217000 | AH38: 1594650 | AI38: 82350 | AJ38: 567023 | AL38: 5674393 | AM38: 428500 | AN38: 205000 | AO38: 223000 | AP38: 856500 | AQ38: 6530893 | AS38: Total general | AU38: 8639099 | AV38: 8452484 | AW38: 11709589 | AX38: 15049400 | AY38: 13552610 | AZ38: 15069750 | BA38: 14554928 | BB38: 14151430 | BC38: 12307980 | BD38: 12757176 | BE38: 9038108 | BF38: 11016582 | BG38: 146299136 | BH38: 11670350 | BI38: 10704297 | BJ38: 15163000 | BK38: 37537647 | BL38: 183836783
B39: Total general | D39: 16402341 | E39: 17392628 | F39: 20793899 | G39: 28262159 | H39: 28727234 | I39: 27962817 | J39: 29721721 | K39: 31988810 | L39: 30488611 | M39: 33531526 | N39: 21589719 | O39: 32989167 | P39: 319850632 | Q39: 20955375 | R39: 22040697 | S39: 36289595 | T39: 79285667 | U39: 399136299 | X39: Total Terreno | Z39: 945330 | AA39: 1056000 | AB39: 1257000 | AC39: 1438000 | AD39: 433040 | AE39: 920000 | AF39: 468750 | AG39: 567000 | AH39: 1715150 | AI39: 306350 | AJ39: 1117023 | AK39: 186000 | AL39: 10409643 | AM39: 1104100 | AN39: 290000 | AO39: 2114906 | AP39: 3509006 | AQ39: 13918649
X40: Total general | Z40: 9062919 | AA40: 9046484 | AB40: 12607089 | AC40: 15981400 | AD40: 14357610 | AE40: 16844750 | AF40: 16210878 | AG40: 15282730 | AH40: 13505530 | AI40: 13949176 | AJ40: 10082989 | AK40: 13140282 | AL40: 160071837 | AM40: 12499750 | AN40: 11538797 | AO40: 17696406 | AP40: 41734953 | AQ40: 201806790
...

Sheet Operaciones Venta
A1: Fecha | B1: AÑO | C1: MES | D1: Ref # | E1: Unificador | F1: Publicación | G1: Estado | H1: Portal | I1: Precio Publicación | J1: Precio Cierre Total | K1: RANGO_TCMC | L1: Moneda Cierre | M1: Moneda Publicación | N1: Dirección | O1: Ubicación | P1: Tipo Propiedad | Q1: Lados | R1: Oficina | S1: Tipo Operación | T1: TIPO_OPERACION2 | U1: Operación | V1: Zona CB | W1: Localidad CB
A2: 46062 | B2: =YEAR($A2) -> 2026 | C2: =MONTH($A2) -> 2 | D2: CAP7557679 | E2: 1 | F2: Venta departamento de un dormitorio y balcón en 4 y 63 - LA PLATA | G2: Realizado | H2: AR ZonaProp | I2: 38000 | J2: 36000 | K2: =IF(J2<'Mapa Oficinas'!$I$21,0,IF(J2>'Mapa Oficinas'!$I$20,0,1)) -> 0 | L2: Dólares | M2: Dólares | N2: Venta departamento de un dormitorio y balcón en 4 y 63 - LA PLATA | O2: Argentina | G.B.A. Zona Sur | La Plata | La Plata | P2: Departamento | Q2: 1 | R2: Golden Team | S2: (Interior) Compartida Fuera de la Red Captación Propia | T2: =VLOOKUP(S2,'Mapa Oficinas'!$H$7:$I$16,2,FALSE) -> Otra Red Captación | U2: Venta | V2: =VLOOKUP($R2,'Mapa Oficinas'!$A$7:$C$46,2,FALSE) -> Zona Sur (GBA) | W2: =VLOOKUP($R2,'Mapa Oficinas'!$A$7:$C$46,3,FALSE) -> La Plata
A3: 45863 | B3: =YEAR($A3) -> 2025 | C3: =MONTH($A3) -> 7 | E3: 0 | F3: UF 13 Loteo A Quetrihue 387,55 | G3: Realizado | H3: Conocido | I3: 36000 | J3: 36000 | K3: =IF(J3<'Mapa Oficinas'!$I$21,0,IF(J3>'Mapa Oficinas'!$I$20,0,1)) -> 0 | L3: Dólares | M3: Dólares | N3: Bv, Quetrihue y Amancay | O3: Argentina | Neuquen | Villa La Angostura | Selva Triste | P3: Terreno | Q3: 2 | R3: Patagonia Lakes VLA | S3: Compartida en Oficina (Dos Asesores) | T3: =VLOOKUP(S3,'Mapa Oficinas'!$H$7:$I$16,2,FALSE) -> CB | U3: Venta | V3: =VLOOKUP($R3,'Mapa Oficinas'!$A$7:$C$46,2,FALSE) -> Interior - Neuquén | W3: =VLOOKUP($R3,'Mapa Oficinas'!$A$7:$C$46,3,FALSE) -> Villa La Angostura
A4: 45699 | B4: =YEAR($A4) -> 2025 | C4: =MONTH($A4) -> 2 | D4: CLA6351991 | E4: 1 | F4: VENTA Lote/terreno de 407,04 m2, UF 26 loteo Quetrihue B° Selva Triste Villa la Angostura | G4: Realizado | H4: Instagram | I4: 36000 | J4: 36000 | K4: =IF(J4<'Mapa Oficinas'!$I$21,0,IF(J4>'Mapa Oficinas'!$I$20,0,1)) -> 0 | L4: Dólares | M4: Dólares | N4: Quetrihue | O4: Argentina | Neuquen | Villa La Angostura | Puerto | P4: Terreno | Q4: 2 | R4: Patagonia Lakes VLA | S4: Compartida en Oficina (Dos Asesores) | T4: =VLOOKUP(S4,'Mapa Oficinas'!$H$7:$I$16,2,FALSE) -> CB | U4: Venta | V4: =VLOOKUP($R4,'Mapa Oficinas'!$A$7:$C$46,2,FALSE) -> Interior - Neuquén | W4: =VLOOKUP($R4,'Mapa Oficinas'!$A$7:$C$46,3,FALSE) -> Villa La Angostura
A5: 45796 | B5: =YEAR($A5) -> 2025 | C5: =MONTH($A5) -> 5 | D5: CHO6746075 | E5: 1 | F5: Casa - Las Paredes | G5: Realizado | H5: AR ZonaProp | I5: 36000 | J5: 36000 | K5: =IF(J5<'Mapa Oficinas'!$I$21,0,IF(J5>'Mapa Oficinas'!$I$20,0,1)) -> 0 | L5: Dólares | M5: Dólares | N5: LOS FILTROS al 8000 | O5: Argentina | Mendoza | San Rafael | Las Paredes | P5: Casa | Q5: 2 | R5: Andes | S5: Compartida en Oficina (Dos Asesores) | T5: =VLOOKUP(S5,'Mapa Oficinas'!$H$7:$I$16,2,FALSE) -> CB | U5: Venta | V5: =VLOOKUP($R5,'Mapa Oficinas'!$A$7:$C$46,2,FALSE) -> Interior - Mendoza | W5: =VLOOKUP($R5,'Mapa Oficinas'!$A$7:$C$46,3,FALSE) -> San Rafael
A6: 45862 | B6: =YEAR($A6) -> 2025 | C6: =MONTH($A6) -> 7 | D6: CAP6796724 | E6: 1 | F6: Departamento en almagro | G6: Realizado | H6: AR ZonaProp | I6: 37000 | J6: 36000 | K6: =IF(J6<'Mapa Oficinas'!$I$21,0,IF(J6>'Mapa Oficinas'!$I$20,0,1)) -> 0 | L6: Dólares | M6: Dólares | N6: Quintino Bocayuva al 400 | O6: Argentina | Capital Federal | Almagro | Almagro Sur | P6: Departamento | Q6: 2 | R6: Haka | S6: Compartida en Oficina (Dos Asesores) | T6: =VLOOKUP(S6,'Mapa Oficinas'!$H$7:$I$16,2,FALSE) -> CB | U6: Venta | V6: =VLOOKUP($R6,'Mapa Oficinas'!$A$7:$C$46,2,FALSE) -> CABA | W6: =VLOOKUP($R6,'Mapa Oficinas'!$A$7:$C$46,3,FALSE) -> Núñez
A7: 45863 | B7: =YEAR($A7) -> 2025 | C7: =MONTH($A7) -> 7 | E7: 1 | F7: UF 12 Loteo A Quetrihue | G7: Realizado | H7: Conocido | I7: 36000 | J7: 36000 | K7: =IF(J7<'Mapa Oficinas'!$I$21,0,IF(J7>'Mapa Oficinas'!$I$20,0,1)) -> 0 | L7: Dólares | M7: Dólares | N7: Bv, Quetrihue y Amancay | O7: Argentina | Neuquen | Villa La Angostura | Selva Triste | P7: Terreno | Q7: 2 | R7: Patagonia Lakes VLA | S7: Compartida en Oficina (Dos Asesores) | T7: =VLOOKUP(S7,'Mapa Oficinas'!$H$7:$I$16,2,FALSE) -> CB | U7: Venta | V7: =VLOOKUP($R7,'Mapa Oficinas'!$A$7:$C$46,2,FALSE) -> Interior - Neuquén | W7: =VLOOKUP($R7,'Mapa Oficinas'!$A$7:$C$46,3,FALSE) -> Villa La Angostura
A8: 45777 | B8: =YEAR($A8) -> 2025 | C8: =MONTH($A8) -> 4 | D8: CAP6917146 | E8: 1 | F8: Departamento | Venta | Juan Pablo II | 3 habitaciones | G8: Realizado | H8: Facebook | I8: 36000 | J8: 36000 | K8: =IF(J8<'Mapa Oficinas'!$I$21,0,IF(J8>'Mapa Oficinas'!$I$20,0,1)) -> 0 | L8: Dólares | M8: Dólares | N8: Juan Pablo II 7 | O8: Argentina | Salta | Capital | Salta | Zona Sur | P8: Departamento | Q8: 2 | R8: Realty Group | S8: Propia (Único Asesor) | T8: =VLOOKUP(S8,'Mapa Oficinas'!$H$7:$I$16,2,FALSE) -> CB | U8: Venta | V8: =VLOOKUP($R8,'Mapa Oficinas'!$A$7:$C$46,2,FALSE) -> Interior - Salta | W8: =VLOOKUP($R8,'Mapa Oficinas'!$A$7:$C$46,3,FALSE) -> San Lorenzo Chico
A9: 45827 | B9: =YEAR($A9) -> 2025 | C9: =MONTH($A9) -> 6 | D9: CAP6916550 | E9: 1 | F9: Departamento en Juan Pablo | G9: Realizado | H9: Referido | I9: 36000 | J9: 36000 | K9: =IF(J9<'Mapa Oficinas'!$I$21,0,IF(J9>'Mapa Oficinas'!$I$20,0,1)) -> 0 | L9: Dólares | M9: Dólares | N9: Juan Pablo | O9: Argentina | Salta | Capital | Salta | Zona Sur | P9: Departamento | Q9: 2 | R9: Realty Group | S9: Propia (Único Asesor) | T9: =VLOOKUP(S9,'Mapa Oficinas'!$H$7:$I$16,2,FALSE) -> CB | U9: Venta | V9: =VLOOKUP($R9,'Mapa Oficinas'!$A$7:$C$46,2,FALSE) -> Interior - Salta | W9: =VLOOKUP($R9,'Mapa Oficinas'!$A$7:$C$46,3,FALSE) -> San Lorenzo Chico
A10: 45882 | B10: =YEAR($A10) -> 2025 | C10: =MONTH($A10) -> 8 | D10: CAP7166417 | E10: 1 | F10: Departamento de 1 dormitorio en 45 e/ 19 y 20, La Plata | G10: Realizado | H10: AR ArgenProp | I10: 37000 | J10: 36000 | K10: =IF(J10<'Mapa Oficinas'!$I$21,0,IF(J10>'Mapa Oficinas'!$I$20,0,1)) -> 0 | L10: Dólares | M10: Dólares | N10: 45 e/ 19 y 20 | O10: Argentina | G.B.A. Zona Sur | La Plata | La Plata | P10: Departamento | Q10: 2 | R10: Golden Team | S10: Propia (Único Asesor) | T10: =VLOOKUP(S10,'Mapa Oficinas'!$H$7:$I$16,2,FALSE) -> CB | U10: Venta | V10: =VLOOKUP($R10,'Mapa Oficinas'!$A$7:$C$46,2,FALSE) -> Zona Sur (GBA) | W10: =VLOOKUP($R10,'Mapa Oficinas'!$A$7:$C$46,3,FALSE) -> La Plata
A11: 45889 | B11: =YEAR($A11) -> 2025 | C11: =MONTH($A11) -> 8 | D11: CAP7214043 | E11: 1 | F11: Departamento en Venta de 1 dormitorio en 46 entre 13 y 14 en La Plata | G11: Realizado | H11: AR ZonaProp | I11: 39900 | J11: 36000 | K11: =IF(J11<'Mapa Oficinas'!$I$21,0,IF(J11>'Mapa Oficinas'!$I$20,0,1)) -> 0 | L11: Dólares | M11: Dólares | N11: Departamento en Venta de 1 dormitorio en 46 entre 13 y 14 en La Plata | O11: Argentina | G.B.A. Zona Sur | La Plata | La Plata | P11: Departamento | Q11: 2 | R11: Golden Team | S11: Propia (Único Asesor) | T11: =VLOOKUP(S11,'Mapa Oficinas'!$H$7:$I$16,2,FALSE) -> CB | U11: Venta | V11: =VLOOKUP($R11,'Mapa Oficinas'!$A$7:$C$46,2,FALSE) -> Zona Sur (GBA) | W11: =VLOOKUP($R11,'Mapa Oficinas'!$A$7:$C$46,3,FALSE) -> La Plata
A12: 45889 | B12: =YEAR($A12) -> 2025 | C12: =MONTH($A12) -> 8 | D12: CLA7090806 | E12: 1 | F12: Terreno en venta ubicado en La Verbena - Salta | G12: Realizado | H12: Facebook | I12: 37500 | J12: 36000 | K12: =IF(J12<'Mapa Oficinas'!$I$21,0,IF(J12>'Mapa Oficinas'!$I$20,0,1)) -> 0 | L12: Dólares | M12: Dólares | N12: La Verbena Calle 8 | O12: Argentina | Salta | Capital | Salta | Zona Sur | P12: Terreno | Q12: 2 | R12: Realty Group | S12: Propia (Único Asesor) | T12: =VLOOKUP(S12,'Mapa Oficinas'!$H$7:$I$16,2,FALSE) -> CB | U12: Venta | V12: =VLOOKUP($R12,'Mapa Oficinas'!$A$7:$C$46,2,FALSE) -> Interior - Salta | W12: =VLOOKUP($R12,'Mapa Oficinas'!$A$7:$C$46,3,FALSE) -> San Lorenzo Chico
A13: 45911 | B13: =YEAR($A13) -> 2025 | C13: =MONTH($A13) -> 9 | D13: CLA6972631 | E13: 1 | F13: Terreno en Las Paredes, San Rafael | G13: Realizado | H13: AR ZonaProp | I13: 40000 | J13: 36000 | K13: =IF(J13<'Mapa Oficinas'!$I$21,0,IF(J13>'Mapa Oficinas'!$I$20,0,1)) -> 0 | L13: Dólares | M13: Dólares | N13: zamarvide al 600 | O13: Argentina | Mendoza | San Rafael | Las Paredes | P13: Terreno | Q13: 2 | R13: Andes | S13: Propia (Único Asesor) | T13: =VLOOKUP(S13,'Mapa Oficinas'!$H$7:$I$16,2,FALSE) -> CB | U13: Venta | V13: =VLOOKUP($R13,'Mapa Oficinas'!$A$7:$C$46,2,FALSE) -> Interior - Mendoza | W13: =VLOOKUP($R13,'Mapa Oficinas'!$A$7:$C$46,3,FALSE) -> San Rafael
A14: 45978 | B14: =YEAR($A14) -> 2025 | C14: =MONTH($A14) -> 11 | D14: CHO7388867 | E14: 1 | F14: Casa en venta a reciclar 158 entre 67 y 68 Los Hornos | G14: Realizado | H14: AR ZonaProp | I14: 35000 | J14: 36000 | K14: =IF(J14<'Mapa Oficinas'!$I$21,0,IF(J14>'Mapa Oficinas'!$I$20,0,1)) -> 0 | L14: Dólares | M14: Dólares | N14: 158 entre 67 y 68 | O14: Argentina | G.B.A. Zona Sur | La Plata | Los Hornos | P14: Casa | Q14: 2 | R14: Golden Team | S14: Propia (Único Asesor) | T14: =VLOOKUP(S14,'Mapa Oficinas'!$H$7:$I$16,2,FALSE) -> CB | U14: Venta | V14: =VLOOKUP($R14,'Mapa Oficinas'!$A$7:$C$46,2,FALSE) -> Zona Sur (GBA) | W14: =VLOOKUP($R14,'Mapa Oficinas'!$A$7:$C$46,3,FALSE) -> La Plata
A15: 45986 | B15: =YEAR($A15) -> 2025 | C15: =MONTH($A15) -> 11 | D15: CLA7046370 | E15: 1 | F15: VENTA Lote Villa Meliquina 1000m2 Oportunidad lote 4 MANZANA J | G15: Realizado | H15: Web Coldwell-Banker | I15: 38500 | J15: 36000 | K15: =IF(J15<'Mapa Oficinas'!$I$21,0,IF(J15>'Mapa Oficinas'!$I$20,0,1)) -> 0 | L15: Dólares | M15: Dólares | N15: meliquina | O15: Argentina | Neuquen | Lacar | San Martin De Los Andes | Villa Lago Meliquina | P15: Terreno | Q15: 2 | R15: Patagonia Lakes SMA | S15: Propia (Único Asesor) | T15: =VLOOKUP(S15,'Mapa Oficinas'!$H$7:$I$16,2,FALSE) -> CB | U15: Venta | V15: =VLOOKUP($R15,'Mapa Oficinas'!$A$7:$C$46,2,FALSE) -> Interior - Neuquén | W15: =VLOOKUP($R15,'Mapa Oficinas'!$A$7:$C$46,3,FALSE) -> San Martín de los Andes
A16: 45995 | B16: =YEAR($A16) -> 2025 | C16: =MONTH($A16) -> 12 | D16: CLA7597779 | E16: 1 | F16: Terreno en Zona Sur | G16: Realizado | H16: Facebook | I16: 37000 | J16: 36000 | K16: =IF(J16<'Mapa Oficinas'!$I$21,0,IF(J16>'Mapa Oficinas'!$I$20,0,1)) -> 0 | L16: Dólares | M16: Dólares | N16: La Verbena, calle 18 | O16: Argentina | Salta | Capital | Salta | Zona Sur | P16: Terreno | Q16: 2 | R16: Realty Group | S16: Propia (Único Asesor) | T16: =VLOOKUP(S16,'Mapa Oficinas'!$H$7:$I$16,2,FALSE) -> CB | U16: Venta | V16: =VLOOKUP($R16,'Mapa Oficinas'!$A$7:$C$46,2,FALSE) -> Interior - Salta | W16: =VLOOKUP($R16,'Mapa Oficinas'!$A$7:$C$46,3,FALSE) -> San Lorenzo Chico
A17: 45996 | B17: =YEAR($A17) -> 2025 | C17: =MONTH($A17) -> 12 | D17: san eliseo golf 414 | E17: 1 | F17: lote venta san elíseo golf 414 | G17: Realizado | H17: AR MercadoLibre | I17: 36000 | J17: 36000 | K17: =IF(J17<'Mapa Oficinas'!$I$21,0,IF(J17>'Mapa Oficinas'!$I$20,0,1)) -> 0 | L17: Dólares | M17: Dólares | O17: Argentina | G.B.A. Zona Sur | San Vicente | P17: Terreno | Q17: 2 | R17: Livello | S17: Propia (Único Asesor) | T17: =VLOOKUP(S17,'Mapa Oficinas'!$H$7:$I$16,2,FALSE) -> CB | U17: Venta | V17: =VLOOKUP($R17,'Mapa Oficinas'!$A$7:$C$46,2,FALSE) -> CABA | W17: =VLOOKUP($R17,'Mapa Oficinas'!$A$7:$C$46,3,FALSE) -> Palermo
A18: 46090 | B18: =YEAR($A18) -> 2026 | C18: =MONTH($A18) -> 3 | D18: CLA7470286 | E18: 1 | F18: Venta terreno en las heras | G18: Realizado | H18: AR ZonaProp | I18: 40000 | J18: 36000 | K18: =IF(J18<'Mapa Oficinas'!$I$21,0,IF(J18>'Mapa Oficinas'!$I$20,0,1)) -> 0 | L18: Dólares | M18: Dólares | N18: Belgrano al 700 | O18: Argentina | Mendoza | Las Heras | P18: Casa | Q18: 2 | R18: Cuyo Real | S18: Propia (Único Asesor) | T18: =VLOOKUP(S18,'Mapa Oficinas'!$H$7:$I$16,2,FALSE) -> CB | U18: Venta | V18: =VLOOKUP($R18,'Mapa Oficinas'!$A$7:$C$46,2,FALSE) -> Interior - Mendoza | W18: =VLOOKUP($R18,'Mapa Oficinas'!$A$7:$C$46,3,FALSE) -> Capital Mendoza
A19: 46092 | B19: =YEAR($A19) -> 2026 | C19: =MONTH($A19) -> 3 | D19: CLA7762823 | E19: 1 | F19: Excelente Terreno en Venta | G19: Realizado | H19: Conocido | I19: 36000 | J19: 36000 | K19: =IF(J19<'Mapa Oficinas'!$I$21,0,IF(J19>'Mapa Oficinas'!$I$20,0,1)) -> 0 | L19: Dólares | M19: Dólares | N19: Terreno en Colastine Norte sobre calle Los Algarrobos | O19: Argentina | Santa Fe | La Capital | Santa Fe | Colastine Norte | P19: Terreno | Q19: 2 | R19: De la Veracruz | S19: Propia (Único Asesor) | T19: =VLOOKUP(S19,'Mapa Oficinas'!$H$7:$I$16,2,FALSE) -> CB | U19: Venta | V19: =VLOOKUP($R19,'Mapa Oficinas'!$A$7:$C$46,2,FALSE) -> Interior - Santa Fe | W19: =VLOOKUP($R19,'Mapa Oficinas'!$A$7:$C$46,3,FALSE) -> Capital Santa Fe
A20: 46100 | B20: =YEAR($A20) -> 2026 | C20: =MONTH($A20) -> 3 | E20: 1 | F20: Lote, con superficie aproximada de 860 m2, ubicado en el Barrio El Remanso, de la ciudad de San Martin de Los andes Pcia. De Neuquén, nomenclaturas catastrales (lotes madres): 15 RR 023 5026 / 5028, identificado internamente como LOTE RE12 | G20: Realizado | H20: Conocido | I20: 36000 | J20: 36000 | K20: =IF(J20<'Mapa Oficinas'!$I$21,0,IF(J20>'Mapa Oficinas'!$I$20,0,1)) -> 0 | L20: Dólares | M20: Dólares | O20: Argentina | Neuquen | Lacar | San Martin De Los Andes | P20: Terreno | Q20: 2 | R20: Patagonia Lakes SMA | S20: Propia (Único Asesor) | T20: =VLOOKUP(S20,'Mapa Oficinas'!$H$7:$I$16,2,FALSE) -> CB | U20: Venta | V20: =VLOOKUP($R20,'Mapa Oficinas'!$A$7:$C$46,2,FALSE) -> Interior - Neuquén | W20: =VLOOKUP($R20,'Mapa Oficinas'!$A$7:$C$46,3,FALSE) -> San Martín de los Andes
A21: 45733 | B21: =YEAR($A21) -> 2025 | C21: =MONTH($A21) -> 3 | D21: CLA6351973 | E21: 1 | F21: VENTA Lote/terreno de 407,04 m2, UF 25 loteo Quetrihue B° Selva Triste Villa la Angostura | G21: Realizado | H21: Conocido | I21: 38000 | J21: 36500 | K21: =IF(J21<'Mapa Oficinas'!$I$21,0,IF(J21>'Mapa Oficinas'!$I$20,0,1)) -> 0 | L21: Dólares | M21: Dólares | N21: Quetrihue | O21: Argentina | Neuquen | Villa La Angostura | Selva Triste | P21: Terreno | Q21: 2 | R21: Patagonia Lakes VLA | S21: Compartida en Oficina (Dos Asesores) | T21: =VLOOKUP(S21,'Mapa Oficinas'!$H$7:$I$16,2,FALSE) -> CB | U21: Venta | V21: =VLOOKUP($R21,'Mapa Oficinas'!$A$7:$C$46,2,FALSE) -> Interior - Neuquén | W21: =VLOOKUP($R21,'Mapa Oficinas'!$A$7:$C$46,3,FALSE) -> Villa La Angostura
A22: 45741 | B22: =YEAR($A22) -> 2025 | C22: =MONTH($A22) -> 3 | D22: CLA6399702 | E22: 1 | F22: Terreno 300 m2 Confluencia Neuquén | G22: Realizado | H22: AR ZonaProp | I22: 37000 | J22: 36500 | K22: =IF(J22<'Mapa Oficinas'!$I$21,0,IF(J22>'Mapa Oficinas'!$I$20,0,1)) -> 0 | L22: Dólares | M22: Dólares | N22: Venta terreno 300 m2 Confluencia Neuquén | O22: Argentina | Neuquen | Confluencia | Neuquen | P22: Terreno | Q22: 2 | R22: Sensus | S22: Compartida en Oficina (Dos Asesores) | T22: =VLOOKUP(S22,'Mapa Oficinas'!$H$7:$I$16,2,FALSE) -> CB | U22: Venta | V22: =VLOOKUP($R22,'Mapa Oficinas'!$A$7:$C$46,2,FALSE) -> Interior - Neuquén | W22: =VLOOKUP($R22,'Mapa Oficinas'!$A$7:$C$46,3,FALSE) -> Capital Neuquén
A23: 45726 | B23: =YEAR($A23) -> 2025 | C23: =MONTH($A23) -> 3 | D23: Lote en carrodilla | E23: 1 | F23: Lote con obra gruesa en carrodilla | G23: Realizado | H23: Conocido | I23: 36500 | J23: 36500 | K23: =IF(J23<'Mapa Oficinas'!$I$21,0,IF(J23>'Mapa Oficinas'!$I$20,0,1)) -> 0 | L23: Dólares | M23: Dólares | O23: Argentina | Mendoza | Lujan De Cuyo | Lujan De Cuyo | Carrodilla | P23: Terreno | Q23: 1 | R23: Cuyo Real | S23: Compartida Fuera de la Red Búsqueda | T23: =VLOOKUP(S23,'Mapa Oficinas'!$H$7:$I$16,2,FALSE) -> Otra Red Búsqueda | U23: Venta | V23: =VLOOKUP($R23,'Mapa Oficinas'!$A$7:$C$46,2,FALSE) -> Interior - Mendoza | W23: =VLOOKUP($R23,'Mapa Oficinas'!$A$7:$C$46,3,FALSE) -> Capital Mendoza
A24: 45881 | B24: =YEAR($A24) -> 2025 | C24: =MONTH($A24) -> 8 | D24: CAP7303870 | E24: 0 | F24: Monoambiente en venta calle Constitución 1950 B San Cristóbal | G24: Realizado | H24: Referido | I24: 36500 | J24: 36500 | K24: =IF(J24<'Mapa Oficinas'!$I$21,0,IF(J24>'Mapa Oficinas'!$I$20,0,1)) -> 0 | L24: Dólares | M24: Dólares | N24: Monoambiente en venta calle Constitución 1950 B San Cristóbal | O24: Argentina | Capital Federal | San Cristobal | P24: Departamento | Q24: 2 | R24: Golden Team | S24: Profesional Referenciador (30%) | T24: =VLOOKUP(S24,'Mapa Oficinas'!$H$7:$I$16,2,FALSE) -> CB | U24: Venta | V24: =VLOOKUP($R24,'Mapa Oficinas'!$A$7:$C$46,2,FALSE) -> Zona Sur (GBA) | W24: =VLOOKUP($R24,'Mapa Oficinas'!$A$7:$C$46,3,FALSE) -> La Plata
A25: 45856 | B25: =YEAR($A25) -> 2025 | C25: =MONTH($A25) -> 7 | D25: CAP6894585 | E25: 1 | F25: VENTA MONOAMBIENTE SAN CRISTOBAL -APTO CREDITO- OPORTUNIDAD | G25: Realizado | H25: AR ZonaProp | I25: 38000 | J25: 36500 | K25: =IF(J25<'Mapa Oficinas'!$I$21,0,IF(J25>'Mapa Oficinas'!$I$20,0,1)) -> 0 | L25: Dólares | M25: Dólares | N25: Constitucion al 1900 | O25: Argentina | Capital Federal | San Cristobal | P25: Departamento | Q25: 2 | R25: Seniority | S25: Profesional Referido (70%) | T25: =VLOOKUP(S25,'Mapa Oficinas'!$H$7:$I$16,2,FALSE) -> CB | U25: Venta | V25: =VLOOKUP($R25,'Mapa Oficinas'!$A$7:$C$46,2,FALSE) -> CABA | W25: =VLOOKUP($R25,'Mapa Oficinas'!$A$7:$C$46,3,FALSE) -> Barrio Parque
A26: 45674 | B26: =YEAR($A26) -> 2025 | C26: =MONTH($A26) -> 1 | D26: Pola 2800 | E26: 1 | F26: POLA 2855 DPTO 3 | G26: Realizado | H26: AR ZonaProp | I26: 36500 | J26: 36500 | K26: =IF(J26<'Mapa Oficinas'!$I$21,0,IF(J26>'Mapa Oficinas'!$I$20,0,1)) -> 0 | L26: Dólares | M26: Dólares | N26: POLA 2855 DPTO 3 | O26: Argentina | Capital Federal | Villa Lugano | P26: PH | Q26: 2 | R26: Lion Team Norte | S26: Propia (Único Asesor) | T26: =VLOOKUP(S26,'Mapa Oficinas'!$H$7:$I$16,2,FALSE) -> CB | U26: Venta | V26: =VLOOKUP($R26,'Mapa Oficinas'!$A$7:$C$46,2,FALSE) -> Zona Norte (GBA) | W26: =VLOOKUP($R26,'Mapa Oficinas'!$A$7:$C$46,3,FALSE) -> Vicente López
A27: 45952 | B27: =YEAR($A27) -> 2025 | C27: =MONTH($A27) -> 10 | D27: Cuenca 4547 | E27: 1 | F27: Cuenca 4547 | G27: Realizado | H27: AR MercadoLibre | I27: 73000 | J27: 36500 | K27: =IF(J27<'Mapa Oficinas'!$I$21,0,IF(J27>'Mapa Oficinas'!$I$20,0,1)) -> 0 | L27: Dólares | M27: Dólares | N27: Cuenca 4547 | O27: Argentina | Capital Federal | Capital Federal | P27: Departamento | Q27: 2 | R27: Lion Team | S27: Propia (Único Asesor) | T27: =VLOOKUP(S27,'Mapa Oficinas'!$H$7:$I$16,2,FALSE) -> CB | U27: Venta | V27: =VLOOKUP($R27,'Mapa Oficinas'!$A$7:$C$46,2,FALSE) -> CABA | W27: =VLOOKUP($R27,'Mapa Oficinas'!$A$7:$C$46,3,FALSE) -> Villa Urquiza
A28: 45768 | B28: =YEAR($A28) -> 2025 | C28: =MONTH($A28) -> 4 | D28: CLA6351579 | E28: 1 | F28: VENTA Lote/Terreno 407m2 UF24 loteo Quetrihue B° Selva Triste Villa la Angostura | G28: Realizado | H28: Web Coldwell-Banker | I28: 36000 | J28: 37000 | K28: =IF(J28<'Mapa Oficinas'!$I$21,0,IF(J28>'Mapa Oficinas'!$I$20,0,1)) -> 0 | L28: Dólares | M28: Dólares | N28: Quetrihue | O28: Argentina | Neuquen | Villa La Angostura | Selva Triste | P28: Terreno | Q28: 2 | R28: Patagonia Lakes VLA | S28: Compartida en Oficina (Dos Asesores) | T28: =VLOOKUP(S28,'Mapa Oficinas'!$H$7:$I$16,2,FALSE) -> CB | U28: Venta | V28: =VLOOKUP($R28,'Mapa Oficinas'!$A$7:$C$46,2,FALSE) -> Interior - Neuquén | W28: =VLOOKUP($R28,'Mapa Oficinas'!$A$7:$C$46,3,FALSE) -> Villa La Angostura
A29: 45996 | B29: =YEAR($A29) -> 2025 | C29: =MONTH($A29) -> 12 | D29: Juan Manuel de Rosas 470 | E29: 1 | F29: Juan Manuel de Rosas 470 | G29: Realizado | H29: AR ZonaProp | I29: 37000 | J29: 37000 | K29: =IF(J29<'Mapa Oficinas'!$I$21,0,IF(J29>'Mapa Oficinas'!$I$20,0,1)) -> 0 | L29: Dólares | M29: Dólares | N29: Juan Manuel de Rosas 470 | O29: Argentina | G.B.A. Zona Oeste | La Matanza | Lomas Del Mirador | P29: Departamento | Q29: 2 | R29: Lion Team | S29: Compartida en Oficina (Dos Asesores) | T29: =VLOOKUP(S29,'Mapa Oficinas'!$H$7:$I$16,2,FALSE) -> CB | U29: Venta | V29: =VLOOKUP($R29,'Mapa Oficinas'!$A$7:$C$46,2,FALSE) -> CABA | W29: =VLOOKUP($R29,'Mapa Oficinas'!$A$7:$C$46,3,FALSE) -> Villa Urquiza
A30: 45694 | B30: =YEAR($A30) -> 2025 | C30: =MONTH($A30) -> 2 | E30: 3 | F30: UF N° 23 de 407,04 m2 Loteo B, Loteo Quetrihue | G30: Realizado | H30: AR MercadoLibre | I30: 37000 | J30: 37000 | K30: =IF(J30<'Mapa Oficinas'!$I$21,0,IF(J30>'Mapa Oficinas'!$I$20,0,1)) -> 0 | L30: Dólares | M30: Dólares | N30: Bv. Quetrihue y Bv. Amancay | O30: Argentina | Neuquen | Villa La Angostura | Selva Triste | P30: Terreno | Q30: 2 | R30: Patagonia Lakes VLA | S30: Master | T30: =VLOOKUP(S30,'Mapa Oficinas'!$H$7:$I$16,2,FALSE) -> CB | U30: Venta | V30: =VLOOKUP($R30,'Mapa Oficinas'!$A$7:$C$46,2,FALSE) -> Interior - Neuquén | W30: =VLOOKUP($R30,'Mapa Oficinas'!$A$7:$C$46,3,FALSE) -> Villa La Angostura
A31: 45726 | B31: =YEAR($A31) -> 2025 | C31: =MONTH($A31) -> 3 | D31: Santa Elisa Pilar del Este | E31: 3 | F31: Terreno en venta Barrio Santa Elisa Pilar del Este | G31: Realizado | H31: AR MercadoLibre | I31: 37000 | J31: 37000 | K31: =IF(J31<'Mapa Oficinas'!$I$21,0,IF(J31>'Mapa Oficinas'!$I$20,0,1)) -> 0 | L31: Dólares | M31: Dólares | O31: Argentina | G.B.A. Zona Norte | Pilar | Countries/B.Cerrado (Pilar) | Pilar Del Este | P31: Terreno | Q31: 2 | R31: North Team | S31: Master | T31: =VLOOKUP(S31,'Mapa Oficinas'!$H$7:$I$16,2,FALSE) -> CB | U31: Venta | V31: =VLOOKUP($R31,'Mapa Oficinas'!$A$7:$C$46,2,FALSE) -> Zona Norte (GBA) | W31: =VLOOKUP($R31,'Mapa Oficinas'!$A$7:$C$46,3,FALSE) -> Pilar
A32: 45834 | B32: =YEAR($A32) -> 2025 | C32: =MONTH($A32) -> 6 | D32: N/C - URUGUAY 847 | E32: 1 | F32: VENTA DPTO MONOAMBIENTE RECOLETA | G32: Realizado | H32: AR ZonaProp | I32: 37000 | J32: 37000 | K32: =IF(J32<'Mapa Oficinas'!$I$21,0,IF(J32>'Mapa Oficinas'!$I$20,0,1)) -> 0 | L32: Dólares | M32: Dólares | N32: URUGUAY 847 | O32: Argentina | Capital Federal | Recoleta | P32: Departamento | Q32: 1 | R32: Destino II | S32: Compartida Fuera de la Red Búsqueda | T32: =VLOOKUP(S32,'Mapa Oficinas'!$H$7:$I$16,2,FALSE) -> Otra Red Búsqueda | U32: Venta | V32: =VLOOKUP($R32,'Mapa Oficinas'!$A$7:$C$46,2,FALSE) -> CABA | W32: =VLOOKUP($R32,'Mapa Oficinas'!$A$7:$C$46,3,FALSE) -> Recoleta
A33: 45820 | B33: =YEAR($A33) -> 2025 | C33: =MONTH($A33) -> 6 | D33: CLO6758717 | E33: 1 | F33: Local en Venta | G33: Realizado | H33: AR ArgenProp | I33: 39000 | J33: 37000 | K33: =IF(J33<'Mapa Oficinas'!$I$21,0,IF(J33>'Mapa Oficinas'!$I$20,0,1)) -> 0 | L33: Dólares | M33: Dólares | N33: Montevideo al 700 | O33: Argentina | Capital Federal | Centro (Capital Federal) | Tribunales | P33: Local Comercial | Q33: 2 | R33: Ser | S33: Compartida Fuera de la Red Captación Propia | T33: =VLOOKUP(S33,'Mapa Oficinas'!$H$7:$I$16,2,FALSE) -> Otra Red Captación | U33: Venta | V33: =VLOOKUP($R33,'Mapa Oficinas'!$A$7:$C$46,2,FALSE) -> CABA | W33: =VLOOKUP($R33,'Mapa Oficinas'!$A$7:$C$46,3,FALSE) -> Belgrano
A34: 45992 | B34: =YEAR($A34) -> 2025 | C34: =MONTH($A34) -> 12 | D34: CAP7382562 | E34: 1 | F34: Monoambiente en venta en Palermo Soho. | G34: Realizado | H34: AR ZonaProp | I34: 40000 | J34: 37000 | K34: =IF(J34<'Mapa Oficinas'!$I$21,0,IF(J34>'Mapa Oficinas'!$I$20,0,1)) -> 0 | L34: Dólares | M34: Dólares | N34: Fray Justo Santa Maria de Oro al 2200, y Charcas | O34: Argentina | Capital Federal | Palermo | Palermo Soho | P34: Departamento | Q34: 2 | R34: Wings | S34: Compartida Fuera de la Red Captación Propia | T34: =VLOOKUP(S34,'Mapa Oficinas'!$H$7:$I$16,2,FALSE) -> Otra Red Captación | U34: Venta | V34: =VLOOKUP($R34,'Mapa Oficinas'!$A$7:$C$46,2,FALSE) -> CABA | W34: =VLOOKUP($R34,'Mapa Oficinas'!$A$7:$C$46,3,FALSE) -> Núñez
A35: 45726 | B35: =YEAR($A35) -> 2025 | C35: =MONTH($A35) -> 3 | D35: CHO6692253 | E35: 1 | F35: Casa en Venta en La Silleta | G35: Realizado | H35: Facebook | I35: 42000 | J35: 37000 | K35: =IF(J35<'Mapa Oficinas'!$I$21,0,IF(J35>'Mapa Oficinas'!$I$20,0,1)) -> 0 | L35: Dólares | M35: Dólares | N35: Barrio Justo Juez, calle Avelino Araoz esquina Gregorio Moreno | O35: Argentina | Salta | Rosario De Lerma | La Silleta | P35: Casa | Q35: 2 | R35: Realty Group | S35: Propia (Único Asesor) | T35: =VLOOKUP(S35,'Mapa Oficinas'!$H$7:$I$16,2,FALSE) -> CB | U35: Venta | V35: =VLOOKUP($R35,'Mapa Oficinas'!$A$7:$C$46,2,FALSE) -> Interior - Salta | W35: =VLOOKUP($R35,'Mapa Oficinas'!$A$7:$C$46,3,FALSE) -> San Lorenzo Chico
A36: 45776 | B36: =YEAR($A36) -> 2025 | C36: =MONTH($A36) -> 4 | D36: CHO6871958 | E36: 1 | F36: Departamento en Tres Cerritos | G36: Realizado | H36: Facebook | I36: 40000 | J36: 37000 | K36: =IF(J36<'Mapa Oficinas'!$I$21,0,IF(J36>'Mapa Oficinas'!$I$20,0,1)) -> 0 | L36: Dólares | M36: Dólares | N36: Los Parrales al 400 | O36: Argentina | Salta | Capital | Salta | Bo.Tres Cerritos | P36: Departamento | Q36: 2 | R36: Realty Group | S36: Propia (Único Asesor) | T36: =VLOOKUP(S36,'Mapa Oficinas'!$H$7:$I$16,2,FALSE) -> CB | U36: Venta | V36: =VLOOKUP($R36,'Mapa Oficinas'!$A$7:$C$46,2,FALSE) -> Interior - Salta | W36: =VLOOKUP($R36,'Mapa Oficinas'!$A$7:$C$46,3,FALSE) -> San Lorenzo Chico
A37: 45827 | B37: =YEAR($A37) -> 2025 | C37: =MONTH($A37) -> 6 | D37: CLA6367239 | E37: 1 | F37: BARRIO GARCIA BAYON - NEUQUEN CAPITAL | G37: Realizado | H37: AR ZonaProp | I37: 37000 | J37: 37000 | K37: =IF(J37<'Mapa Oficinas'!$I$21,0,IF(J37>'Mapa Oficinas'!$I$20,0,1)) -> 0 | L37: Dólares | M37: Dólares | N37: TERRENO GARCIA BAYON | O37: Argentina | Neuquen | Capital | P37: Terreno | Q37: 2 | R37: Sensus | S37: Propia (Único Asesor) | T37: =VLOOKUP(S37,'Mapa Oficinas'!$H$7:$I$16,2,FALSE) -> CB | U37: Venta | V37: =VLOOKUP($R37,'Mapa Oficinas'!$A$7:$C$46,2,FALSE) -> Interior - Neuquén | W37: =VLOOKUP($R37,'Mapa Oficinas'!$A$7:$C$46,3,FALSE) -> Capital Neuquén
A38: 46052 | B38: =YEAR($A38) -> 2026 | C38: =MONTH($A38) -> 1 | D38: CAP6526820 | E38: 1 | F38: Departamento Ideal para renta, Venta 3 dormitorios y cochera | G38: Realizado | H38: Conocido | I38: 40000 | J38: 37000 | K38: =IF(J38<'Mapa Oficinas'!$I$21,0,IF(J38>'Mapa Oficinas'!$I$20,0,1)) -> 0 | L38: Dólares | M38: Dólares | N38: Ideal para renta, Departamento 3 dormitorios y cochera | O38: Argentina | Santa Fe | La Capital | Santo Tome | Sargento Cabral | P38: Departamento | Q38: 2 | R38: De la Veracruz | S38: Propia (Único Asesor) | T38: =VLOOKUP(S38,'Mapa Oficinas'!$H$7:$I$16,2,FALSE) -> CB | U38: Venta | V38: =VLOOKUP($R38,'Mapa Oficinas'!$A$7:$C$46,2,FALSE) -> Interior - Santa Fe | W38: =VLOOKUP($R38,'Mapa Oficinas'!$A$7:$C$46,3,FALSE) -> Capital Santa Fe
A39: 46062 | B39: =YEAR($A39) -> 2026 | C39: =MONTH($A39) -> 2 | D39: CLA6306352 | E39: 1 | F39: Terreno de 436m2 en Dina Huapi con vista al Cerro Leones | G39: Realizado | H39: Teléfono | I39: 38500 | J39: 37000 | K39: =IF(J39<'Mapa Oficinas'!$I$21,0,IF(J39>'Mapa Oficinas'!$I$20,0,1)) -> 0 | L39: Dólares | M39: Dólares | N39: Dina Hue, Dina Huapi | O39: Argentina | Rio Negro | Pilcaniyeu | Dina Huapi | P39: Terreno | Q39: 2 | R39: Patagonia Lakes BRC | S39: Propia (Único Asesor) | T39: =VLOOKUP(S39,'Mapa Oficinas'!$H$7:$I$16,2,FALSE) -> CB | U39: Venta | V39: =VLOOKUP($R39,'Mapa Oficinas'!$A$7:$C$46,2,FALSE) -> Interior - Río Negro | W39: =VLOOKUP($R39,'Mapa Oficinas'!$A$7:$C$46,3,FALSE) -> Bariloche
A40: 45839 | B40: =YEAR($A40) -> 2025 | C40: =MONTH($A40) -> 7 | D40: CHO6782984 | E40: 3 | F40: Venta Casa San Martin de los Andes 72m2 Construidos a Terminar barrio Kaleuche alto | G40: Realizado | H40: Facebook | I40: 45000 | J40: 37500 | K40: =IF(J40<'Mapa Oficinas'!$I$21,0,IF(J40>'Mapa Oficinas'!$I$20,0,1)) -> 0 | L40: Dólares | M40: Dólares | N40: Paseo de los Músicos | O40: Argentina | Neuquen | Lacar | San Martin De Los Andes | Kaleuche | P40: Casa | Q40: 2 | R40: Patagonia Lakes SMA | S40: Master | T40: =VLOOKUP(S40,'Mapa Oficinas'!$H$7:$I$16,2,FALSE) -> CB | U40: Venta | V40: =VLOOKUP($R40,'Mapa Oficinas'!$A$7:$C$46,2,FALSE) -> Interior - Neuquén | W40: =VLOOKUP($R40,'Mapa Oficinas'!$A$7:$C$46,3,FALSE) -> San Martín de los Andes
...

Sheet Mapa Oficinas
A1: Mapeo Oficinas CB → Zona → Localidad
A4: Referencia del PDF oficial Oficinas-CB-ARG-UY-PY.pdf
A6: Oficina | B6: Zona CB | C6: Localidad CB | D6: Operaciones en dataset
A7: Seniority | B7: CABA | C7: Barrio Parque | H7: (Interior) Compartida Fuera de la Red Búsqueda | I7: Otra Red Búsqueda
A8: Ser | B8: CABA | C8: Belgrano | H8: (Interior) Compartida Fuera de la Red Captación Propia | I8: Otra Red Captación
A9: Space BA | B9: CABA | C9: Belgrano | H9: Compartida en Oficina (Dos Asesores) | I9: CB
A10: Desiderio | B10: CABA | C10: Caballito | H10: Compartida en Red (50%) | I10: CB
A11: Goyena | B11: CABA | C11: Caballito | H11: Compartida Fuera de la Red Búsqueda | I11: Otra Red Búsqueda
A12: Database | B12: CABA | C12: Núñez | H12: Compartida Fuera de la Red Captación Propia | I12: Otra Red Captación
A13: Haka | B13: CABA | C13: Núñez | H13: Master | I13: CB
A14: Horizon Group | B14: CABA | C14: Núñez | H14: Profesional Referenciador (30%) | I14: CB
A15: Wings | B15: CABA | C15: Núñez | H15: Profesional Referido (70%) | I15: CB
A16: Livello | B16: CABA | C16: Palermo | H16: Propia (Único Asesor) | I16: CB
A17: Niceto | B17: CABA | C17: Palermo
A18: Notable | B18: CABA | C18: Palermo
A19: Seniority Plus | B19: CABA | C19: Palermo | J19: 0.3
A20: Grupo Elite | B20: CABA | C20: Puerto Madero | H20: RANGO SUPERIOR | I20: 1000000 | J20: =I20*J19 -> 300000
A21: Destino | B21: CABA | C21: Recoleta | H21: RANGO INFERIOR | I21: 69999 | J21: =I21*J19 -> 20999.7
A22: Destino II | B22: CABA | C22: Recoleta
A23: Beyker | B23: CABA | C23: Retiro
A24: Lion Team | B24: CABA | C24: Villa Urquiza
A25: Plaza | B25: Interior - Jujuy | C25: Capital Jujuy
A26: Cuyo Real | B26: Interior - Mendoza | C26: Capital Mendoza
A27: Impacto Pro | B27: Interior - Mendoza | C27: Godoy Cruz
A28: Andes | B28: Interior - Mendoza | C28: San Rafael
A29: Sensus | B29: Interior - Neuquén | C29: Capital Neuquén
A30: Patagonia Lakes SMA | B30: Interior - Neuquén | C30: San Martín de los Andes
A31: Patagonia Lakes VLA | B31: Interior - Neuquén | C31: Villa La Angostura
A32: Patagonia Lakes BRC | B32: Interior - Río Negro | C32: Bariloche
A33: Realty Group | B33: Interior - Salta | C33: San Lorenzo Chico
... A46: Golden Team | B46: Zona Sur (GBA) | C46: La Plata

Sheet DESCARTADO
A2: 45943 | B2: 9102025 | D2: Reserva Venta Flor Lote Dos Valles A25 | E2: Realizado | F2: Teléfono | G2: 43000 | H2: 750 | I2: Dólares | J2: Dólares | L2: Argentina | Rio Negro | Bariloche | San Carlos De Bariloche | M2: Terreno | N2: 1 | O2: Patagonia Lakes BRC | P2: Master | Q2: Venta
A3: 45798 | B3: VCO59064 AP6619653 | D3: Departamento en Altos de Maschwitz - 2 AMB con Jardín | E3: Realizado | F3: AR ZonaProp | G3: 102194 | H3: 1000 | I3: Dólares | J3: Dólares | K3: Departamento en Altos de Maschwitz - 2 AMB con Jardín | L3: Argentina | G.B.A. Zona Norte | Escobar | Ingeniero Maschwitz | Altos de Maschwitz | M3: Departamento | N3: 2 | O3: Puerto Norte | P3: Compartida en Oficina (Dos Asesores) | Q3: Venta
A4: 45992 | B4: CAP7356426 | D4: Departamento en Las Heras | E4: Realizado | F4: AR ZonaProp | G4: 31900 | H4: 2000 | I4: Dólares | J4: Local | K4: Adolfo Calle y Bombal | L4: Argentina | Mendoza | Las Heras | M4: Departamento | N4: 2 | O4: Cuyo Real | P4: Propia (Único Asesor) | Q4: Venta
A5: 45706 | B5: VAP6607532 | D5: Departamento 3 AMB en Alquiler en Infinity Nordelta | E5: Realizado | F5: AR ZonaProp | G5: 800 | H5: 3000 | I5: Dólares | J5: Dólares | K5: Departamento 3 AMB en Alquiler en Infinity Nordelta | L5: Argentina | G.B.A. Zona Norte | Tigre | Countries/B.Cerrado (Tigre) | Nordelta | El Palmar | Infinity Residences | M5: Departamento | N5: 2 | O5: Puerto Norte | P5: Propia (Único Asesor) | Q5: Venta
A6: 45758 | B6: CLA6354054 | D6: LOTES en Barrio Estancia Kingsbroock - 122 y 612 | E6: Realizado | F6: AR ZonaProp | G6: 5200 | H6: 4500 | I6: Dólares | J6: Dólares | K6: LOTES en Barrio Estancia Kingsbroock - 122 y 612 | L6: Argentina | G.B.A. Zona Sur | La Plata | Villa Elvira | M6: Terreno | N6: 2 | O6: Golden Team | P6: Propia (Único Asesor) | Q6: Venta
A7: 45721 | B7: CLA6354054 | D7: LOTES en Barrio Estancia Kingsbroock - 122 y 612 | E7: Realizado | F7: Referido | G7: 5300 | H7: 4774 | I7: Dólares | J7: Dólares | K7: LOTES en Barrio Estancia Kingsbroock - 122 y 612 | L7: Argentina | G.B.A. Zona Sur | La Plata | Villa Elvira | M7: Terreno | N7: 2 | O7: Golden Team | P7: Propia (Único Asesor) | Q7: Venta
A8: 45992 | B8: CHO7100411 | D8: Casa en Las Heras | E8: Realizado | F8: AR ZonaProp | G8: 48000 | H8: 4840 | I8: Dólares | J8: Dólares | K8: 3 de febrero al 500 | L8: Argentina | Mendoza | Las Heras | M8: Casa | N8: 2 | O8: Cuyo Real | P8: Propia (Único Asesor) | Q8: Venta
A9: 45952 | B9: CGA7289163 | D9: Cochera en Mendoza | E9: Realizado | F9: Facebook | G9: 4900 | H9: 4900 | I9: Dólares | J9: Dólares | K9: Garibaldi al 100 | L9: Argentina | Mendoza | Capital | Mendoza | M9: Garage | N9: 2 | O9: Cuyo Real | P9: Propia (Único Asesor) | Q9: Venta
A10: 45992 | B10: CHO6734839 | D10: CASA EN VENTA VISTALBA LOTEO DON CARLOS | E10: Realizado | F10: AR ZonaProp | G10: 140000 | H10: 5000 | I10: Dólares | J10: Dólares | K10: LOTEO DON CARLOS LOS TILOS LOTE K | L10: Argentina | Mendoza | Lujan De Cuyo | Vistalba | M10: Casa | N10: 1 | O10: Cuyo Real | P10: (Interior) Compartida Fuera de la Red Búsqueda | Q10: Venta
