Workbook

Sheet 00_DASHBOARD
A1: TCMC — FCIC Hipotecario · Modelo Financiero v2026.05.11
A2: Dashboard ejecutivo — preparado para reunión de equipo
A4: 📌 NAVEGACIÓN
B5: 🎛️ Panel de Control | D5: ⚖️ Comparativa Lendar | F5: 💧 Cascada Flujo 5Y | H5: 💼 Ingresos TCMC
B6: 📊 Sensibilidades
A8: 📋 PARÁMETROS CLAVE (editar en Panel de Control)
B9: Capital Inicial | C9: ='01_PANEL_CONTROL'!$C$6 -> 3000000 | E9: Ticket Promedio | F9: ='01_PANEL_CONTROL'!$C$9 -> 35000 | H9: LTV Máximo | I9: ='01_PANEL_CONTROL'!$C$10 -> 0.3
B11: Plazo del Fondo | C11: ='01_PANEL_CONTROL'!$C$7&" años" -> 5 años | E11: Tasa Media Cartera | F11: ='01_PANEL_CONTROL'!$C$15 -> 0.124 | H11: WAL | I11: ='01_PANEL_CONTROL'!$C$12&" años" -> 2.9 años
B13: Fee TCMC por crédito | C13: ='01_PANEL_CONTROL'!$C$66 -> 0.0125 | E13: Fee Escribano | F13: ='01_PANEL_CONTROL'!$C$68 -> 0.005 | H13: Tope Gastos (5,4%) | I13: ='01_PANEL_CONTROL'!$C$42 -> 0.054
A15: 🎯 KPIs DEL FONDO (5 años)
B16: TIR INVERSOR (post-fees) | E16: MOIC | H16: TOTAL INGRESOS FONDO 5Y
B17: ='03_CASCADA_FLUJO_5Y'!$H$70 -> 0.093647845 | E17: ='03_CASCADA_FLUJO_5Y'!$H$71 -> 1.3859005 | H17: ='03_CASCADA_FLUJO_5Y'!$H$32 -> 2672118.5
B18: Hurdle: 6%. Carry sobre exceso. | E18: Distribuciones / Capital invertido | H18: Intereses + Upfront Fees
B20: EBITDA NETO 5Y | E20: VOLUMEN TOTAL ORIGINADO | H20: N° CRÉDITOS TOTALES
B21: ='03_CASCADA_FLUJO_5Y'!$H$56 -> 1490959.9 | E21: ='03_CASCADA_FLUJO_5Y'!$H$24 -> 7014133.8 | H21: ='03_CASCADA_FLUJO_5Y'!$H$25 -> 200.40382
B22: Resultado disponible para inversores | E22: Total face-value de créditos en 5Y | H22: Otorgados a lo largo del fondo
A24: 💰 KPIs TCMC (ingreso para el asesor / sponsor)
B25: INGRESO TOTAL TCMC 5Y | E25: SPONSOR OBLIGATION | H25: INGRESO TCMC ANUALIZADO
B26: ='04_INGRESOS_TCMC'!$H$21 -> 203335.63 | E26: ='03_CASCADA_FLUJO_5Y'!$H$49 -> 32598.642 | H26: ='04_INGRESOS_TCMC'!$H$21/5 -> 40667.126
B27: Fee créditos + Carry + Escribano − Sponsor | E27: TCMC paga off-fund si costos > 5,4% PN | H27: Promedio anual
A29: 🚨 SEMÁFOROS Y ALERTAS
B30: TIR vs Hurdle 6% | C30: =IF('03_CASCADA_FLUJO_5Y'!$H$70>='01_PANEL_CONTROL'!$C$44,"✓ TIR supera el hurdle. Carry se activa.","✗ TIR por debajo del hurdle. No hay carry.") -> ✓ TIR supera el hurdle. Carry se activa.
B31: Sponsor Obligation | C31: =IF('03_CASCADA_FLUJO_5Y'!$H$49>0,"⚠ Costos exceden 5,4% PN. TCMC paga "&TEXT('03_CASCADA_FLUJO_5Y'!$H$49,"$#,##0"),"✓ Costos dentro del tope. Sin obligación sponsor.") -> ⚠ Costos exceden 5,4% PN. TCMC paga $32,599
B32: Ingreso TCMC neto | C32: =IF('04_INGRESOS_TCMC'!$H$21>0,"✓ Ingreso TCMC positivo: "&TEXT('04_INGRESOS_TCMC'!$H$21,"$#,##0"),"✗ Ingreso TCMC negativo o nulo") -> ✓ Ingreso TCMC positivo: $203,336
A34: ⚖️ TCMC vs LENDAR — top 5 diferenciales
B35: Variable | C35: TCMC | D35: Lendar | E35: Comentario
B36: Hurdle Rate | C36: ='01_PANEL_CONTROL'!$C$44 -> 0.06 | D36: 0% | E36: TCMC introduce hurdle 6% (alinea incentivos)
B37: Carry | C37: ='01_PANEL_CONTROL'!$C$43 -> 0.1 | D37: 0% | E37: TCMC tiene carry sobre exceso del hurdle
B38: Fee Escribano (off-fund) | C38: ='01_PANEL_CONTROL'!$C$68 -> 0.005 | D38: N/A | E38: Innovación TCMC: ingreso adicional
B39: Fee Asesor Originación | C39: ='01_PANEL_CONTROL'!$C$66 -> 0.0125 | D39: 1,00% | E39: TCMC más alto (1,25%) por valor agregado
B40: LTV Máximo | C40: ='01_PANEL_CONTROL'!$C$10 -> 0.3 | D40: 35% | E40: TCMC más conservador (30%): menos riesgo
A42: Modelo financiero — escenario base. Inputs editables en 01_PANEL_CONTROL. Para sensibilidad ver 05_SENSIBILIDADES. Hojas con prefijo Z_LEGACY_ son respaldo del modelo original.

Sheet 01_PANEL_CONTROL
A1: PANEL DE CONTROL — Modelo FCIC TCMC
A2: Único punto de edición. Celdas amarillas son inputs. El resto se calcula automáticamente.
B4: PARÁMETRO | C4: VALOR | H4: COMENTARIO / FUENTE
A5: I. PARÁMETROS DEL FONDO
B6: Capital Inicial — Tramo I (USD) | C6: 3000000 | H6: Tramo 1 — Propuesta ConoSur Mar-2026. Mín emisión USD 2.5M.
B7: Plazo del Fondo (años) | C7: 5 | H7: Base 5y / Alt 11y (Cl. 16.3.5)
B8: Año inicio del fondo | C8: 2026 | H8: Año fiscal 1 del flujo
B9: Ticket Promedio (USD) — incluye P + 5% upfront + IVA | C9: 35000 | H9: Ticket bruto al tomador. NETO = Ticket / (1 + 5%×1,21)
B10: LTV Máximo | C10: 0.3 | H10: 30% — Propuesta ConoSur. Lendar máx 35% Cl. 3.2.5.
B11: Moneda | C11: USD | H11: Cl. 2.5 Lendar
B12: WAL — Vida Media Ponderada (años) | C12: 2.9 | H12: Calculado por mix de plazos/distribución. Editable si cambia el mix.
B13: Rotación Anual (1 / WAL) | C13: =IFERROR(1/C12,0) -> 0.34482759 | H13: Fracción del stock que se libera por año (amortización)
B14: Rotación Imperfecta (factor) | C14: 1 | H14: Eficiencia de re-originación. 100% = recoloca todo lo liberado.
B15: Tasa Media Ponderada — Cartera | C15: =SUMPRODUCT(D20:D24,E20:E24) -> 0.124 | H15: Calculada del Mix de Créditos abajo
B16: Tasa Media Ajustada — efectiva sobre PN | C16: =C15 -> 0.124 | H16: Tasa neta tras gestión de duration
A18: II. MIX DE CRÉDITOS (Tasas por plazo y distribución)
B19: Plazo (años) | C19: Ticket por plazo | D19: Distribución % | E19: Tasa TNA TCMC | F19: Tasa Lendar | H19: Fuente / cláusula
B20: 1 | C20: =$C$9 -> 35000 | D20: 0.1 | E20: 0.105 | F20: 0.095 | H20: Cl. 16.3.5 piso de rango
B21: 2 | C21: =$C$9 -> 35000 | D21: 0.25 | E21: 0.115 | F21: 0.105 | H21: Cl. 16.3.5 (2.7)
B22: 3 | C22: =$C$9 -> 35000 | D22: 0.4 | E22: 0.125 | F22: 0.115 | H22: Cl. 16.3.5 (2.7)
B23: 4 | C23: =$C$9 -> 35000 | D23: 0.15 | E23: 0.135 | F23: 0.125 | H23: Cl. 16.3.5 (2.7)
B24: 5 | C24: =$C$9 -> 35000 | D24: 0.1 | E24: 0.145 | F24: 0.135 | H24: Cl. 16.3.5 techo de rango
B25: TOTAL | D25: =SUM(D20:D24) -> 1 | E25: =SUMPRODUCT(D20:D24,E20:E24) -> 0.124 | F25: =SUMPRODUCT(D20:D24,F20:F24) -> 0.114 | H25: Tasa media ponderada
A27: III. INGRESOS DEL FONDO (cobrados al tomador del crédito)
B28: Upfront Fee TOTAL al tomador (% s/ Principal NETO) | C28: 0.05 | H28: Capitalizado dentro del ticket. Ingresa al fondo.
B29: IVA (alícuota sobre Upfront) | C29: 0.21 | H29: Pass-through. Capitalizado en el ticket.
B30: Ticket NETO (Principal) — calculado | C30: =C9/(1+C28*(1+C29)) -> 33003.3 | H30: ▸ Ticket / (1 + Upfront × (1+IVA))
B31: Upfront fee al fondo (USD/crédito) | C31: =C30*C28 -> 1650.165 | H31: ▸ Principal NETO × Upfront
B32: IVA capitalizado (pass-through, USD/crédito) | C32: =C31*C29 -> 346.53465 | H32: ▸ Upfront × IVA. Sale del fondo al fisco.
A34: IV. COSTOS DEL FONDO
B35: Honorarios Soc. Gerente — anual % PN | C35: 0.012 | H35: Cono Sur SGFCISA. Cl. 10.1 max 1,20%.
B36: Honorarios Soc. Depositaria — anual % PN neto | C36: 0.002 | H36: Banco Comafi (a confirmar). Cl. 10.3.
B37: Mín. anual Soc. Depositaria (USD sin IVA) | C37: 21600 | H37: Si 0,2%×PN < mínimo, aplica mínimo. Cl. 10.3.
B38: Setup inicial Depositaria (Y1 only, USD) | C38: 10000 | H38: One-time. Cl. 10.3.
B39: Comisión Colocadores — one-time (% s/ captación) | C39: 0.015 | H39: Cl. 10.4. Sale del capital captado.
B40: Comisión Organizador — one-time (% s/ captación) | C40: 0.0025 | H40: Cono Sur Inversiones SA. Cl. 10.4.
B41: Reserva inicial para gastos (% s/ captación, Y1) | C41: 0.015 | H41: Buffer para cubrir costos Y1. Editable.
B42: Tope Máximo de Gastos del Fondo (% PN anual) | C42: 0.054 | H42: Cl. 10.5. Si se excede, sponsor paga la diferencia.
B43: Carry sobre exceso de hurdle (%) | C43: 0.1 | H43: Opción B Propuesta ConoSur. Cobrable al cierre.
B44: Hurdle Rate (anual, % s/ PN) | C44: 0.06 | H44: Tasa de retorno mínima antes de carry.
...

Sheet 02_COMPARATIVA_LENDAR
A1: COMPARATIVA TCMC vs LENDAR
A2: Side-by-side de parámetros principales. Verde = TCMC más favorable; Rojo = menos favorable; Amarillo = neutro/depende.
B4: PARÁMETRO | C4: TCMC | D4: LENDAR (CI) | E4: DELTA | F4: VENT. | G4: Cl. Lendar | H4: Observaciones
A5: I. PARÁMETROS DEL FONDO
B6: Capital Inicial (USD) | C6: ='01_PANEL_CONTROL'!$C$6 -> 3000000 | D6: 3000000 | E6: =C6-D6 -> 0 | F6: ▸ | G6: — | H6: Tramo I propuesto. Lendar no publica.
B7: Plazo del Fondo (años) | C7: ='01_PANEL_CONTROL'!$C$7 -> 5 | D7: 11 | E7: =C7-D7 -> -6 | F7: TCMC | G7: Cl. 16.3.5 | H7: TCMC base 5y, alt 11y. Lendar 11y máx.
B8: Ticket Promedio (USD) | C8: ='01_PANEL_CONTROL'!$C$9 -> 35000 | D8: N/D | E8: — | F8: ▸ | G8: — | H8: TCMC define ticket explícito.
B9: LTV Máximo | C9: ='01_PANEL_CONTROL'!$C$10 -> 0.3 | D9: 0.35 | E9: =C9-D9 -> -0.05 | F9: LDR | G9: Cl. 3.2.5 | H9: TCMC más conservador (30% vs 35%).
B10: Moneda | C10: USD | D10: USD | E10: — | F10: ▸ | G10: Cl. 2.5 | H10: Ambos USD.
B11: WAL (años) | C11: ='01_PANEL_CONTROL'!$C$12 -> 2.9 | D11: N/A | E11: — | F11: ▸ | G11: — | H11: TCMC explícito.
B12: Tasa Media TCMC | C12: ='01_PANEL_CONTROL'!$C$15 -> 0.124 | D12: 0.115 | E12: =C12-D12 -> 0.009 | F12: TCMC | G12: Cl. 16.3.5 | H12: TCMC 10 bps superior (mix similar).
A14: II. COSTOS DEL FONDO
B15: Hon. Soc. Gerente (anual % PN) | C15: ='01_PANEL_CONTROL'!$C$35 -> 0.012 | D15: 0.0125 | E15: =C15-D15 -> -0.0005 | F15: TCMC | G15: Cl. 16.5.1 | H15: TCMC -5 bps. Cono Sur 1,20%.
B16: Hon. Soc. Depositaria (% PN) | C16: ='01_PANEL_CONTROL'!$C$36 -> 0.002 | D16: 0.002 | E16: =C16-D16 -> 0 | F16: ▸ | G16: Cl. 16.5.2 | H16: Mismo % nominal. TCMC: min USD 21,600/año.
B17: Mín. anual Depositaria (USD) | C17: ='01_PANEL_CONTROL'!$C$37 -> 21600 | D17: 21600 | E17: =C17-D17 -> 0 | F17: ▸ | G17: Cl. 10.3 | H17: Comafi a confirmar.
B18: Fee Asesor por crédito ORIGINADO | C18: ='01_PANEL_CONTROL'!$C$66 -> 0.0125 | D18: 0.01 | E18: =C18-D18 -> 0.0025 | F18: LDR | G18: Cl. 16.5.5 | H18: TCMC 1,25% vs Lendar 1%. Cono Sur propuso 1-1,5%.
B19: Fee Asesor por crédito ADQUIRIDO | C19: ='01_PANEL_CONTROL'!$C$67 -> 0.01 | D19: 0.007 | E19: =C19-D19 -> 0.003 | F19: LDR | G19: Cl. 16.5.5 | H19: TCMC 1% vs Lendar 0,7%.
B20: Carried Interest | C20: ='01_PANEL_CONTROL'!$C$43 -> 0.1 | D20: 0 | E20: =C20-D20 -> 0.1 | F20: LDR | G20: Cl. 16.4 | H20: Lendar no tiene carry. TCMC sí (Opción B).
B21: Hurdle Rate | C21: ='01_PANEL_CONTROL'!$C$44 -> 0.06 | D21: 0 | E21: =C21-D21 -> 0.06 | F21: TCMC | G21: Cl. 16.4 | H21: TCMC: 6% hurdle (alineado a inversor).
B22: Tope gastos (% PN anual) | C22: ='01_PANEL_CONTROL'!$C$42 -> 0.054 | D22: 0.054 | E22: =C22-D22 -> 0 | F22: ▸ | G22: Cl. 10.5 | H22: Idéntico 5,4%. Mismo régimen sponsor.
B23: Comisión Colocadores (one-time) | C23: ='01_PANEL_CONTROL'!$C$39 -> 0.015 | D23: 0.005 | E23: =C23-D23 -> 0.01 | F23: LDR | G23: Cl. 16.5.4 | H23: TCMC 1,5% vs Lendar 0,5%. Cono Sur 1,5%.
B24: Comisión Organizador (one-time) | C24: ='01_PANEL_CONTROL'!$C$40 -> 0.0025 | D24: 0.0025 | E24: =C24-D24 -> 0 | F24: ▸ | G24: — | H24: TCMC y Lendar similar.
A26: III. INGRESOS DEL FONDO (cobrados al tomador)
B27: Upfront Fee al fondo (% s/ NETO) | C27: ='01_PANEL_CONTROL'!$C$28 -> 0.05 | D27: 0.05 | E27: =C27-D27 -> 0 | F27: ▸ | G27: Cl. 16.3.5 | H27: Idéntico 5%. Cl. 2.7 CFT include 5%+IVA.
B28: IVA sobre Upfront | C28: ='01_PANEL_CONTROL'!$C$29 -> 0.21 | D28: 0.21 | E28: =C28-D28 -> 0 | F28: ▸ | G28: — | H28: Pass-through al fisco.
A30: IV. RESCATES Y LIQUIDEZ
B31: Año inicio rescate parcial | C31: ='01_PANEL_CONTROL'!$C$74 -> 3 | D31: 3 | E31: =C31-D31 -> 0 | F31: LDR | G31: Cl. 6.11 | H31: Lendar 3y, TCMC 2y (Cono Sur).
B32: Recompra anual (% PN) | C32: 6,0% | D32: 20% por evento | E32: — | F32: TCMC | G32: Cl. 6.11 | H32: TCMC menor pero recurrente.
B33: Fee sobre retiros (%) | C33: ='01_PANEL_CONTROL'!$C$69 -> 0 | D33: 0.05 | E33: =C33-D33 -> -0.05 | F33: TCMC | G33: Cl. 16.8 | H33: TCMC default 0%, Lendar hasta 5%.
B34: Penalidad rescate adicional | C34: 0 | D34: 0 | E34: — | F34: ▸ | G34: Cl. 16.8 | H34: Ninguno default. Editable.
A36: V. APALANCAMIENTO Y CIERRE
B37: Leverage máximo (x PN) | C37: ='01_PANEL_CONTROL'!$C$72 -> 1 | D37: 1 | E37: =C37-D37 -> 0 | F37: ▸ | G37: Cl. 16.1.5 | H37: Hasta 1x PN previa CNV.
B38: Leverage efectivo usado | C38: ='01_PANEL_CONTROL'!$C$73 -> 0.5 | D38: 0 | E38: =C38-D38 -> 0.5 | F38: ▸ | G38: — | H38: TCMC 50%, Lendar no publica.
B39: Año inicio apalancamiento | C39: ='01_PANEL_CONTROL'!$C$74 -> 3 | D39: 3 | E39: =C39-D39 -> 0 | F39: ▸ | G39: — | H39: Mismo timing.
B40: Tasa Securitización cierre | C40: ='01_PANEL_CONTROL'!$C$76 -> 0.09 | D40: 0.09 | E40: =C40-D40 -> 0 | F40: ▸ | G40: — | H40: Supuesto homologado.
A42: VI. INGRESOS TCMC PROPIOS (no contemplados en Lendar)
B43: Fee TCMC vía escribano (% s/ inmueble) | C43: ='01_PANEL_CONTROL'!$C$68 -> 0.005 | D43: N/A | E43: — | F43: TCMC | G43: — | H43: OFF-FUND. Innovación TCMC.
B44: Sponsor Obligation (TCMC paga >5,4%) | C44: SÍ | D44: SÍ (estructura) | E44: — | F44: ▸ | G44: Cl. 10.5 | H44: Mismo régimen. TCMC asume rol sponsor.
A47: VII. SCORECARD — RESUMEN COMPARATIVO
B48: Categoría | C48: Ventaja TCMC | D48: Ventaja Lendar | E48: Neutro
...

Sheet 03_CASCADA_FLUJO_5Y
A1: CASCADA FLUJO DEL FONDO — 5 AÑOS
A2: Cascada paso a paso: captación → comisiones → reserva → originación → ingresos/costos → SPONSOR → resultado inversor
B4: CONCEPTO | C4: Año 1 | D4: Año 2 | E4: Año 3 | F4: Año 4 | G4: Año 5 | H4: TOTAL 5Y | I4: Notas / Fórmula
B5: Año calendario | C5: ='01_PANEL_CONTROL'!$C$8+0 -> 2026 | D5: ='01_PANEL_CONTROL'!$C$8+1 -> 2027 | E5: ='01_PANEL_CONTROL'!$C$8+2 -> 2028 | F5: ='01_PANEL_CONTROL'!$C$8+3 -> 2029 | G5: ='01_PANEL_CONTROL'!$C$8+4 -> 2030 | H5: TOTAL | I5: 5 años fiscales
A7: A. CAPTACIÓN DE CAPITAL (waterfall inicial)
B8: Captación bruta del año | C8: ='01_PANEL_CONTROL'!$C$6+'01_PANEL_CONTROL'!C$59 -> 3000000 | D8: ='01_PANEL_CONTROL'!D$59 -> 0 | E8: ='01_PANEL_CONTROL'!E$59 -> 0 | F8: ='01_PANEL_CONTROL'!F$59 -> 0 | G8: ='01_PANEL_CONTROL'!G$59 -> 0 | H8: =SUM(C8:G8) -> 3000000 | I8: Capital inicial Y1 + captaciones adicionales por año (Panel C59:G59)
B9: (−) Comisión Colocadores | C9: =-C8*'01_PANEL_CONTROL'!$C$39 -> -45000 | D9: =-D8*'01_PANEL_CONTROL'!$C$39 -> 0 | E9: =-E8*'01_PANEL_CONTROL'!$C$39 -> 0 | F9: =-F8*'01_PANEL_CONTROL'!$C$39 -> 0 | G9: =-G8*'01_PANEL_CONTROL'!$C$39 -> 0 | H9: =SUM(C9:G9) -> -45000 | I9: ▸ Captación × '01_PANEL_CONTROL'!$C$39
B10: (−) Comisión Organizador | C10: =-C8*'01_PANEL_CONTROL'!$C$40 -> -7500 | D10: =-D8*'01_PANEL_CONTROL'!$C$40 -> 0 | E10: =-E8*'01_PANEL_CONTROL'!$C$40 -> 0 | F10: =-F8*'01_PANEL_CONTROL'!$C$40 -> 0 | G10: =-G8*'01_PANEL_CONTROL'!$C$40 -> 0 | H10: =SUM(C10:G10) -> -7500 | I10: ▸ Captación × '01_PANEL_CONTROL'!$C$40
B11: Reserva interna para gastos (informativa, no sale del fondo) | C11: =-C8*'01_PANEL_CONTROL'!$C$41 -> -45000 | D11: 0 | E11: 0 | F11: 0 | G11: 0 | H11: =SUM(C11:G11) -> -45000 | I11: Buffer Y1 para cubrir costos operativos iniciales
B12: ▸ Capital neto para colocar en cartera | C12: =C8+C9+C10 -> 2947500 | D12: =D8+D9+D10 -> 0 | E12: =E8+E9+E10 -> 0 | F12: =F8+F9+F10 -> 0 | G12: =G8+G9+G10 -> 0 | H12: =SUM(C12:G12) -> 2947500 | I12: Después de deducir comisiones + reserva Y1
A14: B. APALANCAMIENTO (deuda senior opcional)
B15: Deuda Senior (USD) — desde año inicio apalancamiento | C15: =IF(1>='01_PANEL_CONTROL'!$C$74,'01_PANEL_CONTROL'!$C$6*'01_PANEL_CONTROL'!$C$73,0) -> 0 | D15: =IF(2>='01_PANEL_CONTROL'!$C$74,'01_PANEL_CONTROL'!$C$6*'01_PANEL_CONTROL'!$C$73,0) -> 0 | E15: =IF(3>='01_PANEL_CONTROL'!$C$74,'01_PANEL_CONTROL'!$C$6*'01_PANEL_CONTROL'!$C$73,0) -> 1500000 | F15: =IF(4>='01_PANEL_CONTROL'!$C$74,'01_PANEL_CONTROL'!$C$6*'01_PANEL_CONTROL'!$C$73,0) -> 1500000 | G15: =IF(5>='01_PANEL_CONTROL'!$C$74,'01_PANEL_CONTROL'!$C$6*'01_PANEL_CONTROL'!$C$73,0) -> 1500000 | H15: =MAX(C15:G15) -> 1500000 | I15: ▸ PN × '01_PANEL_CONTROL'!$C$73 si año >= '01_PANEL_CONTROL'!$C$74
B16: Capital total desplegable (Equity neto + Deuda) | C16: =C12+C15 -> 2947500 | D16: =D12+D15 -> 0 | E16: =E12+E15 -> 1500000 | F16: =F12+F15 -> 1500000 | G16: =G12+G15 -> 1500000 | H16: — | I16: Capital total deployment-ready
A18: C. CARTERA — ROTACIÓN Y NUEVA ORIGINACIÓN
B19: Cartera Inicio del año (stock crédito) | C19: =C16 -> 2947500 | D19: =C27+D15-C15 -> 2947500 | E19: =D27+E15-D15 -> 4573302.9 | F19: =E27+F15-E15 -> 4579999.9 | G19: =F27+G15-F15 -> 4652460.1
B20: (−) Capital liberado por amortización (rotación) | C20: =-C19*'01_PANEL_CONTROL'!$C$13 -> -1016379.3 | D20: =-D19*'01_PANEL_CONTROL'!$C$13 -> -1016379.3 | E20: =-E19*'01_PANEL_CONTROL'!$C$13 -> -1577001 | F20: =-F19*'01_PANEL_CONTROL'!$C$13 -> -1579310.3 | G20: =-G19*'01_PANEL_CONTROL'!$C$13 -> -1604296.6 | H20: =SUM(C20:G20) -> -6793366.5 | I20: ▸ Cartera × '01_PANEL_CONTROL'!$C$13 (1/WAL)
B21: (−) Recompra a inversores (cash al inversor) | C21: =-C19*'01_PANEL_CONTROL'!C$60 -> 0 | D21: =-D19*'01_PANEL_CONTROL'!D$60 -> -176850 | E21: =-E19*'01_PANEL_CONTROL'!E$60 -> -274398.17 | F21: =-F19*'01_PANEL_CONTROL'!F$60 -> -274800 | G21: =-G19*'01_PANEL_CONTROL'!G$60 -> 0 | H21: =SUM(C21:G21) -> -726048.17 | I21: ▸ Cartera × '01_PANEL_CONTROL'!C60:G60 (6% editable)
B22: (−) Fondo de Liquidez (monto adicional) | C22: =-'01_PANEL_CONTROL'!C$61 -> 0 | D22: =-'01_PANEL_CONTROL'!D$61 -> 0 | E22: =-'01_PANEL_CONTROL'!E$61 -> 0 | F22: =-'01_PANEL_CONTROL'!F$61 -> 0 | G22: =-'01_PANEL_CONTROL'!G$61 -> 0 | H22: =SUM(C22:G22) -> 0 | I22: Editable por año (Panel C61:G61)
B23: Capital disponible para originar este año | C23: =C16 -> 2947500 | D23: =-D20*'01_PANEL_CONTROL'!$C$14+D12+D21+D22 -> 839529.31 | E23: =-E20*'01_PANEL_CONTROL'!$C$14+E12+E21+E22 -> 1302602.8 | F23: =-F20*'01_PANEL_CONTROL'!$C$14+F12+F21+F22 -> 1304510.3 | G23: =-G20*'01_PANEL_CONTROL'!$C$14+G12+G21+G22 -> 1604296.6 | H23: =SUM(C23:G23) -> 7998439 | I23: Y1: capital captado neto + deuda. Y2+: amortizado × rot. + captac. nuevas − recompras
B24: Volumen BRUTO originado (ticket × N° créditos) | C24: =MAX(0,C23)*(1+'01_PANEL_CONTROL'!$C$13*'01_PANEL_CONTROL'!$C$14)*'01_PANEL_CONTROL'!C$62*'01_PANEL_CONTROL'!C$63 -> 3567491.4 | D24: =MAX(0,D23)*'01_PANEL_CONTROL'!D$62*'01_PANEL_CONTROL'!D$63 -> 839529.31 | E24: =MAX(0,E23)*'01_PANEL_CONTROL'!E$62*'01_PANEL_CONTROL'!E$63 -> 1302602.8 | F24: =MAX(0,F23)*'01_PANEL_CONTROL'!F$62*'01_PANEL_CONTROL'!F$63 -> 1304510.3 | G24: =MAX(0,G23)*'01_PANEL_CONTROL'!G$62*'01_PANEL_CONTROL'!G$63 -> 0 | H24: =SUM(C24:G24) -> 7014133.8 | I24: × orig_activa (0/1) × ramp-up (0-1). Volumen total face-value de créditos otorgados
B25: N° de créditos otorgados | C25: =IFERROR(C24/'01_PANEL_CONTROL'!$C$9,0) -> 101.92833 | D25: =IFERROR(D24/'01_PANEL_CONTROL'!$C$9,0) -> 23.986552 | E25: =IFERROR(E24/'01_PANEL_CONTROL'!$C$9,0) -> 37.217223 | F25: =IFERROR(F24/'01_PANEL_CONTROL'!$C$9,0) -> 37.271724 | G25: =IFERROR(G24/'01_PANEL_CONTROL'!$C$9,0) -> 0 | H25: =SUM(C25:G25) -> 200.40382 | I25: ▸ Volumen / Ticket bruto ('01_PANEL_CONTROL'!$C$9)
B26: Volumen NETO otorgado (Principal a tomadores) | C26: =C25*'01_PANEL_CONTROL'!$C$30 -> 3363971.1 | D26: =D25*'01_PANEL_CONTROL'!$C$30 -> 791635.37 | E26: =E25*'01_PANEL_CONTROL'!$C$30 -> 1228291.2 | F26: =F25*'01_PANEL_CONTROL'!$C$30 -> 1230089.9 | G26: =G25*'01_PANEL_CONTROL'!$C$30 -> 0 | H26: =SUM(C26:G26) -> 6613987.6 | I26: ▸ N° × Ticket NETO ('01_PANEL_CONTROL'!$C$30) — efectivo desembolsado
B27: Stock cartera FIN del año | C27: =C19+C21+C22+IF('01_PANEL_CONTROL'!C$62=0,C20,0) -> 2947500 | D27: =D19+D12+D21+D22+C56+IF('01_PANEL_CONTROL'!D$62=0,D20,0) -> 3073302.9 | E27: =E19+E12+E21+E22+D56+IF('01_PANEL_CONTROL'!E$62=0,E20,0) -> 4579999.9 | F27: =F19+F12+F21+F22+E56+IF('01_PANEL_CONTROL'!F$62=0,F20,0) -> 4652460.1 | G27: =G19+G12+G21+G22+F56+IF('01_PANEL_CONTROL'!G$62=0,G20,0) -> 3400298.2 | H27: — | I27: ▸ Cartera inicio − liberado − recompras − liq + nueva originación
A29: D. INGRESOS DEL FONDO
B30: Intereses ganados sobre cartera | C30: =((C19+C27)/2)*'01_PANEL_CONTROL'!$C$16*'01_PANEL_CONTROL'!C$63 -> 328941 | D30: =((D19+D27)/2)*'01_PANEL_CONTROL'!$C$16*'01_PANEL_CONTROL'!D$63 -> 373289.78 | E30: =((E19+E27)/2)*'01_PANEL_CONTROL'!$C$16*'01_PANEL_CONTROL'!E$63 -> 567504.77 | F30: =((F19+F27)/2)*'01_PANEL_CONTROL'!$C$16*'01_PANEL_CONTROL'!F$63 -> 572412.52 | G30: =((G19+G27)/2)*'01_PANEL_CONTROL'!$C$16*'01_PANEL_CONTROL'!G$63 -> 499271.01 | H30: =SUM(C30:G30) -> 2341419.1 | I30: ▸ Cartera promedio × '01_PANEL_CONTROL'!$C$16 × ramp-up
B31: Upfront Fee al Fondo (5% sobre NETO) | C31: =C26*'01_PANEL_CONTROL'!$C$28 -> 168198.56 | D31: =D26*'01_PANEL_CONTROL'!$C$28 -> 39581.769 | E31: =E26*'01_PANEL_CONTROL'!$C$28 -> 61414.56 | F31: =F26*'01_PANEL_CONTROL'!$C$28 -> 61504.495 | G31: =G26*'01_PANEL_CONTROL'!$C$28 -> 0 | H31: =SUM(C31:G31) -> 330699.38 | I31: ▸ Volumen NETO × '01_PANEL_CONTROL'!$C$28. Capitalizado dentro del ticket
B32: TOTAL INGRESOS DEL FONDO | C32: =C30+C31 -> 497139.56 | D32: =D30+D31 -> 412871.55 | E32: =E30+E31 -> 628919.33 | F32: =F30+F31 -> 633917.01 | G32: =G30+G31 -> 499271.01 | H32: =SUM(C32:G32) -> 2672118.5 | I32: Intereses + Upfront
A34: E. COSTOS DEL FONDO
B35: PN Inicio del año (proxy = capital desplegable) | C35: =C19 -> 2947500 | D35: =D19 -> 2947500 | E35: =E19 -> 4573302.9 | F35: =F19 -> 4579999.9 | G35: =G19 -> 4652460.1 | H35: — | I35: Base para honorarios % PN
B36: Honorarios Soc. Gerente (1,2% × PN) | C36: =C35*'01_PANEL_CONTROL'!$C$35 -> 35370 | D36: =D35*'01_PANEL_CONTROL'!$C$35 -> 35370 | E36: =E35*'01_PANEL_CONTROL'!$C$35 -> 54879.634 | F36: =F35*'01_PANEL_CONTROL'!$C$35 -> 54959.999 | G36: =G35*'01_PANEL_CONTROL'!$C$35 -> 55829.521 | H36: =SUM(C36:G36) -> 236409.15 | I36: ▸ PN × '01_PANEL_CONTROL'!$C$35
B37: Honorarios Soc. Depositaria (max 0,2%×PN, mín) | C37: =MAX(C35*'01_PANEL_CONTROL'!$C$36,'01_PANEL_CONTROL'!$C$37)+'01_PANEL_CONTROL'!$C$38 -> 31600 | D37: =MAX(D35*'01_PANEL_CONTROL'!$C$36,'01_PANEL_CONTROL'!$C$37) -> 21600 | E37: =MAX(E35*'01_PANEL_CONTROL'!$C$36,'01_PANEL_CONTROL'!$C$37) -> 21600 | F37: =MAX(F35*'01_PANEL_CONTROL'!$C$36,'01_PANEL_CONTROL'!$C$37) -> 21600 | G37: =MAX(G35*'01_PANEL_CONTROL'!$C$36,'01_PANEL_CONTROL'!$C$37) -> 21600 | H37: =SUM(C37:G37) -> 118000 | I37: ▸ MAX(PN×'01_PANEL_CONTROL'!$C$36, '01_PANEL_CONTROL'!$C$37) [Y1: + '01_PANEL_CONTROL'!$C$38]
B38: Fee TCMC por crédito originado | C38: =C24*'01_PANEL_CONTROL'!$C$66 -> 44593.642 | D38: =D24*'01_PANEL_CONTROL'!$C$66 -> 10494.116 | E38: =E24*'01_PANEL_CONTROL'!$C$66 -> 16282.535 | F38: =F24*'01_PANEL_CONTROL'!$C$66 -> 16306.379 | G38: =G24*'01_PANEL_CONTROL'!$C$66 -> 0 | H38: =SUM(C38:G38) -> 87676.673 | I38: ▸ Volumen BRUTO × '01_PANEL_CONTROL'!$C$66 (cobrado por TCMC al fondo)
B39: Costos fijos anuales | C39: ='01_PANEL_CONTROL'!$C$55 -> 80200 | D39: ='01_PANEL_CONTROL'!$C$54 -> 56000 | E39: ='01_PANEL_CONTROL'!$C$54 -> 56000 | F39: ='01_PANEL_CONTROL'!$C$54 -> 56000 | G39: ='01_PANEL_CONTROL'!$C$54 -> 56000 | H39: =SUM(C39:G39) -> 304200 | I39: Y1 incluye setup ('01_PANEL_CONTROL'!$C$55). Y2+: '01_PANEL_CONTROL'!$C$54
B40: IVA sobre Upfront (pass-through al fisco) | C40: =C31*'01_PANEL_CONTROL'!$C$29 -> 35321.697 | D40: =D31*'01_PANEL_CONTROL'!$C$29 -> 8312.1714 | E40: =E31*'01_PANEL_CONTROL'!$C$29 -> 12897.058 | F40: =F31*'01_PANEL_CONTROL'!$C$29 -> 12915.944 | G40: =G31*'01_PANEL_CONTROL'!$C$29 -> 0 | H40: =SUM(C40:G40) -> 69446.87 | I40: ▸ Upfront × '01_PANEL_CONTROL'!$C$29 — no es costo neto pero sale del fondo
B41: Intereses deuda senior | C41: =C15*'01_PANEL_CONTROL'!$C$75 -> 0 | D41: =D15*'01_PANEL_CONTROL'!$C$75 -> 0 | E41: =E15*'01_PANEL_CONTROL'!$C$75 -> 120000 | F41: =F15*'01_PANEL_CONTROL'!$C$75 -> 120000 | G41: =G15*'01_PANEL_CONTROL'!$C$75 -> 120000 | H41: =SUM(C41:G41) -> 360000 | I41: ▸ Deuda × '01_PANEL_CONTROL'!$C$75
B42: Comisiones Coloc.+Org. (informativo, ya deducidas en captación) | C42: =-(C9+C10) -> 52500 | D42: =-(D9+D10) -> 0 | E42: =-(E9+E10) -> 0 | F42: =-(F9+F10) -> 0 | G42: =-(G9+G10) -> 0 | H42: =SUM(C42:G42) -> 52500 | I42: Ya descontadas de captación (no se vuelven a contar)
B43: SUBTOTAL COSTOS DEL FONDO | C43: =C36+C37+C38+C39+C40+C41 -> 227085.34 | D43: =D36+D37+D38+D39+D40+D41 -> 131776.29 | E43: =E36+E37+E38+E39+E40+E41 -> 281659.23 | F43: =F36+F37+F38+F39+F40+F41 -> 281782.32 | G43: =G36+G37+G38+G39+G40+G41 -> 253429.52 | H43: =SUM(C43:G43) -> 1175732.7 | I43: SG + SD + Fee TCMC + Fijos + IVA + Intereses deuda
A45: F. TEST DE TOPE 5,4% — SPONSOR OBLIGATION (TCMC paga el exceso)
B46: Costos elegibles para tope (SG + SD + Asesor + Fijos) | C46: =C36+C37+C38+C39 -> 191763.64 | D46: =D36+D37+D38+D39 -> 123464.12 | E46: =E36+E37+E38+E39 -> 148762.17 | F46: =F36+F37+F38+F39 -> 148866.38 | G46: =G36+G37+G38+G39 -> 133429.52 | H46: =SUM(C46:G46) -> 746285.83 | I46: Excluye comisiones colocador/org, IVA y deuda (no aplican al tope)
B47: Tope 5,4% × PN | C47: =C35*'01_PANEL_CONTROL'!$C$42 -> 159165 | D47: =D35*'01_PANEL_CONTROL'!$C$42 -> 159165 | E47: =E35*'01_PANEL_CONTROL'!$C$42 -> 246958.35 | F47: =F35*'01_PANEL_CONTROL'!$C$42 -> 247320 | G47: =G35*'01_PANEL_CONTROL'!$C$42 -> 251232.84 | H47: =SUM(C47:G47) -> 1063841.2 | I47: ▸ PN × '01_PANEL_CONTROL'!$C$42
...

Sheet 04_INGRESOS_TCMC
A1: INGRESOS TCMC — ON-FUND + OFF-FUND
A2: Detalle de los flujos que cobra TCMC como asesor + sponsor obligation. Off-fund vía escribano.
B4: CONCEPTO | C4: Año 1 | D4: Año 2 | E4: Año 3 | F4: Año 4 | G4: Año 5 | H4: TOTAL 5Y | I4: Notas / Fórmula
A5: I. INGRESOS ON-FUND (dentro del fondo)
B6: Fee TCMC por crédito originado (1,25% × Volumen BRUTO) | C6: ='03_CASCADA_FLUJO_5Y'!C38 -> 44593.642 | D6: ='03_CASCADA_FLUJO_5Y'!D38 -> 10494.116 | E6: ='03_CASCADA_FLUJO_5Y'!E38 -> 16282.535 | F6: ='03_CASCADA_FLUJO_5Y'!F38 -> 16306.379 | G6: ='03_CASCADA_FLUJO_5Y'!G38 -> 0 | H6: =SUM(C6:G6) -> 87676.673 | I6: Cobrado por TCMC al fondo. Pull desde Cascada fila 38.
B7: Carry cobrado (10% sobre exceso > hurdle, sólo Y5) | C7: ='03_CASCADA_FLUJO_5Y'!C55 -> 0 | D7: ='03_CASCADA_FLUJO_5Y'!D55 -> 0 | E7: ='03_CASCADA_FLUJO_5Y'!E55 -> 0 | F7: ='03_CASCADA_FLUJO_5Y'!F55 -> 0 | G7: ='03_CASCADA_FLUJO_5Y'!G55 -> 38024.475 | H7: =SUM(C7:G7) -> 38024.475 | I7: Success fee al cierre. Pull desde Cascada fila 55.
B8: Fee sobre retiros de liquidez | C8: =-('03_CASCADA_FLUJO_5Y'!C21)*'01_PANEL_CONTROL'!$C$69 -> 0 | D8: =-('03_CASCADA_FLUJO_5Y'!D21)*'01_PANEL_CONTROL'!$C$69 -> 0 | E8: =-('03_CASCADA_FLUJO_5Y'!E21)*'01_PANEL_CONTROL'!$C$69 -> 0 | F8: =-('03_CASCADA_FLUJO_5Y'!F21)*'01_PANEL_CONTROL'!$C$69 -> 0 | G8: =-('03_CASCADA_FLUJO_5Y'!G21)*'01_PANEL_CONTROL'!$C$69 -> 0 | H8: =SUM(C8:G8) -> 0 | I8: ▸ Recompra × '01_PANEL_CONTROL'!$C$69 (default 0%)
B9: SUBTOTAL ON-FUND | C9: =C6+C7+C8 -> 44593.642 | D9: =D6+D7+D8 -> 10494.116 | E9: =E6+E7+E8 -> 16282.535 | F9: =F6+F7+F8 -> 16306.379 | G9: =G6+G7+G8 -> 38024.475 | H9: =SUM(C9:G9) -> 125701.15 | I9: Ingresos cobrados por TCMC al propio fondo
A11: II. INGRESOS OFF-FUND (vía escribano, fuera del fondo)
B12: Valor del inmueble por crédito = Ticket NETO / LTV | C12: =IFERROR('01_PANEL_CONTROL'!$C$30/'01_PANEL_CONTROL'!$C$10,0) -> 110011 | D12: =IFERROR('01_PANEL_CONTROL'!$C$30/'01_PANEL_CONTROL'!$C$10,0) -> 110011 | E12: =IFERROR('01_PANEL_CONTROL'!$C$30/'01_PANEL_CONTROL'!$C$10,0) -> 110011 | F12: =IFERROR('01_PANEL_CONTROL'!$C$30/'01_PANEL_CONTROL'!$C$10,0) -> 110011 | G12: =IFERROR('01_PANEL_CONTROL'!$C$30/'01_PANEL_CONTROL'!$C$10,0) -> 110011 | H12: — | I12: Fórmula: Ticket NETO / LTV (con LTV 30%, inmueble ≈ 3.3x ticket)
B13: Valor inmueble TOTAL movilizado por año | C13: =C12*'03_CASCADA_FLUJO_5Y'!C25 -> 11213237 | D13: =D12*'03_CASCADA_FLUJO_5Y'!D25 -> 2638784.6 | E13: =E12*'03_CASCADA_FLUJO_5Y'!E25 -> 4094304 | F13: =F12*'03_CASCADA_FLUJO_5Y'!F25 -> 4100299.6 | G13: =G12*'03_CASCADA_FLUJO_5Y'!G25 -> 0 | H13: =SUM(C13:G13) -> 22046625 | I13: ▸ Valor inmueble × N° créditos otorgados (Cascada f.25)
B14: Fee Escribano TCMC (0,5% sobre valor inmueble) | C14: =C13*'01_PANEL_CONTROL'!$C$68 -> 56066.185 | D14: =D13*'01_PANEL_CONTROL'!$C$68 -> 13193.923 | E14: =E13*'01_PANEL_CONTROL'!$C$68 -> 20471.52 | F14: =F13*'01_PANEL_CONTROL'!$C$68 -> 20501.498 | G14: =G13*'01_PANEL_CONTROL'!$C$68 -> 0 | H14: =SUM(C14:G14) -> 110233.13 | I14: ▸ Valor inmueble TOTAL × '01_PANEL_CONTROL'!$C$68
B15: SUBTOTAL OFF-FUND | C15: =C14 -> 56066.185 | D15: =D14 -> 13193.923 | E15: =E14 -> 20471.52 | F15: =F14 -> 20501.498 | G15: =G14 -> 0 | H15: =SUM(C15:G15) -> 110233.13 | I15: Ingresos cobrados vía escribanía (no entra al fondo)
A17: III. SPONSOR OBLIGATION (TCMC paga el exceso > 5,4% PN)
B18: Sponsor Obligation (TCMC paga al fondo, sale de TCMC) | C18: =-'03_CASCADA_FLUJO_5Y'!C49 -> -32598.642 | D18: =-'03_CASCADA_FLUJO_5Y'!D49 -> 0 | E18: =-'03_CASCADA_FLUJO_5Y'!E49 -> 0 | F18: =-'03_CASCADA_FLUJO_5Y'!F49 -> 0 | G18: =-'03_CASCADA_FLUJO_5Y'!G49 -> 0 | H18: =SUM(C18:G18) -> -32598.642 | I18: Signo negativo: TCMC compensa el exceso > 5,4% del PN. Cascada f.49.
A20: IV. INGRESO TOTAL TCMC (NETO de Sponsor Obligation)
B21: TOTAL INGRESO TCMC NETO | C21: =C9+C15+C18 -> 68061.185 | D21: =D9+D15+D18 -> 23688.039 | E21: =E9+E15+E18 -> 36754.055 | F21: =F9+F15+F18 -> 36807.877 | G21: =G9+G15+G18 -> 38024.475 | H21: =SUM(C21:G21) -> 203335.63 | I21: Ingreso TCMC neto = On-fund + Off-fund − Sponsor Obligation
B23: Acumulado (running total) | C23: =C21 -> 68061.185 | D23: =C23+D21 -> 91749.225 | E23: =D23+E21 -> 128503.28 | F23: =E23+F21 -> 165311.16 | G23: =F23+G21 -> 203335.63 | H23: — | I23: Suma acumulada año a año
A25: V. DESAGREGADO POR FUENTE — ESCENARIOS
B26: Componente | C26: Total 5Y (USD) | D26: Promedio anual | E26: % del total
B27: Fee por crédito originado | C27: =H6 -> 87676.673 | D27: =C27/5 -> 17535.335 | E27: =IFERROR(C27/SUM(C27:C31),0) -> 0.43119188
B28: Carry cobrado | C28: =H7 -> 38024.475 | D28: =C28/5 -> 7604.895 | E28: =IFERROR(C28/SUM(C27:C31),0) -> 0.1870035
B29: Fee retiros de liquidez | C29: =H8 -> 0 | D29: =C29/5 -> 0 | E29: =IFERROR(C29/SUM(C27:C31),0) -> 0
B30: Fee escribano (off-fund) | C30: =H14 -> 110233.13 | D30: =C30/5 -> 22046.625 | E30: =IFERROR(C30/SUM(C27:C31),0) -> 0.542124
B31: (−) Sponsor obligation | C31: =H18 -> -32598.642 | D31: =C31/5 -> -6519.7284 | E31: =IFERROR(C31/SUM(C27:C31),0) -> -0.16031938
B32: TOTAL | C32: =SUM(C27:C31) -> 203335.63 | D32: =C32/5 -> 40667.126 | E32: 100%
A34: VI. RETORNO TCMC — IMPACTO ECONÓMICO
B35: Ratio Ingreso TCMC / Capital Inicial Fondo | C35: =H21/'01_PANEL_CONTROL'!$C$6 -> 0.067778544 | I35: Ingreso TCMC como % del PN del fondo (proxy ROIC para TCMC)
B36: Ingreso TCMC anualizado | C36: =H21/5 -> 40667.126 | I36: Total 5Y / 5

Sheet 05_SENSIBILIDADES
A1: SENSIBILIDADES — Variables Clave
A2: Tablas de escenarios. Las celdas centrales aplican fórmulas paramétricas usando los inputs del Panel.
A4: TABLA 1: TIR INVERSOR vs Tasa Media × Honorarios Soc. Gerente (% PN)
B5: Tasa Media \ SG % PN | C5: 0.008 | D5: 0.01 | E5: 0.012 | F5: 0.014 | G5: 0.016
B6: 0.1 | C6: 0.095 | D6: 0.093 | E6: 0.091 | F6: 0.089 | G6: 0.087
B7: 0.115 | C7: 0.11 | D7: 0.108 | E7: 0.106 | F7: 0.104 | G7: 0.102
B8: 0.124 | C8: 0.119 | D8: 0.117 | E8: 0.115 | F8: 0.113 | G8: 0.111
B9: 0.135 | C9: 0.13 | D9: 0.128 | E9: 0.126 | F9: 0.124 | G9: 0.122
B10: 0.15 | C10: 0.145 | D10: 0.143 | E10: 0.141 | F10: 0.139 | G10: 0.137
B11: Nota: | C11: Heurística simplificada para visualización. Para TIR exacta cambiar inputs en Panel y leer Cascada H70.
A13: TABLA 2: INGRESO TCMC TOTAL 5Y vs Capital Inicial × Ticket Promedio
B14: Capital Inicial \ Ticket | C14: 25000 | D14: 30000 | E14: 35000 | F14: 40000 | G14: 50000
B15: 2000000 | C15: 397511 | D15: 397511 | E15: 397511 | F15: 397511 | G15: 397511
B16: 3000000 | C16: 596266.5 | D16: 596266.5 | E16: 596266.5 | F16: 596266.5 | G16: 596266.5
B17: 5000000 | C17: 993777.5 | D17: 993777.5 | E17: 993777.5 | F17: 993777.5 | G17: 993777.5
B18: 7500000 | C18: 1490666.3 | D18: 1490666.3 | E18: 1490666.3 | F18: 1490666.3 | G18: 1490666.3
B19: 10000000 | C19: 1987555 | D19: 1987555 | E19: 1987555 | F19: 1987555 | G19: 1987555
B21: Heurística: ingreso TCMC ≈ Volumen × 1,25% + (Volumen / LTV) × 0,5% + Carry estimado. Independiente del Panel para fines comparativos.
A23: TABLA 3: SPONSOR OBLIGATION 5Y vs Costos Fijos Anuales × Capital Inicial
B24: Capital \ Costos Fijos/año | C24: 40000 | D24: 56000 | E24: 75000 | F24: 100000 | G24: 150000
B25: 2000000 | C25: 0 | D25: 0 | E25: 68000 | F25: 193000 | G25: 443000
B26: 3000000 | C26: 0 | D26: 0 | E26: 0 | F26: 0 | G26: 235500
B27: 5000000 | C27: 0 | D27: 0 | E27: 0 | F27: 0 | G27: 0
B28: 7500000 | C28: 0 | D28: 0 | E28: 0 | F28: 0 | G28: 0
B29: 10000000 | C29: 0 | D29: 0 | E29: 0 | F29: 0 | G29: 0
B31: Heurística: estima sponsor obligation 5Y según relación costos vs tope 5,4%. A mayor PN, mayor margen para absorber costos fijos.
A33: TABLA 4: TIR INVERSOR vs WAL × Tasa Media
B34: Tasa Media \ WAL | C34: 2 | D34: 2.5 | E34: 2.9 | F34: 3.5 | G34: 4.5
B35: 0.1 | C35: 0.10155 | D35: 0.09684 | E35: 0.094241379 | F35: 0.091457143 | G35: 0.088466667
B36: 0.115 | C36: 0.11655 | D36: 0.11184 | E36: 0.10924138 | F36: 0.10645714 | G36: 0.10346667
B37: 0.124 | C37: 0.12555 | D37: 0.12084 | E37: 0.11824138 | F37: 0.11545714 | G37: 0.11246667
B38: 0.135 | C38: 0.13655 | D38: 0.13184 | E38: 0.12924138 | F38: 0.12645714 | G38: 0.12346667
B39: 0.15 | C39: 0.15155 | D39: 0.14684 | E39: 0.14424138 | F39: 0.14145714 | G39: 0.13846667
B41: Heurística: TIR ≈ Tasa Media + (1/WAL × 4,71%) − 2,2% costos. WAL más corto → más upfront amortizado por año.
A43: IMPACTO DE CADA VARIABLE EN LA TIR (sensibilidad de 1% punto)
B44: Variable | C44: Direcc. | D44: ΔTIR si sube 1%pt | E44: Tipo | F44: Comentario
B45: Tasa Media | C45: + | D45: +1,00% | E45: Lineal | F45: Cada 1pp en tasa cartera = +1pp TIR. Limitada por aforo y mercado.
B46: Hon. Soc. Gerente (%PN) | C46: − | D46: −1,00% | E46: Lineal | F46: Cada 1pp baja TIR 1pp. Cono Sur 1,2%, máx 1,2% Cl.10.1.
B47: Costos Fijos USD/año | C47: − | D47: −0,1% por $30K | E47: Por capital | F47: Capacidad de dilución según PN.
B48: Recompra anual (%) | C48: − | D48: −0,3% por 1pp | E48: Compuesto | F48: Reduce stock para originar, comprime tasa efectiva.
...

Sheet SUPUESTOS
A1: MODELO TCMC — FCIC HIPOTECARIO (Cono Sur Investments)
A2: Basado en Propuesta ConoSur a Capital Token Group S.A., Marzo 2026. Capital: USD 5M Tramo I. Plazo base: 5yr / Alt: 11yr.
B3: TCMC (TBD) | C3: Detalle / Fuente | D3: LENDAR (Allaria) | E3: Detalle / CI (Cláusula Informativa)
A5: I. PARÁMETROS DEL FONDO
A6: Capital Inicial (USD) | B6: 3000000 | C6: Tramo 1 — Propuesta ConoSur Mar-2026: ≈USD 5M (ampliable). Mín emisión: USD 2.5M, Máx: USD 100M | D6: 3000000 | E6: No publicado. Usamos 3M como referencia. | F6: 2.4 Mínimo de emisión: 2.500.000 Máximo 100.000.000
A7: Plazo del Fondo (años) | B7: 11 | C7: Base: 5yr (ConoSur) / Alt: 11yr. ≈5 años con opción de extensión | D7: 11 | E7: Plazos crédito hasta 11 años. Cl. 16.3.5 | F7: 2.3.3 El vencimiento de los diversos créditos hipotecarios originados y/o adquiridos por el Fondo podrá operar con posterioridad al vencimiento del Plazo del Fondo.
A8: Ticket Promedio Crédito (USD) | B8: 40000 | C8: ≈USD 30,000 por crédito. Plazos 1-3 años. Aforos ≈30% | D8: N/D | E8: No publicado
A9: LTV Máximo | B9: 0.35 | C9: 30% — Propuesta ConoSur Mar-2026 | D9: 0.35 | E9: Presentación prensa Lendar | F9: 3.2.5 | G9: LTV máximo 35% según Cl. 3.2.5 Reglamento
A10: Moneda | B10: USD | C10: Dólares estadounidenses — Propuesta ConoSur Mar-2026 | D10: USD | E10: Cl. 2.5: "La moneda del Fondo será el Dólar Estadounidense"
A12: II. MIX DE CRÉDITOS
A13: Plazo (años) | B13: Tasa TNA | C13: Distribución % | D13: Lendar Tasa TNA | E13: Fuente CI
A14: 1 | B14: 0.105 | C14: 0.1 | D14: 0.095 | E14: Cl. 16.3.5 — piso de rango | G14: =-PMT((B14/12),(12*A14),(C14*B$6)) -> 26444.581
A15: 2 | B15: 0.115 | C15: 0.25 | D15: 0.105 | E15: 2.7 | G15: =-PMT((B15/12),(12*A15),(C15*B$6)) -> 35130.236
A16: 3 | B16: 0.125 | C16: 0.4 | D16: 0.115 | E16: 2.7 | G16: =-PMT((B16/12),(12*A16),(C16*B$6)) -> 40144.351
A17: 4 | B17: 0.135 | C17: 0.15 | D17: 0.125 | E17: 2.7 | G17: =-PMT((B17/12),(12*A17),(C17*B$6)) -> 12184.345
A18: 5 | B18: 0.145 | C18: 0.1 | D18: 0.135 | E18: Cl. 16.3.5 — techo de rango | G18: =-PMT((B18/12),(12*A18),(C18*B$6)) -> 7058.4843
G19: =SUM(G14:G18) -> 120962
A20: WAL (años) | B20: =A14*C14+A15*C15+A16*C16+A17*C17+A18*C18 -> 2.9 | G20: =G19*12 -> 1451544
A21: Tasa Media Ponderada | B21: =B14*C14+B15*C15+B16*C16+B17*C17+B18*C18 -> 0.124
A22: Rotación Anual (1/WAL) | B22: =1/B20 -> 0.34482759
A23: Rotación Imperfecta | B23: 1
A24: Tasa Media Ajustada | B24: =B21*B23 -> 0.124 | C24: =B24*0.7 -> 0.0868
A26: III. COSTOS DEL FONDO (% sobre PN)
A27: Concepto | B27: TCMC | C27: Detalle | D27: LENDAR | E27: CI Lendar
A28: Honorarios Soc. Gerente (anual) | B28: 0.012 | C28: 1.20% anual PN — Cono Sur S.G.F.C.I.S.A. (Propuesta ConoSur Mar-2026) | D28: 0.0125 | E28: Cl. 16.5.1: 1.25% anual del PN | F28: 10.1 | G28: Cl. 10.1: máx 1.20% anual del PN. Liquidación trimestral + IVA.
A29: Honorarios Soc. Depositaria (anual) | B29: 0.002 | C29: 0.20% anual PN neto — Banco Comafi S.A. (a confirmar). Mín USD 21,600+IVA/año (Propuesta ConoSur) | D29: 0.002 | E29: Cl. 16.5.2: 0.20% anual del PN. NOTA: parece caro vs mercado | F29: 10.3 | G29: Mínimo de 21600 USD + IVA anual. Fee inicial de 10000 USD + IVA (one-time). Si 0.2%*PN < 21600, aplica el mínimo.
A30: Honorarios Asesor Inversión (anual % PN) | B30: 0 | C30: Opción A (activa): SIN mgmt fee % PN, cobra por crédito. Alt B: 1% PN + 10% carry >6% hurdle (Propuesta ConoSur) | D30: 0 | E30: NO cobra % anual PN. Cobra one-time por crédito (ver abajo) | F30: 16.5 | G30: Lendar Cl. 16.5: NO prevé mgmt fee % PN para asesor. Solo fee por crédito (1%/0.7%)
A31: Fee Asesor por crédito originado (one-time) | B31: 0.0125 | C31: 1% por crédito originado — Propuesta ConoSur Mar-2026 (antes 1.5%) | D31: 0.01 | E31: Cl. 16.5.5: 1% por crédito originado directamente | F31: 16.5.5 | G31: Cl. 16.5.5: ≤1% anual del valor de cada crédito originado + IVA
A32: Fee Asesor por crédito adquirido (one-time) | B32: 0.01 | C32: 1% por crédito adquirido — Propuesta ConoSur Mar-2026 | D32: 0.007 | E32: Cl. 16.5.5: 0.7% por crédito adquirido a terceros | F32: 16.5.5 | G32: Cl. 16.5.5: ≤0.7% anual del valor de cada crédito adquirido + IVA
A33: Carried Interest | B33: 0.1 | C33: 10% sobre exceso hurdle — Opción B de Propuesta ConoSur Mar-2026. EDITABLE. | D33: 0 | E33: Cl. 16.4: No previsto. "No se garantiza rendimiento"
A34: Hurdle Rate | B34: 0.06 | C34: 6% hurdle rate — Propuesta ConoSur Mar-2026 (antes 10%). EDITABLE. | D34: 0 | E34: N/A — sin carry, sin hurdle
A35: Tope Máximo Gastos (Reglamento) | B35: 0.054 | C35: 5.4% anual PN — Propuesta ConoSur Mar-2026 | D35: 0.054 | E35: Cl. 16.5: Tope 5.4% anual PN | F35: 10.5 | G35: Cl. 10.5: tope gastos ordinarios + hon. Adm + Cust = 5.4% + IVA
A36: Comisión Colocadores (one-time) | B36: 0.015 | C36: 1.5% del monto suscripto — Propuesta ConoSur Mar-2026 | D36: 0.015 | E36: Cl. 16.5.4: 0.5% del monto suscripto | F36: 10.4
A37: Comisión Organizador (one-time) | B37: 0.0025 | C37: 0.25% del monto suscripto — Cono Sur Inversiones S.A. (Propuesta ConoSur Mar-2026) | D37: 0.0025 | E37: Incluida en Soc. Gerente según reglamento | F37: 10.4
A38: Upfront Fee al Fondo | B38: 0.05 | C38: 5% del monto otorgado (4% al fondo + 1% extracción asesor) — Propuesta ConoSur Mar-2026 | D38: 0.05 | E38: Cl. 16.3.5: 5% + IVA cobrado al tomador. Ingresa al fondo. | F38: 2.7 | G38: Cl. 2.7: CFT = tasa + amort + 5% fee + IVA. Cobrado al tomador.
A39: IVA | B39: 0.21 | D39: 0.21
A40: Mín. Anual Soc. Depositaria (USD sin IVA) | B40: 21600 | C40: Cl. 10.3: aplica si 0.2%*PN < este mínimo | D40: 21600 | E40: Cl. 10.3
A41: IV. COSTOS FIJOS ANUALES (USD)
A42: Auditoría externa | B42: 10000 | C42: Anual
A43: Asesoría legal | B43: 10000 | C43: Anual
...

Sheet FLUJO 5 AÑOS (5Y)
A1: FLUJO DEL FONDO — MODELO TCMC 5 AÑOS (Cono Sur / Capital Token Group, USD 5M)
A3: AÑO | B3: 2026 | C3: 2027 | D3: 2028 | E3: 2029 | F3: 2030 | G3: TOTAL
A4: A. CAPITAL Y ORIGINACIÓN | B4: 0.9 | C4: 1 | D4: 1 | E4: 1 | F4: 1
A5: Cartera Total Desplegada Inicio | B5: =B47*(1-SUPUESTOS!$B$36-SUPUESTOS!$B$37)+B14 -> 2947500 | C5: =B9+B42+C14-B14 -> 3187809.9 | D5: =C9+C42+D14-C14 -> 4985016.5 | E5: =D9+D42+E14-D14 -> 5237747 | F5: =E9+E42+F14-E14 -> 5467012.8
A6: Capital Liberado (Amortización) | B6: =B5*SUPUESTOS!$B$22 -> 1016379.3 | C6: =C5*SUPUESTOS!$B$22 -> 1099244.8 | D6: =D5*SUPUESTOS!$B$22 -> 1718971.2 | E6: =E5*SUPUESTOS!$B$22 -> 1806119.7 | F6: =F5*SUPUESTOS!$B$22 -> 1885176.8
A7: ¿Año de Originación Activa? | B7: 1 | C7: 1 | D7: 1 | E7: 1 | F7: 0
A8: Nuevos Créditos (re-originación) | B8: =IF(B7=1,B6*SUPUESTOS!$B$23,0) -> 1016379.3 | C8: =IF(C7=1,C6*SUPUESTOS!$B$23,0) -> 1099244.8 | D8: =IF(D7=1,D6*SUPUESTOS!$B$23,0) -> 1718971.2 | E8: =IF(E7=1,E6*SUPUESTOS!$B$23,0) -> 1806119.7 | F8: =IF(F7=1,F6*SUPUESTOS!$B$23,0) -> 0
A9: Stock de Capital Fin Año | B9: =B5-B6+B8 -> 2947500 | C9: =C5-C6+C8 -> 3187809.9 | D9: =D5-D6+D8 -> 4985016.5 | E9: =E5-E6+E8 -> 5237747 | F9: =F5-F6+F8 -> 3581836
A10: Volumen Total Originado | B10: =B5+B8 -> 3963879.3 | C10: =C8+MAX(0,C5-B9) -> 1339554.7 | D10: =D8+MAX(0,D5-C9) -> 3516177.8 | E10: =E8+MAX(0,E5-D9) -> 2058850.2 | F10: =F8+MAX(0,F5-E9) -> 229265.82 | G10: =SUM(B10:F10) -> 11107728
A12: B. APALANCAMIENTO (editar fila 13: 1=ajustar deuda al 50% PN, 0=mantener nivel anterior)
A13: ¿Ajustar deuda? (1=reset a 0.5x PN, 0=mantener) — editable por año | B13: 0 | C13: 0 | D13: 1 | E13: 0 | F13: 0 | G13: 0
A14: Deuda Senior (monto) | B14: =IF(B13=1, B47*SUPUESTOS!$B$52, 0) -> 0 | C14: =IF(C13=1, C47*SUPUESTOS!$B$52, B14) -> 0 | D14: =IF(D13=1, D47*SUPUESTOS!$B$52, C14) -> 1679172.2 | E14: =IF(E13=1, E47*SUPUESTOS!$B$52, D14) -> 1679172.2 | F14: =IF(F13=1, F47*SUPUESTOS!$B$52, E14) -> 1679172.2
A15: Capital Total Desplegado (Equity + Deuda) | B15: =B5 -> 2947500 | C15: =C5 -> 3187809.9 | D15: =D5 -> 4985016.5 | E15: =E5 -> 5237747 | F15: =F5 -> 5467012.8
A16: Leverage Ratio (Deuda / PN Inicio) | B16: =IF(B5>0,B14/B5,0) -> 0 | C16: =IF(C5>0,C14/C5,0) -> 0 | D16: =IF(D5>0,D14/D5,0) -> 0.33684385 | E16: =IF(E5>0,E14/E5,0) -> 0.32059054 | F16: =IF(F5>0,F14/F5,0) -> 0.30714619
A18: C. INGRESOS
A19: Interés Ganado (sobre capital total desplegado) | B19: =((B5+B9)/2)*SUPUESTOS!$B$24*B4 -> 328941 | C19: =((C5+C9)/2)*SUPUESTOS!$B$24*C4 -> 395288.42 | D19: =((D5+D9)/2)*SUPUESTOS!$B$24*D4 -> 618142.04 | E19: =((E5+E9)/2)*SUPUESTOS!$B$24*E4 -> 649480.63 | F19: =((F5+F9)/2)*SUPUESTOS!$B$24*F4 -> 561028.63 | G19: =SUM(B19:F19) -> 2552880.7
A20: Upfront Fee (4% al Fondo) | B20: =(B10/(1+SUPUESTOS!$B$38))*SUPUESTOS!$B$38 -> 188756.16 | C20: =(C10/(1+SUPUESTOS!$B$38))*SUPUESTOS!$B$38 -> 63788.317 | D20: =(D10/(1+SUPUESTOS!$B$38))*SUPUESTOS!$B$38 -> 167437.04 | E20: =(E10/(1+SUPUESTOS!$B$38))*SUPUESTOS!$B$38 -> 98040.484 | F20: =(F10/(1+SUPUESTOS!$B$38))*SUPUESTOS!$B$38 -> 10917.42 | G20: =SUM(B20:F20) -> 528939.42
A21: TOTAL INGRESOS FONDO | B21: =B19+B20 -> 517697.16 | C21: =C19+C20 -> 459076.74 | D21: =D19+D20 -> 785579.08 | E21: =E19+E20 -> 747521.11 | F21: =F19+F20 -> 571946.05 | G21: =SUM(B21:F21) -> 3081820.1
A23: D. COSTOS DEL FONDO
A24: Honorarios Soc. Gerente (1.2%) | B24: =B47*SUPUESTOS!$B$28 -> 36000 | C24: =C47*SUPUESTOS!$B$28 -> 38883.718 | D24: =D47*SUPUESTOS!$B$28 -> 40300.132 | E24: =E47*SUPUESTOS!$B$28 -> 43332.898 | F24: =F47*SUPUESTOS!$B$28 -> 46084.088 | G24: =SUM(B24:F24) -> 204600.84
A25: Honorarios Soc. Depositaria (0.2%, mín $21,600/yr + $10K inicial Y1) | B25: =MAX(B47*SUPUESTOS!$B$29,SUPUESTOS!$B$40)+10000 -> 31600 | C25: =MAX(C47*SUPUESTOS!$B$29,SUPUESTOS!$B$40) -> 21600 | D25: =MAX(D47*SUPUESTOS!$B$29,SUPUESTOS!$B$40) -> 21600 | E25: =MAX(E47*SUPUESTOS!$B$29,SUPUESTOS!$B$40) -> 21600 | F25: =MAX(F47*SUPUESTOS!$B$29,SUPUESTOS!$B$40) -> 21600 | G25: =SUM(B25:F25) -> 118000
A26: Honorarios Asesor Inversión (0% PN — eliminado) | B26: =B47*SUPUESTOS!$B$30 -> 0 | C26: =C47*SUPUESTOS!$B$30 -> 0 | D26: =D47*SUPUESTOS!$B$30 -> 0 | E26: =E47*SUPUESTOS!$B$30 -> 0 | F26: =F47*SUPUESTOS!$B$30 -> 0 | G26: =SUM(B26:F26) -> 0
A27: Fee Asesor (Originación + Adquisición) | B27: =B10*(SUPUESTOS!$B$31) -> 49548.491 | C27: =C10*(SUPUESTOS!$B$31) -> 16744.433 | D27: =D10*(SUPUESTOS!$B$31) -> 43952.223 | E27: =E10*(SUPUESTOS!$B$31) -> 25735.627 | F27: =F10*(SUPUESTOS!$B$31) -> 2865.8228 | G27: =SUM(B27:F27) -> 138846.6
A28: Costos Fijos Operativos | B28: =SUPUESTOS!$B$42+SUPUESTOS!$B$43+SUPUESTOS!$B$44+SUPUESTOS!$B$45+SUPUESTOS!$B$46+SUPUESTOS!$B$47+SUPUESTOS!$B$48 -> 68100 | C28: =SUPUESTOS!$B$42+SUPUESTOS!$B$43+SUPUESTOS!$B$45+SUPUESTOS!$B$46+SUPUESTOS!$B$47+SUPUESTOS!$B$48 -> 56000 | D28: =SUPUESTOS!$B$42+SUPUESTOS!$B$43+SUPUESTOS!$B$45+SUPUESTOS!$B$46+SUPUESTOS!$B$47+SUPUESTOS!$B$48 -> 56000 | E28: =SUPUESTOS!$B$42+SUPUESTOS!$B$43+SUPUESTOS!$B$45+SUPUESTOS!$B$46+SUPUESTOS!$B$47+SUPUESTOS!$B$48 -> 56000 | F28: =SUPUESTOS!$B$42+SUPUESTOS!$B$43+SUPUESTOS!$B$45+SUPUESTOS!$B$46+SUPUESTOS!$B$47+SUPUESTOS!$B$48 -> 56000 | G28: =SUM(B28:F28) -> 292100
A29: Comisiones (Colocador+Org) sobre capital | B29: =(SUPUESTOS!$B$6+B45)*(SUPUESTOS!$B$36+SUPUESTOS!$B$37) -> 52500 | C29: =C45*(SUPUESTOS!$B$36+SUPUESTOS!$B$37) -> 0 | D29: =D45*(SUPUESTOS!$B$36+SUPUESTOS!$B$37) -> 0 | E29: =E45*(SUPUESTOS!$B$36+SUPUESTOS!$B$37) -> 0 | F29: =F45*(SUPUESTOS!$B$36+SUPUESTOS!$B$37) -> 0 | G29: =SUM(B29:F29) -> 52500
A30: IVA sobre Upfront Fee (REVISAR: ¿lo paga el fondo o el tomador?) | B30: =B20*SUPUESTOS!$B$39 -> 39638.793 | C30: =C20*SUPUESTOS!$B$39 -> 13395.547 | D30: =D20*SUPUESTOS!$B$39 -> 35161.778 | E30: =E20*SUPUESTOS!$B$39 -> 20588.502 | F30: =F20*SUPUESTOS!$B$39 -> 2292.6582 | G30: =SUM(B30:F30) -> 111077.28
A31: Intereses Deuda Senior | B31: =B14*SUPUESTOS!$B$54 -> 0 | C31: =C14*SUPUESTOS!$B$54 -> 0 | D31: =D14*SUPUESTOS!$B$54 -> 134333.77 | E31: =E14*SUPUESTOS!$B$54 -> 134333.77 | F31: =F14*SUPUESTOS!$B$54 -> 134333.77 | G31: =SUM(B31:F31) -> 403001.32
A32: TOTAL COSTOS | B32: =B24+B25+B26+B27+B28+B29+B30+B31+B34 -> 277387.28 | C32: =C24+C25+C26+C27+C28+C29+C30+C31+C34 -> 146623.7 | D32: =D24+D25+D26+D27+D28+D29+D30+D31+D34 -> 331347.91 | E32: =E24+E25+E26+E27+E28+E29+E30+E31+E34 -> 301590.8 | F32: =F24+F25+F26+F27+F28+F29+F30+F31+F34 -> 337045.33 | G32: =SUM(B32:F32) -> 1393995
A33: Carry devengado del período | B33: ='RESULTADOS ASESOR TCMC (5Y)'!B14 -> 6030.9873 | C33: ='RESULTADOS ASESOR TCMC (5Y)'!C14 -> 11803.445 | D33: ='RESULTADOS ASESOR TCMC (5Y)'!D14 -> 25273.052 | E33: ='RESULTADOS ASESOR TCMC (5Y)'!E14 -> 22926.582 | F33: ='RESULTADOS ASESOR TCMC (5Y)'!F14 -> 7834.9265 | G33: ='RESULTADOS ASESOR TCMC (5Y)'!G14 -> 73868.993
A34: Carry COBRADO (Success Fee: sólo al cierre Y6, tope 5% Cl.10.5) | B34: ='RESULTADOS ASESOR TCMC (5Y)'!B18 -> 0 | C34: ='RESULTADOS ASESOR TCMC (5Y)'!C18 -> 0 | D34: ='RESULTADOS ASESOR TCMC (5Y)'!D18 -> 0 | E34: ='RESULTADOS ASESOR TCMC (5Y)'!E18 -> 0 | F34: ='RESULTADOS ASESOR TCMC (5Y)'!F18 -> 73868.993 | G34: ='RESULTADOS ASESOR TCMC (5Y)'!G18 -> 73868.993
B35: =(B32-B31)/B48 -> 0.085605172 | C35: =(C32-C31)/C48 -> 0.04127033 | D35: =(D32-D31)/D48 -> 0.051674815 | E35: =(E32-E31)/E48 -> 0.041226723 | F35: =(F32-F31)/F48 -> 0.049742222
A36: =CONCATENATE("SPONSOR SI > ",SUPUESTOS!B35*100,"%") -> SPONSOR SI > 5.4% | B36: =IF(B35>SUPUESTOS!$B$35,(B48*SUPUESTOS!$B$35)-B32,0) -> -102410.55 | C36: =IF(C35>SUPUESTOS!$B$35,(C48*SUPUESTOS!$B$35)-C32,0) -> 0 | D36: =IF(D35>SUPUESTOS!$B$35,(D48*SUPUESTOS!$B$35)-D32,0) -> 0 | E36: =IF(E35>SUPUESTOS!$B$35,(E48*SUPUESTOS!$B$35)-E32,0) -> 0 | F36: =IF(F35>SUPUESTOS!$B$35,(F48*SUPUESTOS!$B$35)-F32,0) -> 0
A38: E. RESULTADO
A39: EBITDA Fondo (neto de carry) | B39: =B21-B32 -> 240309.87 | C39: =C21-C32 -> 312453.04 | D39: =D21-D32 -> 454231.18 | E39: =E21-E32 -> 445930.31 | F39: =F21-F32 -> 234900.71 | G39: =SUM(B39:F39) -> 1687825.1
A40: EBITDA / Equity (%) | B40: =IF(B47>0,B39/B47,0) -> 0.080103291 | C40: =IF(C47>0,C39/C47,0) -> 0.096426902 | D40: =IF(D47>0,D39/D47,0) -> 0.1352545 | E40: =IF(E47>0,E39/E47,0) -> 0.12348963 | F40: =IF(F47>0,F39/F47,0) -> 0.061166634
A41: Retiros Parciales Inversores (detalle filas 69-80) | B41: =B79 -> 0 | C41: =C79 -> 194418.59 | D41: =D79 -> 201500.66 | E41: =E79 -> 216664.49 | F41: =F79 -> 0 | G41: =SUM(B41:F41) -> 612583.74
A42: Neto Reinvertido / Acumulado | B42: =B39-B41 -> 240309.87 | C42: =C39-C41 -> 118034.45 | D42: =D39-D41 -> 252730.52 | E42: =E39-E41 -> 229265.82 | F42: =F39-F41 -> 234900.71 | G42: =SUM(B42:F42) -> 1075241.4
A44: F. PATRIMONIO NETO
A45: Captaciones Nuevas (ingreso capital por año) | B45: 0 | C45: 0 | D45: 0 | E45: 0 | F45: 0 | G45: =SUM(B45:F45) -> 0
A46: Nota: Captaciones editable por año. Comisiones se cobran sobre capital nuevo.
...

Sheet RESULTADOS ASESOR TCMC (5Y)
A1: RESULTADOS ASESOR — MODELO TCMC 5 AÑOS (Propuesta ConoSur Mar-2026)
A2: Escenario ácido: USD 5M, sin captaciones. Fee 1% originación, hurdle 6%, carry 10%.
A4: I. MANAGEMENT FEE (Honorarios Asesor)
A5: Concepto | B5: 2026 | C5: 2027 | D5: 2028 | E5: 2029 | F5: 2030 | G5: TOTAL
A6: PN Inicio | B6: ='FLUJO 5 AÑOS (5Y)'!B47 -> 3000000 | C6: ='FLUJO 5 AÑOS (5Y)'!C47 -> 3240309.9 | D6: ='FLUJO 5 AÑOS (5Y)'!D47 -> 3358344.3 | E6: ='FLUJO 5 AÑOS (5Y)'!E47 -> 3611074.8 | F6: ='FLUJO 5 AÑOS (5Y)'!F47 -> 3840340.7 | G6: =SUM(B6:F6) -> 17050070
A7: Management Fee (0% — eliminado, modelo Lendar) | B7: ='FLUJO 5 AÑOS (5Y)'!B26 -> 0 | C7: ='FLUJO 5 AÑOS (5Y)'!C26 -> 0 | D7: ='FLUJO 5 AÑOS (5Y)'!D26 -> 0 | E7: ='FLUJO 5 AÑOS (5Y)'!E26 -> 0 | F7: ='FLUJO 5 AÑOS (5Y)'!F26 -> 0 | G7: =SUM(B7:F7) -> 0
A8: Fee por Crédito: 1% Orig + 1% Adq (ver SUPUESTOS B31/B32) | B8: ='FLUJO 5 AÑOS (5Y)'!B27 -> 49548.491 | C8: ='FLUJO 5 AÑOS (5Y)'!C27 -> 16744.433 | D8: ='FLUJO 5 AÑOS (5Y)'!D27 -> 43952.223 | E8: ='FLUJO 5 AÑOS (5Y)'!E27 -> 25735.627 | F8: ='FLUJO 5 AÑOS (5Y)'!F27 -> 2865.8228 | G8: =SUM(B8:F8) -> 138846.6
A9: TOTAL FEES ASESOR (dentro del fondo) | B9: =B7+B8 -> 49548.491 | C9: =C7+C8 -> 16744.433 | D9: =D7+D8 -> 43952.223 | E9: =E7+E8 -> 25735.627 | F9: =F7+F8 -> 2865.8228 | G9: =G7+G8 -> 138846.6
A11: II. CARRY WATERFALL (con tope 5.4% — Cl. 10.5)
A12: Concepto | B12: 2026 | C12: 2027 | D12: 2028 | E12: 2029 | F12: 2030 | G12: TOTAL
A13: EBITDA pre-carry | B13: ='FLUJO 5 AÑOS (5Y)'!B21-'FLUJO 5 AÑOS (5Y)'!B24-'FLUJO 5 AÑOS (5Y)'!B25-'FLUJO 5 AÑOS (5Y)'!B26-'FLUJO 5 AÑOS (5Y)'!B27-'FLUJO 5 AÑOS (5Y)'!B28-'FLUJO 5 AÑOS (5Y)'!B29-'FLUJO 5 AÑOS (5Y)'!B30-'FLUJO 5 AÑOS (5Y)'!B31 -> 240309.87 | C13: ='FLUJO 5 AÑOS (5Y)'!C21-'FLUJO 5 AÑOS (5Y)'!C24-'FLUJO 5 AÑOS (5Y)'!C25-'FLUJO 5 AÑOS (5Y)'!C26-'FLUJO 5 AÑOS (5Y)'!C27-'FLUJO 5 AÑOS (5Y)'!C28-'FLUJO 5 AÑOS (5Y)'!C29-'FLUJO 5 AÑOS (5Y)'!C30-'FLUJO 5 AÑOS (5Y)'!C31 -> 312453.04 | D13: ='FLUJO 5 AÑOS (5Y)'!D21-'FLUJO 5 AÑOS (5Y)'!D24-'FLUJO 5 AÑOS (5Y)'!D25-'FLUJO 5 AÑOS (5Y)'!D26-'FLUJO 5 AÑOS (5Y)'!D27-'FLUJO 5 AÑOS (5Y)'!D28-'FLUJO 5 AÑOS (5Y)'!D29-'FLUJO 5 AÑOS (5Y)'!D30-'FLUJO 5 AÑOS (5Y)'!D31 -> 454231.18 | E13: ='FLUJO 5 AÑOS (5Y)'!E21-'FLUJO 5 AÑOS (5Y)'!E24-'FLUJO 5 AÑOS (5Y)'!E25-'FLUJO 5 AÑOS (5Y)'!E26-'FLUJO 5 AÑOS (5Y)'!E27-'FLUJO 5 AÑOS (5Y)'!E28-'FLUJO 5 AÑOS (5Y)'!E29-'FLUJO 5 AÑOS (5Y)'!E30-'FLUJO 5 AÑOS (5Y)'!E31 -> 445930.31 | F13: ='FLUJO 5 AÑOS (5Y)'!F21-'FLUJO 5 AÑOS (5Y)'!F24-'FLUJO 5 AÑOS (5Y)'!F25-'FLUJO 5 AÑOS (5Y)'!F26-'FLUJO 5 AÑOS (5Y)'!F27-'FLUJO 5 AÑOS (5Y)'!F28-'FLUJO 5 AÑOS (5Y)'!F29-'FLUJO 5 AÑOS (5Y)'!F30-'FLUJO 5 AÑOS (5Y)'!F31 -> 308769.7 | G13: =SUM(B13:F13) -> 1761694.1
A14: Carry Devengado del Período | B14: =MAX(0,B13-'FLUJO 5 AÑOS (5Y)'!B47*SUPUESTOS!$B$34)*SUPUESTOS!$B$33 -> 6030.9873 | C14: =MAX(0,C13-'FLUJO 5 AÑOS (5Y)'!C47*SUPUESTOS!$B$34)*SUPUESTOS!$B$33 -> 11803.445 | D14: =MAX(0,D13-'FLUJO 5 AÑOS (5Y)'!D47*SUPUESTOS!$B$34)*SUPUESTOS!$B$33 -> 25273.052 | E14: =MAX(0,E13-'FLUJO 5 AÑOS (5Y)'!E47*SUPUESTOS!$B$34)*SUPUESTOS!$B$33 -> 22926.582 | F14: =MAX(0,F13-'FLUJO 5 AÑOS (5Y)'!F47*SUPUESTOS!$B$34)*SUPUESTOS!$B$33 -> 7834.9265 | G14: =SUM(B14:F14) -> 73868.993
A15: Carry Diferido Acum. (entrada) | B15: 0 | C15: =B19 -> 6030.9873 | D15: =C19 -> 17834.432 | E15: =D19 -> 43107.484 | F15: =E19 -> 66034.066
A16: Total Carry Pendiente (devengado + diferido) | B16: =B14+B15 -> 6030.9873 | C16: =C14+C15 -> 17834.432 | D16: =D14+D15 -> 43107.484 | E16: =E14+E15 -> 66034.066 | F16: =F14+F15 -> 73868.993 | G16: =SUM(B14:F14)+B15 -> 73868.993
A17: Espacio Disponible (5.4%*PN − costos cubiertos por tope) | B17: =MAX(0, SUPUESTOS!$B$35*'FLUJO 5 AÑOS (5Y)'!B47-('FLUJO 5 AÑOS (5Y)'!B24+'FLUJO 5 AÑOS (5Y)'!B25+'FLUJO 5 AÑOS (5Y)'!B26+'FLUJO 5 AÑOS (5Y)'!B27+'FLUJO 5 AÑOS (5Y)'!B28)) -> 0 | C17: =MAX(0, SUPUESTOS!$B$35*'FLUJO 5 AÑOS (5Y)'!C47-('FLUJO 5 AÑOS (5Y)'!C24+'FLUJO 5 AÑOS (5Y)'!C25+'FLUJO 5 AÑOS (5Y)'!C26+'FLUJO 5 AÑOS (5Y)'!C27+'FLUJO 5 AÑOS (5Y)'!C28)) -> 41748.581 | D17: =MAX(0, SUPUESTOS!$B$35*'FLUJO 5 AÑOS (5Y)'!D47-('FLUJO 5 AÑOS (5Y)'!D24+'FLUJO 5 AÑOS (5Y)'!D25+'FLUJO 5 AÑOS (5Y)'!D26+'FLUJO 5 AÑOS (5Y)'!D27+'FLUJO 5 AÑOS (5Y)'!D28)) -> 19498.239 | E17: =MAX(0, SUPUESTOS!$B$35*'FLUJO 5 AÑOS (5Y)'!E47-('FLUJO 5 AÑOS (5Y)'!E24+'FLUJO 5 AÑOS (5Y)'!E25+'FLUJO 5 AÑOS (5Y)'!E26+'FLUJO 5 AÑOS (5Y)'!E27+'FLUJO 5 AÑOS (5Y)'!E28)) -> 48329.516 | F17: =MAX(0, SUPUESTOS!$B$35*'FLUJO 5 AÑOS (5Y)'!F47-('FLUJO 5 AÑOS (5Y)'!F24+'FLUJO 5 AÑOS (5Y)'!F25+'FLUJO 5 AÑOS (5Y)'!F26+'FLUJO 5 AÑOS (5Y)'!F27+'FLUJO 5 AÑOS (5Y)'!F28)) -> 80828.485 | G17: =SUM(B17:F17) -> 190404.82
A18: Carry COBRADO (limitado por tope) | B18: 0 | C18: 0 | D18: 0 | E18: 0 | F18: =MIN(F16,F17) -> 73868.993 | G18: =SUM(B18:F18) -> 73868.993
A19: Carry Diferido Acum. (salida → pasa al año sig.) | B19: =B16-B18 -> 6030.9873 | C19: =C16-C18 -> 17834.432 | D19: =D16-D18 -> 43107.484 | E19: =E16-E18 -> 66034.066 | F19: =F16-F18 -> 0 | G19: =G16-G18 -> 0
A20: Nota: excluidos del tope 5.4%: comisiones colocador (row29), IVA upfront (row30), intereses deuda (row31)
A21: III. UPFRONT FEE EXTRACTION (pre-fondo)
A22: Concepto | B22: 2026 | C22: 2027 | D22: 2028 | E22: 2029 | F22: 2030 | G22: TOTAL
A23: Volumen Total Originado | B23: ='FLUJO 5 AÑOS (5Y)'!B10 -> 3963879.3 | C23: ='FLUJO 5 AÑOS (5Y)'!C10 -> 1339554.7 | D23: ='FLUJO 5 AÑOS (5Y)'!D10 -> 3516177.8 | E23: ='FLUJO 5 AÑOS (5Y)'!E10 -> 2058850.2 | F23: ='FLUJO 5 AÑOS (5Y)'!F10 -> 229265.82 | G23: =SUM(B23:F23) -> 11107728
A24: Upfront Total (5% del otorgado neto) | B24: =(B23/(1+SUPUESTOS!$B$73))*SUPUESTOS!$B$73 -> 188756.16 | C24: =(C23/(1+SUPUESTOS!$B$73))*SUPUESTOS!$B$73 -> 63788.317 | D24: =(D23/(1+SUPUESTOS!$B$73))*SUPUESTOS!$B$73 -> 167437.04 | E24: =(E23/(1+SUPUESTOS!$B$73))*SUPUESTOS!$B$73 -> 98040.484 | F24: =(F23/(1+SUPUESTOS!$B$73))*SUPUESTOS!$B$73 -> 10917.42 | G24: =SUM(B24:F24) -> 528939.42
A25: Porción al Fondo (4%) | B25: =(B23/(1+SUPUESTOS!$B$73))*SUPUESTOS!$B$74 -> 188756.16 | C25: =(C23/(1+SUPUESTOS!$B$73))*SUPUESTOS!$B$74 -> 63788.317 | D25: =(D23/(1+SUPUESTOS!$B$73))*SUPUESTOS!$B$74 -> 167437.04 | E25: =(E23/(1+SUPUESTOS!$B$73))*SUPUESTOS!$B$74 -> 98040.484 | F25: =(F23/(1+SUPUESTOS!$B$73))*SUPUESTOS!$B$74 -> 10917.42 | G25: =SUM(B25:F25) -> 528939.42
A26: Extracción Asesor Pre-Fondo (1%) | B26: =(B23/(1+SUPUESTOS!$B$73))*SUPUESTOS!$B$75 -> 0 | C26: =(C23/(1+SUPUESTOS!$B$73))*SUPUESTOS!$B$75 -> 0 | D26: =(D23/(1+SUPUESTOS!$B$73))*SUPUESTOS!$B$75 -> 0 | E26: =(E23/(1+SUPUESTOS!$B$73))*SUPUESTOS!$B$75 -> 0 | F26: =(F23/(1+SUPUESTOS!$B$73))*SUPUESTOS!$B$75 -> 0 | G26: =SUM(B26:F26) -> 0
A27: IVA sobre Extracción (21%) | B27: =B26*SUPUESTOS!$B$76 -> 0 | C27: =C26*SUPUESTOS!$B$76 -> 0 | D27: =D26*SUPUESTOS!$B$76 -> 0 | E27: =E26*SUPUESTOS!$B$76 -> 0 | F27: =F26*SUPUESTOS!$B$76 -> 0 | G27: =SUM(B27:F27) -> 0
A28: Neto Extracción (sin IVA) | B28: =B26 -> 0 | C28: =C26 -> 0 | D28: =D26 -> 0 | E28: =E26 -> 0 | F28: =F26 -> 0 | G28: =G26 -> 0
A29: Fee por Retiros de Liquidez (5% default) | B29: ='FLUJO 5 AÑOS (5Y)'!B81 -> 0 | C29: ='FLUJO 5 AÑOS (5Y)'!C81 -> 0 | D29: ='FLUJO 5 AÑOS (5Y)'!D81 -> 0 | E29: ='FLUJO 5 AÑOS (5Y)'!E81 -> 0 | F29: ='FLUJO 5 AÑOS (5Y)'!F81 -> 0 | G29: =SUM(B29:F29) -> 0
A30: TOTAL A COBRAR ASESOR TCMC (año por año) | B30: =B9+B18+B28+B29 -> 49548.491 | C30: =C9+C18+C28+C29+B32 -> 39992.925 | D30: =D9+D18+D28+D29+C32 -> 43952.223 | E30: =E9+E18+E28+E29+D32 -> 25735.627 | F30: =F9+F18+F28+F29+E32 -> 76734.816 | G30: =SUM(B30:F30) -> 235964.08
A31: TOTAL ACUMULADO (sumador) | B31: =B30 -> 49548.491 | C31: =B31+C30 -> 89541.416 | D31: =C31+D30 -> 133493.64 | E31: =D31+E30 -> 159229.27 | F31: =E31+F30 -> 235964.08
A32: SPONSOR (exceso >5.4% PN → pago fuera del fondo) | B32: =MAX(0, ('FLUJO 5 AÑOS (5Y)'!B24+'FLUJO 5 AÑOS (5Y)'!B25+'FLUJO 5 AÑOS (5Y)'!B26+'FLUJO 5 AÑOS (5Y)'!B27+'FLUJO 5 AÑOS (5Y)'!B28) - SUPUESTOS!$B$35*'FLUJO 5 AÑOS (5Y)'!B47) -> 23248.491 | C32: =MAX(0, ('FLUJO 5 AÑOS (5Y)'!C24+'FLUJO 5 AÑOS (5Y)'!C25+'FLUJO 5 AÑOS (5Y)'!C26+'FLUJO 5 AÑOS (5Y)'!C27+'FLUJO 5 AÑOS (5Y)'!C28) - SUPUESTOS!$B$35*'FLUJO 5 AÑOS (5Y)'!C47) -> 0 | D32: =MAX(0, ('FLUJO 5 AÑOS (5Y)'!D24+'FLUJO 5 AÑOS (5Y)'!D25+'FLUJO 5 AÑOS (5Y)'!D26+'FLUJO 5 AÑOS (5Y)'!D27+'FLUJO 5 AÑOS (5Y)'!D28) - SUPUESTOS!$B$35*'FLUJO 5 AÑOS (5Y)'!D47) -> 0 | E32: =MAX(0, ('FLUJO 5 AÑOS (5Y)'!E24+'FLUJO 5 AÑOS (5Y)'!E25+'FLUJO 5 AÑOS (5Y)'!E26+'FLUJO 5 AÑOS (5Y)'!E27+'FLUJO 5 AÑOS (5Y)'!E28) - SUPUESTOS!$B$35*'FLUJO 5 AÑOS (5Y)'!E47) -> 0 | F32: =MAX(0, ('FLUJO 5 AÑOS (5Y)'!F24+'FLUJO 5 AÑOS (5Y)'!F25+'FLUJO 5 AÑOS (5Y)'!F26+'FLUJO 5 AÑOS (5Y)'!F27+'FLUJO 5 AÑOS (5Y)'!F28) - SUPUESTOS!$B$35*'FLUJO 5 AÑOS (5Y)'!F47) -> 0 | G32: =SUM(B32:F32) -> 23248.491 | I32: Se cobra el año siguiente si hay lugar
A33: IV. RESUMEN TOTAL ASESOR — ESCENARIOS
A35: Escenario | B35: Total 5Y (USD) | C35: Promedio Anual
A36: A. Solo Fee por Crédito (1%/0.7%) | B36: =G8 -> 138846.6 | C36: =B36/5 -> 27769.319
A37: B. Fee Crédito + Carry | B37: =G8+G18 -> 212715.59 | C37: =B37/5 -> 42543.118
A38: C. Full (Fee Crédito + Carry + Extracción 1%) | B38: =G8+G18+G26 -> 212715.59 | C38: =B38/5 -> 42543.118
A39: D. Full + Fee Retiros Liquidez | B39: =G8+G18+G26+G29 -> 212715.59 | C39: =B39/5 -> 42543.118
A41: V. MÉTRICAS CLAVE
A42: TIR Inversor (post all fees) | B42: ='FLUJO 5 AÑOS (5Y)'!B65 -> 0.088919693
A43: MOIC | B43: ='FLUJO 5 AÑOS (5Y)'!B66 -> 1.3682255
A44: Total EBITDA Acumulado (6Y) | B44: =G13 -> 1761694.1
...

Sheet FLUJO 11 AÑOS
A1: FLUJO DEL FONDO — MODELO TCMC 11 AÑOS (Cono Sur / Capital Token Group, con captaciones)
A3: AÑO | B3: 2026 | C3: 2027 | D3: 2028 | E3: 2029 | F3: 2030 | G3: 2031 | H3: 2032 | I3: 2033 | J3: 2034 | K3: 2035 | L3: 2036 | M3: TOTAL
A4: A. CAPITAL Y ORIGINACIÓN
A5: Cartera Total Desplegada Inicio | B5: =B44*(1-SUPUESTOS!$B$36-SUPUESTOS!$B$37)+B14 -> 2947500 | C5: =C44+C14 -> 8276858.9 | D5: =D44+D14 -> 13582179 | E5: =E44+E14 -> 19097054 | F5: =F44+F14 -> 27830408 | G5: =G44+G14 -> 36929753 | H5: =H44+H14 -> 46390089 | I5: =I44+I14 -> 56225245 | J5: =J44+J14 -> 58450061 | ... L5: =L44+L14 -> 63057631
A6: Capital Liberado (Amortización) | B6: =B5*SUPUESTOS!$B$22 -> 1016379.3 | C6: =C5*SUPUESTOS!$B$22 -> 2854089.3 | D6: =D5*SUPUESTOS!$B$22 -> 4683509.9 | E6: =E5*SUPUESTOS!$B$22 -> 6585191 | F6: =F5*SUPUESTOS!$B$22 -> 9596692.3 | G6: =G5*SUPUESTOS!$B$22 -> 12734398 | H6: =H5*SUPUESTOS!$B$22 -> 15996582 | I6: =I5*SUPUESTOS!$B$22 -> 19388016 | ... L6: =L5*SUPUESTOS!$B$22 -> 21744011
A7: ¿Año de Originación Activa? | B7: 1 | C7: 1 | D7: 1 | E7: 1 | F7: 1 | G7: 1 | H7: 1 | I7: 1 | J7: 1 | K7: 1 | L7: 0
A8: Nuevos Créditos (re-originación) | B8: =IF(B7=1,B6*SUPUESTOS!$B$23,0) -> 1016379.3 | C8: =IF(C7=1,C6*SUPUESTOS!$B$23,0) -> 2854089.3 | D8: =IF(D7=1,D6*SUPUESTOS!$B$23,0) -> 4683509.9 | E8: =IF(E7=1,E6*SUPUESTOS!$B$23,0) -> 6585191 | F8: =IF(F7=1,F6*SUPUESTOS!$B$23,0) -> 9596692.3 | G8: =IF(G7=1,G6*SUPUESTOS!$B$23,0) -> 12734398 | H8: =IF(H7=1,H6*SUPUESTOS!$B$23,0) -> 15996582 | I8: =IF(I7=1,I6*SUPUESTOS!$B$23,0) -> 19388016 | ... L8: =IF(L7=1,L6*SUPUESTOS!$B$23,0) -> 0
A9: Stock de Capital Fin Año | B9: =B5-B6+B8 -> 2947500 | C9: =C5-C6+C8 -> 8276858.9 | D9: =D5-D6+D8 -> 13582179 | E9: =E5-E6+E8 -> 19097054 | F9: =F5-F6+F8 -> 27830408 | G9: =G5-G6+G8 -> 36929753 | H9: =H5-H6+H8 -> 46390089 | I9: =I5-I6+I8 -> 56225245 | ... L9: =L5-L6+L8 -> 41313620
