Workbook

Sheet TCA
A1: RESPUESTAS PROVISORIAS A CUESTIONARIO TCA — FCIC CRÉDITOS HIPOTECARIOS
A2: Fuente: Propuesta Cono Sur Investments (Marzo 2026) + definiciones Capital Token Group. Sujeto a revisión y confirmación.
A3: # | B3: Pregunta TCA | C3: Respuesta Provisoria | D3: Status / Notas
A4: SECCIÓN I — PAUTAS DE INVERSIÓN Y ESTRUCTURA DEL FCIC
A5: 1 | B5: Nombre del FCIC (debe constar desde el inicio para actas de creación de órganos) | C5: A definir. Propuesta: "TCMC Créditos Hipotecarios I" o "Tu Casa +Cerca I — FCIC de Créditos" | D5: PENDIENTE — Definir con CTG
A6: 2 | B6: Participantes: depositaria / asesor de inversiones / comité de inversiones (integración y pautas generales de funcionamiento) | C6: Sociedad Gerente: Cono Sur S.G.F.C.I.S.A. Sociedad Depositaria: Banco Comafi S.A. (a confirmar) Asesor de Inversión: Capital Token Group S.A. (en formación) Organizador/Asesor Financiero/Hacedor de Mercado: Cono Sur Inversiones S.A. Comité de Inversiones: integración y pautas a definir en reglamento de gestión | D6: CONFIRMADO por Cono Sur Depo. a confirmar CTG en formación
A7: 3 | B7: Monto del FCIC y cantidad de cuotapartes / posibilidad de aumento de monto y emisión de nuevas cuotapartes | C7: Primer tramo: mínimo USD 3.000.000. Máximo a definir según colocación. Meta de crecimiento a USD 30M (2026-2030). Cuotapartes: a definir VN unitario. Posibilidad de emitir nuevos tramos sujeto a asamblea y CNV. | D7: CORREGIDO 06/04 — Mínimo USD 3M, máximo según colocación (no fijo)
A8: 4 | B8: Plazo del FCIC | C8: Base: 5 años, ampliable a 11 años. Si se amplía, REVISAR con SL (asesor fiscal in-house) si se mantienen los beneficios impositivos (reducción/exención IG bajo Art. 206 Ley 27.440). Modelo financiero corre ambos escenarios. | D8: CORREGIDO 06/04 — 5Y base ampliable a 11Y. Validar fiscal con SL
A9: 5 | B9: Objetivo de inversión del FCIC | C9: Invertir en originación y/o adquisición de créditos hipotecarios a personas humanas destinados a vivienda en Argentina. Ticket promedio estimado USD 30.000. Plazos de crédito: 1 a 5 años. LTV máx 30%. El mix por duration se medirá contra mercado (no se predetermina la distribución por plazo). | D9: CORREGIDO 06/04 — Eliminado mix fijo por duration. Se mide contra mercado
A10: 6 | B10: Principales activos elegibles | C10: Activos específicos: créditos hipotecarios originados o adquiridos por el fondo, garantizados con hipoteca en primer grado sobre inmuebles residenciales en Argentina (min. 75% del patrimonio del fondo). Activos transitorios: FCI money market, depósitos bancarios, títulos públicos, ONs, VDF, cauciones y otros instrumentos líquidos (hasta 25% del patrimonio). | D10: CONFIRMADO por Cono Sur
A11: 7 | B11: Tipos de inversión en los activos elegibles | C11: Originación directa de créditos hipotecarios a personas humanas a través del canal Coldwell Banker (red inmobiliaria exclusiva). Sistema francés de amortización. Tasa fija en USD. | D11: PARCIAL — Confirmar si también adquisición de cartera de terceros
A12: 8 | B12: Pautas de diversificación y condiciones de elegibilidad de los activos | C12: Diversificación: ningún crédito individual puede exceder el 5% del patrimonio del fondo. Elegibilidad: (i) hipoteca en 1er grado, (ii) destino vivienda única o primera vivienda, (iii) LTV max 30%, (iv) inmueble en Argentina, (v) deudor persona humana con capacidad de repago verificada, (vi) seguro de vida del deudor, (vii) tasación por valuador independiente registrado. | D12: PROVISORIO — Sujeto a definición final de scoring y criterios de originación
A13: 9 | B13: Formas de valuación de activos | C13: Créditos performing: costo amortizado (valor presente de flujos futuros descontados a tasa de originación). Créditos en mora >90 días: valor recuperable neto (valor de garantía menos costos de ejecución). Activos transitorios: valor de mercado o cotización. | D13: PROVISORIO — Sujeto a validación con auditor y CNV
A14: 10 | B14: Tipo y Clases de cuotapartes | C14: Propuesta inicial: clase única de cuotapartes (cuotapartes de condominio). Alternativa a evaluar: Clase A (senior, renta fija) + Clase B (subordinada, equity). Cuotapartes escriturales, nominativas, no endosables. | D14: PENDIENTE — Definir si una o dos clases
A15: 11 | B15: Moneda del FCIC y bimonetariedad (suscripción y rescate en otras monedas para alguna clase) | C15: Moneda del fondo: dólares estadounidenses (USD). Suscripción: en USD. Evaluar posibilidad de suscripción en ARS al tipo de cambio MEP/CCL del día. Rescate: en USD. | D15: PARCIAL — Confirmar mecanismo de suscripción en ARS
A16: 12 | B16: Forma de integración (posibilidad de integración en especie) | C16: Integración en efectivo (USD). No se prevé integración en especie en la etapa inicial. Podría evaluarse para futuras ampliaciones la cesión de carteras de créditos hipotecarios como aporte en especie. | D16: PROVISORIO
... A19: 15 | B19: Forma de liquidación del FCIC | C19: Al vencimiento del plazo, por decisión de asamblea extraordinaria de cuotapartistas (mayoría calificada), o por eventos regulatorios previstos en Ley 24.083. Liquidación: realización ordenada de activos, pago de pasivos y distribución del remanente a prorrata. | D19: CONFIRMADO por Cono Sur
A21: SECCIÓN II — INFORMACIÓN DEL ASESOR DE INVERSIÓN (para Prospecto)
A22: 1 | B22: Denominación social | C22: Capital Token Group S.A. (en proceso de constitución) | D22: PENDIENTE — CTG en formación
A23: 2 | B23: CUIT | C23: A obtener con inscripción societaria | D23: PENDIENTE
A24: 3 | B24: Sede Social | C24: A definir (Buenos Aires, Argentina) | D24: PENDIENTE
A25: 4 | B25: Estatuto Social | C25: En redacción. Objeto social incluirá asesoramiento de inversión en FCI. | D25: PENDIENTE
A26: 5 | B26: Dirección de email | C26: A definir (ej. info@capitaltokengroup.com) | D26: PENDIENTE
A27: 6 | B27: Página web | C27: A definir. Landing actual del producto: developfb.github.io/TuCasaMasCerca/ | D27: PARCIAL
A28: 7 | B28: Datos registrales ante Registro Público de Comercio | C28: Pendiente de constitución e inscripción | D28: PENDIENTE
A29: 8 | B29: Nómina de miembros del Órgano de Administración y Fiscalización (fecha designación y vencimiento mandato) | C29: A completar una vez constituida la sociedad | D29: PENDIENTE — CTG
A30: 9 | B30: Nómina de Accionistas y/o Socios | C30: A completar una vez constituida la sociedad | D30: PENDIENTE — CTG
A31: 10 | B31: 0.015 | C31: 1.5% por crédito originado (one-time), cobrado al FCIC. El fondo recibe el 5% del tomador y paga 1.5% al asesor por la originación. | D31: CORREGIDO 06/04 — 1.5% (no 1%). El asesor cobra al fondo, no al tomador.
A32: 11 | B32: Reseña histórica de la empresa (info comercial/promocional) | C32: Capital Token Group nace como vehículo de inversión y asesoramiento enfocado en créditos hipotecarios de bajo monto (micro-mortgages) para el segmento de primera vivienda en Argentina, en alianza con la red inmobiliaria Coldwell Banker. | D32: PROVISORIO — Expandir
A33: 12 | B33: EECC anuales últimos 3 ejercicios | C33: No disponibles (sociedad en formación, sin ejercicios previos) | D33: N/A — Sociedad nueva
A34: 13 | B34: Información sobre política ambiental (si existe) | C34: En desarrollo. El fondo se orientará a financiar vivienda accesible, alineado con ODS 11 (Ciudades y Comunidades Sostenibles). | D34: PROVISORIO
B35: A DEFINIR | C35: NO replicar el tope fijo de 5.4% de Lendar. En su lugar: definir rendimiento objetivo en el plazo propuesto, sin comprometer un ratio transaccional fijo. Fundamento: el FCIC es un fondo a riesgo, no a renta fija. Un tope rígido obliga al sponsor a cubrir desfasajes financieros momentáneos, lo cual es inconsistente con la naturaleza del vehículo. Lendar (Cl. 10.5) fija 5.4% como referencia. | D35: CORREGIDO 06/04 — Sin tope fijo. Rendimiento objetivo, no transaccional. Fondo a riesgo.
A36: SECCIÓN III — ESTRUCTURA DE HONORARIOS (Ref. Propuesta Cono Sur)
A37: # | B37: Concepto | C37: Honorario / Comisión | D37: Responsable
A38: 1 | B38: 0.05 | C38: 5% + IVA cobrado al tomador del crédito. El 100% ingresa al FCIC como ingreso del fondo. No hay extracción pre-fondo. | D38: CORREGIDO 06/04 — Todo el 5% va al fondo. No hay split pre-fondo.
A39: 2 | B39: Sociedad Depositaria | C39: 0.20% anual del PN (en propuesta Cono Sur; modelo usa 0.15%) | D39: Banco Comafi S.A.
A40: 3 | B40: Asesor de Inversión (Mgmt Fee) | C40: Opción A (ACTIVA EN MODELO): SIN mgmt fee % PN → cobra 1% por crédito originado (one-time). Opción B (propuesta ConoSur): 1% PN + 10% carry >6% hurdle. SUPUESTOS fila 30: B30 = 0% (sin fee anual sobre PN). | D40: CORREGIDO — Modelo usa Opción A (0% PN). TCA anterior decía 1.25% → INCORRECTO
A41: 4 | B41: Carried Interest | C41: 10% sobre exceso de hurdle 6% — Consistente con Propuesta ConoSur Mar-2026. SUPUESTOS fila 33: B33 = 10%, fila 34: B34 = 6%. | D41: CONFIRMADO 06/04 — 10% carry sobre exceso hurdle 6%
A42: 5 | B42: Colocadores | C42: 1.50% del monto suscripto (one-time) — Propuesta ConoSur Mar-2026. SUPUESTOS fila 36: B36 = 1.5%. | D42: Cono Sur Inversiones + otros ACyDIs
A43: 6 | B43: Organizador | C43: 0.25% del monto suscripto (one-time) | D43: Cono Sur Inversiones S.A.
...

Sheet TODO LIST
A1: TODO LIST — TCMC FCIC
A2: Última reunión: 31 marzo 2026 | Próximo follow-up: semana 7-11 abril 2026
A4: A. ACCIONES POST-REUNIÓN 31/03/2026
A5: # | B5: Prioridad | C5: Tarea / Descripción | D5: Responsable | E5: Consultar con | F5: Deadline | G5: Estado / Notas
A6: 1 | B6: ALTA | C6: Elaborar Term Sheet (TS) del FCIC — resumen de términos y condiciones | D6: Gonzalo Ortiz / Pancho | E6: TCA (asesores legales) | F6: 10/04/2026 | G6: PENDIENTE — Usar datos Tanoira (Sección C) como base
A7: 2 | B7: ALTA | C7: Validar comisión up-front 5% que abona tomador a favor del FCIC | D7: Pancho | E7: TCA / SL (asesor fiscal) | F7: 10/04/2026 | G7: PENDIENTE — Definir si es IVA gravado
A8: 3 | B8: ALTA | C8: Confirmar si extensión de plazo FCIC (~5 a ~11 años) mantiene reducción/exención de IG | D8: CONO SUR | E8: SL (asesor fiscal in-house) | F8: 10/04/2026 | G8: PENDIENTE — Clave para definición de plazo
A9: 4 | B9: ALTA | C9: Definir mecanismo de liquidación (way out) del FCIC | D9: CONO SUR | E9: TCA (asesores legales) | F9: Reunión follow-up | G9: PENDIENTE
A10: 5 | B10: ALTA | C10: Definir mecanismo para ampliar monto o emitir nueva serie | D10: Gonzalo Ortiz / Pancho | E10: TCA (asesores legales) | F10: Reunión follow-up | G10: PENDIENTE
A11: 6 | B11: MEDIA | C11: Programa de liquidez para cuotapartes del FCIC | D11: CONO SUR | E11: A3 / BYMA (mercados) | F11: Reunión follow-up | G11: PENDIENTE — Evaluar market maker
A12: 7 | B12: MEDIA | C12: Mecanismo de recompra de cuotapartes por parte del FCIC | D12: Gonzalo Ortiz / Pancho | E12: TCA (asesores legales) | F12: Reunión follow-up | G12: PENDIENTE
A13: 8 | B13: MEDIA | C13: Apalancamiento mediante financiamiento garantizado con créditos del FCIC | D13: Gonzalo Ortiz / Pancho | E13: TCA / potenciales inversores | F13: Reunión follow-up | G13: PENDIENTE — Evaluar viabilidad regulatoria
A14: 9 | B14: MEDIA | C14: Mecanismo de venta de créditos por parte del FCIC | D14: CONO SUR | E14: TCA (asesores legales) | F14: Reunión follow-up | G14: PENDIENTE
A15: 10 | B15: ALTA | C15: Compartir TS con TCA, FAs de ConoSur y potenciales colocadores/distribuidores | D15: Gonzalo Ortiz / Pancho | E15: — | F15: Post 10/04 | G15: PENDIENTE — Depende de #1
A16: 11 | B16: ALTA | C16: Agendar reunión de follow-up | D16: Pancho | E16: Todos | F16: Semana 7-11/04 | G16: PENDIENTE
A18: B. FACTURACIÓN TCA (TANOIRA CASSAGNE) — USD 6.000 (30% gestión)
A19: # | B19: Prioridad | C19: Tarea / Descripción | D19: Responsable | E19: Consultar con | F19: Deadline | G19: Estado / Notas
A20: 12 | B20: ALTA | C20: Proveer datos de facturación a TCA para emisión factura USD 6K (30% valor gestión) | D20: Pancho | E20: TCA | F20: URGENTE | G20: Me contacto desde la administración de TCA Tanoira Cassagne. Nos encontramos en condiciones de avanzar con la facturación de USD 6.000 + impuestos, en concepto de FCI Cerrado - Cuota 1 - 30% emitida de manera anticipada al inicio de los trabajos Agradeceremos que nos brinden su conformidad y nos proporcionen los datos de facturación correspondientes para proceder con la emisión.
A21: 13 | B21: MEDIA | C21: Confirmar forma de pago y moneda de facturación | D21: Pancho | E21: TCA | F21: ASAP | G21: PENDIENTE
A23: C. INFORMACIÓN REQUERIDA POR TCA (TANOIRA CASSAGNE) — Para Reglamento y Prospecto
A25: C.1. DEFINICIONES ESTRUCTURALES DEL FCIC (15 puntos — para borrador de Reglamento de Gestión)
A26: # | C26: Pregunta / Requerimiento TCA | D26: Responsable | E26: Respuesta / Definición | F26: Estado | G26: Notas para TS
A27: C1.1 | C27: Nombre del FCIC | D27: Pancho / Gonzalo | F27: PENDIENTE | G27: Debe constar desde el inicio para actas de creación
A28: C1.2 | C28: Participantes: Depositaria / Asesor de Inversión / Comité de Inversiones (integración y pautas) | D28: Pancho / Gonzalo | F28: PENDIENTE | G28: Definir roles y funcionamiento
A29: C1.3 | C29: Monto del FCIC y cantidad de cuotapartes / posibilidad de aumento y nueva emisión | D29: Pancho / Gonzalo | F29: PENDIENTE | G29: Relacionado con tarea #5
A30: C1.4 | C30: Plazo del FCIC | D30: Pancho / SL | F30: PENDIENTE | G30: Relacionado con tarea #3 (5Y vs 11Y)
A31: C1.5 | C31: Objetivo de inversión del FCIC | D31: Pancho | F31: PENDIENTE | G31: Micro-hipotecas residenciales
A32: C1.6 | C32: Principales activos elegibles | D32: Pancho | F32: PENDIENTE | G32: Créditos hipotecarios
A33: C1.7 | C33: Tipos de inversión en los activos elegibles | D33: Pancho | F33: PENDIENTE
A34: C1.8 | C34: Pautas de diversificación y condiciones de elegibilidad de activos | D34: Pancho | F34: PENDIENTE | G34: LTV, cuota/ingreso, scoring
A35: C1.9 | C35: Formas de valuación de activos | D35: Pancho / Gonzalo | F35: PENDIENTE
A36: C1.10 | C36: Tipo y Clases de cuotapartes | D36: Pancho / TCA | F36: PENDIENTE
A37: C1.11 | C37: Moneda del FCIC y bimonetariedad (suscripción/rescate en otras monedas) | D37: Pancho | F37: PENDIENTE | G37: USD base
A38: C1.12 | C38: Forma de integración (posibilidad de integración en especie) | D38: Pancho / TCA | F38: PENDIENTE
A39: C1.13 | C39: Distribución de utilidades / posibilidad de capitalización | D39: Pancho / Gonzalo | F39: PENDIENTE | G39: Ver waterfall del modelo
A40: C1.14 | C40: Supuesto de rescate parcial anticipado | D40: Pancho / TCA | F40: PENDIENTE | G40: Relacionado con tarea #7
A41: C1.15 | C41: Forma de liquidación del FCIC | D41: Pancho / TCA | F41: PENDIENTE | G41: Relacionado con tarea #4
A43: C.2. DATOS DEL ASESOR DE INVERSIÓN — Para Prospecto (13 puntos)
A44: # | C44: Dato Requerido por TCA | D44: Responsable | E44: Dato / Documento | F44: Estado | G44: Notas
A45: C2.1 | C45: Denominación social | D45: Pancho | F45: PENDIENTE | G45: Nombre legal de +Cerca
...

Sheet SUPUESTOS
A1: MODELO TCMC — FCIC HIPOTECARIO (Cono Sur Investments)
A2: Basado en Propuesta ConoSur a Capital Token Group S.A., Marzo 2026. Capital: USD 5M Tramo I. Plazo base: 5yr / Alt: 11yr.
B3: TCMC (TBD) | C3: Detalle / Fuente | D3: LENDAR (Allaria) | E3: Detalle / CI (Cláusula Informativa)
A5: I. PARÁMETROS DEL FONDO
A6: Capital Inicial (USD) | B6: 3000000 | C6: Tramo 1 — Propuesta ConoSur Mar-2026: ≈USD 5M (ampliable). Mín emisión: USD 2.5M, Máx: USD 100M | D6: 3000000 | E6: No publicado. Usamos 3M como referencia. | F6: 2.4 Mínimo de emisión: 2.500.000 Máximo 100.000.000
A7: Plazo del Fondo (años) | B7: 11 | C7: Base: 5yr (ConoSur) / Alt: 11yr. ≈5 años con opción de extensión | D7: 11 | E7: Plazos crédito hasta 11 años. Cl. 16.3.5 | F7: 2.3.3 El vencimiento de los diversos créditos hipotecarios originados y/o adquiridos por el Fondo podrá operar con posterioridad al vencimiento del Plazo del Fondo.
A8: Ticket Promedio Crédito (USD) | B8: 40000 | C8: ≈USD 30,000 por crédito. Plazos 1-3 años. Aforos ≈30% | D8: N/D | E8: No publicado
A9: LTV Máximo | B9: 0.35 | C9: 30% — Propuesta ConoSur Mar-2026 | D9: 0.35 | E9: Presentación prensa Lendar | F9: 3.2.5 | G9: LTV máximo 35% según Cl. 3.2.5 Reglamento
A10: Moneda | B10: USD | C10: Dólares estadounidenses — Propuesta ConoSur Mar-2026 | D10: USD | E10: Cl. 2.5: "La moneda del Fondo será el Dólar Estadounidense"
A12: II. MIX DE CRÉDITOS
A13: Plazo (años) | B13: Tasa TNA | C13: Distribución % | D13: Lendar Tasa TNA | E13: Fuente CI
A14: 1 | B14: 0.105 | C14: 0.1 | D14: 0.095 | E14: Cl. 16.3.5 — piso de rango | G14: =-PMT((B14/12),(12*A14),(C14*B$6)) -> 26444.581
A15: 2 | B15: 0.115 | C15: 0.25 | D15: 0.105 | E15: 2.7 | G15: =-PMT((B15/12),(12*A15),(C15*B$6)) -> 35130.236
A16: 3 | B16: 0.125 | C16: 0.4 | D16: 0.115 | E16: 2.7 | G16: =-PMT((B16/12),(12*A16),(C16*B$6)) -> 40144.351
A17: 4 | B17: 0.135 | C17: 0.15 | D17: 0.125 | E17: 2.7 | G17: =-PMT((B17/12),(12*A17),(C17*B$6)) -> 12184.345
A18: 5 | B18: 0.145 | C18: 0.1 | D18: 0.135 | E18: Cl. 16.3.5 — techo de rango | G18: =-PMT((B18/12),(12*A18),(C18*B$6)) -> 7058.4843
G19: =SUM(G14:G18) -> 120962
A20: WAL (años) | B20: =A14*C14+A15*C15+A16*C16+A17*C17+A18*C18 -> 2.9 | G20: =G19*12 -> 1451544
A21: Tasa Media Ponderada | B21: =B14*C14+B15*C15+B16*C16+B17*C17+B18*C18 -> 0.124
A22: Rotación Anual (1/WAL) | B22: =1/B20 -> 0.34482759
A23: Rotación Imperfecta | B23: 1
A24: Tasa Media Ajustada | B24: =B21*B23 -> 0.124 | C24: =B24*0.7 -> 0.0868
A26: III. COSTOS DEL FONDO (% sobre PN)
A27: Concepto | B27: TCMC | C27: Detalle | D27: LENDAR | E27: CI Lendar
A28: Honorarios Soc. Gerente (anual) | B28: 0.012 | C28: 1.20% anual PN — Cono Sur S.G.F.C.I.S.A. (Propuesta ConoSur Mar-2026) | D28: 0.0125 | E28: Cl. 16.5.1: 1.25% anual del PN | F28: 10.1 | G28: Cl. 10.1: máx 1.20% anual del PN. Liquidación trimestral + IVA.
A29: Honorarios Soc. Depositaria (anual) | B29: 0.002 | C29: 0.20% anual PN neto — Banco Comafi S.A. (a confirmar). Mín USD 21,600+IVA/año (Propuesta ConoSur) | D29: 0.002 | E29: Cl. 16.5.2: 0.20% anual del PN. NOTA: parece caro vs mercado | F29: 10.3 | G29: Mínimo de 21600 USD + IVA anual. Fee inicial de 10000 USD + IVA (one-time). Si 0.2%*PN < 21600, aplica el mínimo.
A30: Honorarios Asesor Inversión (anual % PN) | B30: 0 | C30: Opción A (activa): SIN mgmt fee % PN, cobra por crédito. Alt B: 1% PN + 10% carry >6% hurdle (Propuesta ConoSur) | D30: 0 | E30: NO cobra % anual PN. Cobra one-time por crédito (ver abajo) | F30: 16.5 | G30: Lendar Cl. 16.5: NO prevé mgmt fee % PN para asesor. Solo fee por crédito (1%/0.7%)
A31: Fee Asesor por crédito originado (one-time) | B31: 0.0125 | C31: 1% por crédito originado — Propuesta ConoSur Mar-2026 (antes 1.5%) | D31: 0.01 | E31: Cl. 16.5.5: 1% por crédito originado directamente | F31: 16.5.5 | G31: Cl. 16.5.5: ≤1% anual del valor de cada crédito originado + IVA
A32: Fee Asesor por crédito adquirido (one-time) | B32: 0.01 | C32: 1% por crédito adquirido — Propuesta ConoSur Mar-2026 | D32: 0.007 | E32: Cl. 16.5.5: 0.7% por crédito adquirido a terceros | F32: 16.5.5 | G32: Cl. 16.5.5: ≤0.7% anual del valor de cada crédito adquirido + IVA
A33: Carried Interest | B33: 0.1 | C33: 10% sobre exceso hurdle — Opción B de Propuesta ConoSur Mar-2026. EDITABLE. | D33: 0 | E33: Cl. 16.4: No previsto. "No se garantiza rendimiento"
A34: Hurdle Rate | B34: 0.06 | C34: 6% hurdle rate — Propuesta ConoSur Mar-2026 (antes 10%). EDITABLE. | D34: 0 | E34: N/A — sin carry, sin hurdle
A35: Tope Máximo Gastos (Reglamento) | B35: 0.054 | C35: 5.4% anual PN — Propuesta ConoSur Mar-2026 | D35: 0.054 | E35: Cl. 16.5: Tope 5.4% anual PN | F35: 10.5 | G35: Cl. 10.5: tope gastos ordinarios + hon. Adm + Cust = 5.4% + IVA
A36: Comisión Colocadores (one-time) | B36: 0.015 | C36: 1.5% del monto suscripto — Propuesta ConoSur Mar-2026 | D36: 0.015 | E36: Cl. 16.5.4: 0.5% del monto suscripto | F36: 10.4
A37: Comisión Organizador (one-time) | B37: 0.0025 | C37: 0.25% del monto suscripto — Cono Sur Inversiones S.A. (Propuesta ConoSur Mar-2026) | D37: 0.0025 | E37: Incluida en Soc. Gerente según reglamento | F37: 10.4
A38: Upfront Fee al Fondo | B38: 0.05 | C38: 5% del monto otorgado (4% al fondo + 1% extracción asesor) — Propuesta ConoSur Mar-2026 | D38: 0.05 | E38: Cl. 16.3.5: 5% + IVA cobrado al tomador. Ingresa al fondo. | F38: 2.7 | G38: Cl. 2.7: CFT = tasa + amort + 5% fee + IVA. Cobrado al tomador.
A39: IVA | B39: 0.21 | D39: 0.21
A40: Mín. Anual Soc. Depositaria (USD sin IVA) | B40: 21600 | C40: Cl. 10.3: aplica si 0.2%*PN < este mínimo | D40: 21600 | E40: Cl. 10.3
A41: IV. COSTOS FIJOS ANUALES (USD)
A42: Auditoría externa | B42: 10000 | C42: Anual
A43: Asesoría legal | B43: 10000 | C43: Anual
...

Sheet FLUJO 5 AÑOS (5Y)
A1: FLUJO DEL FONDO — MODELO TCMC 5 AÑOS (Cono Sur / Capital Token Group, USD 5M)
A3: AÑO | B3: 2026 | C3: 2027 | D3: 2028 | E3: 2029 | F3: 2030 | G3: TOTAL
A4: A. CAPITAL Y ORIGINACIÓN | B4: 0.9 | C4: 1 | D4: 1 | E4: 1 | F4: 1
A5: Cartera Total Desplegada Inicio | B5: =B47*(1-SUPUESTOS!$B$36-SUPUESTOS!$B$37)+B14 -> 2947500 | C5: =B9+B42+C14-B14 -> 3187809.9 | D5: =C9+C42+D14-C14 -> 4985016.5 | E5: =D9+D42+E14-D14 -> 5237747 | F5: =E9+E42+F14-E14 -> 5467012.8
A6: Capital Liberado (Amortización) | B6: =B5*SUPUESTOS!$B$22 -> 1016379.3 | C6: =C5*SUPUESTOS!$B$22 -> 1099244.8 | D6: =D5*SUPUESTOS!$B$22 -> 1718971.2 | E6: =E5*SUPUESTOS!$B$22 -> 1806119.7 | F6: =F5*SUPUESTOS!$B$22 -> 1885176.8
A7: ¿Año de Originación Activa? | B7: 1 | C7: 1 | D7: 1 | E7: 1 | F7: 0
A8: Nuevos Créditos (re-originación) | B8: =IF(B7=1,B6*SUPUESTOS!$B$23,0) -> 1016379.3 | C8: =IF(C7=1,C6*SUPUESTOS!$B$23,0) -> 1099244.8 | D8: =IF(D7=1,D6*SUPUESTOS!$B$23,0) -> 1718971.2 | E8: =IF(E7=1,E6*SUPUESTOS!$B$23,0) -> 1806119.7 | F8: =IF(F7=1,F6*SUPUESTOS!$B$23,0) -> 0
A9: Stock de Capital Fin Año | B9: =B5-B6+B8 -> 2947500 | C9: =C5-C6+C8 -> 3187809.9 | D9: =D5-D6+D8 -> 4985016.5 | E9: =E5-E6+E8 -> 5237747 | F9: =F5-F6+F8 -> 3581836
A10: Volumen Total Originado | B10: =B5+B8 -> 3963879.3 | C10: =C8+MAX(0,C5-B9) -> 1339554.7 | D10: =D8+MAX(0,D5-C9) -> 3516177.8 | E10: =E8+MAX(0,E5-D9) -> 2058850.2 | F10: =F8+MAX(0,F5-E9) -> 229265.82 | G10: =SUM(B10:F10) -> 11107728
A12: B. APALANCAMIENTO (editar fila 13: 1=ajustar deuda al 50% PN, 0=mantener nivel anterior)
A13: ¿Ajustar deuda? (1=reset a 0.5x PN, 0=mantener) — editable por año | B13: 0 | C13: 0 | D13: 1 | E13: 0 | F13: 0 | G13: 0
A14: Deuda Senior (monto) | B14: =IF(B13=1, B47*SUPUESTOS!$B$52, 0) -> 0 | C14: =IF(C13=1, C47*SUPUESTOS!$B$52, B14) -> 0 | D14: =IF(D13=1, D47*SUPUESTOS!$B$52, C14) -> 1679172.2 | E14: =IF(E13=1, E47*SUPUESTOS!$B$52, D14) -> 1679172.2 | F14: =IF(F13=1, F47*SUPUESTOS!$B$52, E14) -> 1679172.2
A15: Capital Total Desplegado (Equity + Deuda) | B15: =B5 -> 2947500 | C15: =C5 -> 3187809.9 | D15: =D5 -> 4985016.5 | E15: =E5 -> 5237747 | F15: =F5 -> 5467012.8
A16: Leverage Ratio (Deuda / PN Inicio) | B16: =IF(B5>0,B14/B5,0) -> 0 | C16: =IF(C5>0,C14/C5,0) -> 0 | D16: =IF(D5>0,D14/D5,0) -> 0.33684385 | E16: =IF(E5>0,E14/E5,0) -> 0.32059054 | F16: =IF(F5>0,F14/F5,0) -> 0.30714619
A18: C. INGRESOS
A19: Interés Ganado (sobre capital total desplegado) | B19: =((B5+B9)/2)*SUPUESTOS!$B$24*B4 -> 328941 | C19: =((C5+C9)/2)*SUPUESTOS!$B$24*C4 -> 395288.42 | D19: =((D5+D9)/2)*SUPUESTOS!$B$24*D4 -> 618142.04 | E19: =((E5+E9)/2)*SUPUESTOS!$B$24*E4 -> 649480.63 | F19: =((F5+F9)/2)*SUPUESTOS!$B$24*F4 -> 561028.63 | G19: =SUM(B19:F19) -> 2552880.7
A20: Upfront Fee (4% al Fondo) | B20: =(B10/(1+SUPUESTOS!$B$38))*SUPUESTOS!$B$38 -> 188756.16 | C20: =(C10/(1+SUPUESTOS!$B$38))*SUPUESTOS!$B$38 -> 63788.317 | D20: =(D10/(1+SUPUESTOS!$B$38))*SUPUESTOS!$B$38 -> 167437.04 | E20: =(E10/(1+SUPUESTOS!$B$38))*SUPUESTOS!$B$38 -> 98040.484 | F20: =(F10/(1+SUPUESTOS!$B$38))*SUPUESTOS!$B$38 -> 10917.42 | G20: =SUM(B20:F20) -> 528939.42
A21: TOTAL INGRESOS FONDO | B21: =B19+B20 -> 517697.16 | C21: =C19+C20 -> 459076.74 | D21: =D19+D20 -> 785579.08 | E21: =E19+E20 -> 747521.11 | F21: =F19+F20 -> 571946.05 | G21: =SUM(B21:F21) -> 3081820.1
A23: D. COSTOS DEL FONDO
A24: Honorarios Soc. Gerente (1.2%) | B24: =B47*SUPUESTOS!$B$28 -> 36000 | C24: =C47*SUPUESTOS!$B$28 -> 38883.718 | D24: =D47*SUPUESTOS!$B$28 -> 40300.132 | E24: =E47*SUPUESTOS!$B$28 -> 43332.898 | F24: =F47*SUPUESTOS!$B$28 -> 46084.088 | G24: =SUM(B24:F24) -> 204600.84
A25: Honorarios Soc. Depositaria (0.2%, mín $21,600/yr + $10K inicial Y1) | B25: =MAX(B47*SUPUESTOS!$B$29,SUPUESTOS!$B$40)+10000 -> 31600 | C25: =MAX(C47*SUPUESTOS!$B$29,SUPUESTOS!$B$40) -> 21600 | D25: =MAX(D47*SUPUESTOS!$B$29,SUPUESTOS!$B$40) -> 21600 | E25: =MAX(E47*SUPUESTOS!$B$29,SUPUESTOS!$B$40) -> 21600 | F25: =MAX(F47*SUPUESTOS!$B$29,SUPUESTOS!$B$40) -> 21600 | G25: =SUM(B25:F25) -> 118000
A26: Honorarios Asesor Inversión (0% PN — eliminado) | B26: =B47*SUPUESTOS!$B$30 -> 0 | C26: =C47*SUPUESTOS!$B$30 -> 0 | D26: =D47*SUPUESTOS!$B$30 -> 0 | E26: =E47*SUPUESTOS!$B$30 -> 0 | F26: =F47*SUPUESTOS!$B$30 -> 0 | G26: =SUM(B26:F26) -> 0
A27: Fee Asesor (Originación + Adquisición) | B27: =B10*(SUPUESTOS!$B$31) -> 49548.491 | C27: =C10*(SUPUESTOS!$B$31) -> 16744.433 | D27: =D10*(SUPUESTOS!$B$31) -> 43952.223 | E27: =E10*(SUPUESTOS!$B$31) -> 25735.627 | F27: =F10*(SUPUESTOS!$B$31) -> 2865.8228 | G27: =SUM(B27:F27) -> 138846.6
A28: Costos Fijos Operativos | B28: =SUPUESTOS!$B$42+SUPUESTOS!$B$43+SUPUESTOS!$B$44+SUPUESTOS!$B$45+SUPUESTOS!$B$46+SUPUESTOS!$B$47+SUPUESTOS!$B$48 -> 68100 | C28: =SUPUESTOS!$B$42+SUPUESTOS!$B$43+SUPUESTOS!$B$45+SUPUESTOS!$B$46+SUPUESTOS!$B$47+SUPUESTOS!$B$48 -> 56000 | D28: =SUPUESTOS!$B$42+SUPUESTOS!$B$43+SUPUESTOS!$B$45+SUPUESTOS!$B$46+SUPUESTOS!$B$47+SUPUESTOS!$B$48 -> 56000 | E28: =SUPUESTOS!$B$42+SUPUESTOS!$B$43+SUPUESTOS!$B$45+SUPUESTOS!$B$46+SUPUESTOS!$B$47+SUPUESTOS!$B$48 -> 56000 | F28: =SUPUESTOS!$B$42+SUPUESTOS!$B$43+SUPUESTOS!$B$45+SUPUESTOS!$B$46+SUPUESTOS!$B$47+SUPUESTOS!$B$48 -> 56000 | G28: =SUM(B28:F28) -> 292100
A29: Comisiones (Colocador+Org) sobre capital | B29: =(SUPUESTOS!$B$6+B45)*(SUPUESTOS!$B$36+SUPUESTOS!$B$37) -> 52500 | C29: =C45*(SUPUESTOS!$B$36+SUPUESTOS!$B$37) -> 0 | D29: =D45*(SUPUESTOS!$B$36+SUPUESTOS!$B$37) -> 0 | E29: =E45*(SUPUESTOS!$B$36+SUPUESTOS!$B$37) -> 0 | F29: =F45*(SUPUESTOS!$B$36+SUPUESTOS!$B$37) -> 0 | G29: =SUM(B29:F29) -> 52500
A30: IVA sobre Upfront Fee (REVISAR: ¿lo paga el fondo o el tomador?) | B30: =B20*SUPUESTOS!$B$39 -> 39638.793 | C30: =C20*SUPUESTOS!$B$39 -> 13395.547 | D30: =D20*SUPUESTOS!$B$39 -> 35161.778 | E30: =E20*SUPUESTOS!$B$39 -> 20588.502 | F30: =F20*SUPUESTOS!$B$39 -> 2292.6582 | G30: =SUM(B30:F30) -> 111077.28
A31: Intereses Deuda Senior | B31: =B14*SUPUESTOS!$B$54 -> 0 | C31: =C14*SUPUESTOS!$B$54 -> 0 | D31: =D14*SUPUESTOS!$B$54 -> 134333.77 | E31: =E14*SUPUESTOS!$B$54 -> 134333.77 | F31: =F14*SUPUESTOS!$B$54 -> 134333.77 | G31: =SUM(B31:F31) -> 403001.32
A32: TOTAL COSTOS | B32: =B24+B25+B26+B27+B28+B29+B30+B31+B34 -> 277387.28 | C32: =C24+C25+C26+C27+C28+C29+C30+C31+C34 -> 146623.7 | D32: =D24+D25+D26+D27+D28+D29+D30+D31+D34 -> 331347.91 | E32: =E24+E25+E26+E27+E28+E29+E30+E31+E34 -> 301590.8 | F32: =F24+F25+F26+F27+F28+F29+F30+F31+F34 -> 337045.33 | G32: =SUM(B32:F32) -> 1393995
A33: Carry devengado del período | B33: ='RESULTADOS ASESOR TCMC (5Y)'!B14 -> 6030.9873 | C33: ='RESULTADOS ASESOR TCMC (5Y)'!C14 -> 11803.445 | D33: ='RESULTADOS ASESOR TCMC (5Y)'!D14 -> 25273.052 | E33: ='RESULTADOS ASESOR TCMC (5Y)'!E14 -> 22926.582 | F33: ='RESULTADOS ASESOR TCMC (5Y)'!F14 -> 7834.9265 | G33: ='RESULTADOS ASESOR TCMC (5Y)'!G14 -> 73868.993
A34: Carry COBRADO (Success Fee: sólo al cierre Y6, tope 5% Cl.10.5) | B34: ='RESULTADOS ASESOR TCMC (5Y)'!B18 -> 0 | C34: ='RESULTADOS ASESOR TCMC (5Y)'!C18 -> 0 | D34: ='RESULTADOS ASESOR TCMC (5Y)'!D18 -> 0 | E34: ='RESULTADOS ASESOR TCMC (5Y)'!E18 -> 0 | F34: ='RESULTADOS ASESOR TCMC (5Y)'!F18 -> 73868.993 | G34: ='RESULTADOS ASESOR TCMC (5Y)'!G18 -> 73868.993
B35: =(B32-B31)/B48 -> 0.085605172 | C35: =(C32-C31)/C48 -> 0.04127033 | D35: =(D32-D31)/D48 -> 0.051674815 | E35: =(E32-E31)/E48 -> 0.041226723 | F35: =(F32-F31)/F48 -> 0.049742222
A36: =CONCATENATE("SPONSOR SI > ",SUPUESTOS!B35*100,"%") -> SPONSOR SI > 5.4% | B36: =IF(B35>SUPUESTOS!$B$35,(B48*SUPUESTOS!$B$35)-B32,0) -> -102410.55 | C36: =IF(C35>SUPUESTOS!$B$35,(C48*SUPUESTOS!$B$35)-C32,0) -> 0 | D36: =IF(D35>SUPUESTOS!$B$35,(D48*SUPUESTOS!$B$35)-D32,0) -> 0 | E36: =IF(E35>SUPUESTOS!$B$35,(E48*SUPUESTOS!$B$35)-E32,0) -> 0 | F36: =IF(F35>SUPUESTOS!$B$35,(F48*SUPUESTOS!$B$35)-F32,0) -> 0
A38: E. RESULTADO
A39: EBITDA Fondo (neto de carry) | B39: =B21-B32 -> 240309.87 | C39: =C21-C32 -> 312453.04 | D39: =D21-D32 -> 454231.18 | E39: =E21-E32 -> 445930.31 | F39: =F21-F32 -> 234900.71 | G39: =SUM(B39:F39) -> 1687825.1
A40: EBITDA / Equity (%) | B40: =IF(B47>0,B39/B47,0) -> 0.080103291 | C40: =IF(C47>0,C39/C47,0) -> 0.096426902 | D40: =IF(D47>0,D39/D47,0) -> 0.1352545 | E40: =IF(E47>0,E39/E47,0) -> 0.12348963 | F40: =IF(F47>0,F39/F47,0) -> 0.061166634
A41: Retiros Parciales Inversores (detalle filas 69-80) | B41: =B79 -> 0 | C41: =C79 -> 194418.59 | D41: =D79 -> 201500.66 | E41: =E79 -> 216664.49 | F41: =F79 -> 0 | G41: =SUM(B41:F41) -> 612583.74
A42: Neto Reinvertido / Acumulado | B42: =B39-B41 -> 240309.87 | C42: =C39-C41 -> 118034.45 | D42: =D39-D41 -> 252730.52 | E42: =E39-E41 -> 229265.82 | F42: =F39-F41 -> 234900.71 | G42: =SUM(B42:F42) -> 1075241.4
A44: F. PATRIMONIO NETO
A45: Captaciones Nuevas (ingreso capital por año) | B45: 0 | C45: 0 | D45: 0 | E45: 0 | F45: 0 | G45: =SUM(B45:F45) -> 0
A46: Nota: Captaciones editable por año. Comisiones se cobran sobre capital nuevo.
...

Sheet Copia de FLUJO 5 AÑOS (5Y)
A1: FLUJO DEL FONDO — MODELO TCMC 5 AÑOS (Cono Sur / Capital Token Group, USD 5M)
B2: 0.96
A3: AÑO | B3: 2026 | C3: 2027 | D3: 2028 | E3: 2029 | F3: 2030 | G3: TOTAL
A4: A. CAPITAL Y ORIGINACIÓN
A5: Cartera Total Desplegada Inicio | B5: =(B44*(1-SUPUESTOS!$B$36-SUPUESTOS!$B$37)+B14)*B2 -> 2829600 | C5: =(C44+C14) -> 3258256.5 | D5: =(D44+D14) -> 5081919.9 | E5: =(E44+E14) -> 5343094.2 | F5: =(F44+F14) -> 5580773
A6: Capital Liberado (Amortización) | B6: =B5*SUPUESTOS!$B$22 -> 975724.14 | C6: =(C5*SUPUESTOS!$B$22)*($B2) -> 1078595.3 | D6: =(D5*SUPUESTOS!$B$22)*($B2) -> 1682290.7 | E6: =(E5*SUPUESTOS!$B$22)*($B2) -> 1768748.4 | F6: =(F5*SUPUESTOS!$B$22)*($B2) -> 1847428.3
A7: ¿Año de Originación Activa? | B7: 1 | C7: 1 | D7: 1 | E7: 1 | F7: 0
A8: Nuevos Créditos (re-originación) | B8: =IF(B7=1,B6*SUPUESTOS!$B$23,0) -> 975724.14 | C8: =IF(C7=1,C6*SUPUESTOS!$B$23,0) -> 1078595.3 | D8: =IF(D7=1,D6*SUPUESTOS!$B$23,0) -> 1682290.7 | E8: =IF(E7=1,E6*SUPUESTOS!$B$23,0) -> 1768748.4 | F8: =IF(F7=1,F6*SUPUESTOS!$B$23,0) -> 0
A9: Stock de Capital Fin Año | B9: =B5-B6+B8 -> 2829600 | C9: =C5-C6+C8 -> 3258256.5 | D9: =D5-D6+D8 -> 5081919.9 | E9: =E5-E6+E8 -> 5343094.2 | F9: =F5-F6+F8 -> 3733344.7
A10: Volumen Total Originado | B10: =B5+B8 -> 3805324.1 | C10: =C8+MAX(0,C5-B9) -> 1507251.8 | D10: =D8+MAX(0,D5-C9) -> 3505954.1 | E10: =E8+MAX(0,E5-D9) -> 2029922.7 | F10: =F8+MAX(0,F5-E9) -> 237678.83 | G10: =SUM(B10:F10) -> 11086132
A12: B. APALANCAMIENTO (editar fila 13: 1=ajustar deuda al 50% PN, 0=mantener nivel anterior)
A13: ¿Ajustar deuda? (1=reset a 0.5x PN, 0=mantener) — editable por año | B13: 0 | C13: 0 | D13: 1 | E13: 0 | F13: 0 | G13: 0
A14: Deuda Senior (monto) | B14: =IF(B13=1, B44*SUPUESTOS!$B$52, 0) -> 0 | C14: =IF(C13=1, C44*SUPUESTOS!$B$52, B14) -> 0 | D14: =IF(D13=1, D44*SUPUESTOS!$B$52, C14) -> 1693973.3 | E14: =IF(E13=1, E44*SUPUESTOS!$B$52, D14) -> 1693973.3 | F14: =IF(F13=1, F44*SUPUESTOS!$B$52, E14) -> 1693973.3
A15: Capital Total Desplegado (Equity + Deuda) | B15: =B5 -> 2829600 | C15: =C5 -> 3258256.5 | D15: =D5 -> 5081919.9 | E15: =E5 -> 5343094.2 | F15: =F5 -> 5580773
A16: Leverage Ratio (Deuda / PN Inicio) | B16: =IF(B5>0,B14/B5,0) -> 0 | C16: =IF(C5>0,C14/C5,0) -> 0 | D16: =IF(D5>0,D14/D5,0) -> 0.33333333 | E16: =IF(E5>0,E14/E5,0) -> 0.31703976 | F16: =IF(F5>0,F14/F5,0) -> 0.30353739
A18: C. INGRESOS
A19: Interés Ganado (sobre capital total desplegado) | B19: =IF(B7=1,B5*SUPUESTOS!$B$24,B5*SUPUESTOS!$B$24/2) -> 350870.4 | C19: =IF(C7=1,C5*SUPUESTOS!$B$24,C5*SUPUESTOS!$B$24/2) -> 404023.81 | D19: =IF(D7=1,D5*SUPUESTOS!$B$24,D5*SUPUESTOS!$B$24/2) -> 630158.07 | E19: =IF(E7=1,E5*SUPUESTOS!$B$24,E5*SUPUESTOS!$B$24/2) -> 662543.68 | F19: =IF(F7=1,F5*SUPUESTOS!$B$24,F5*SUPUESTOS!$B$24/2) -> 346007.93 | G19: =SUM(B19:F19) -> 2393603.9
A20: Upfront Fee (4% al Fondo) | B20: =(B10/(1+SUPUESTOS!$B$38))*SUPUESTOS!$B$38 -> 181205.91 | C20: =(C10/(1+SUPUESTOS!$B$38))*SUPUESTOS!$B$38 -> 71773.894 | D20: =(D10/(1+SUPUESTOS!$B$38))*SUPUESTOS!$B$38 -> 166950.19 | E20: =(E10/(1+SUPUESTOS!$B$38))*SUPUESTOS!$B$38 -> 96662.985 | F20: =(F10/(1+SUPUESTOS!$B$38))*SUPUESTOS!$B$38 -> 11318.04 | G20: =SUM(B20:F20) -> 527911.02
A21: TOTAL INGRESOS FONDO | B21: =B19+B20 -> 532076.31 | C21: =C19+C20 -> 475797.7 | D21: =D19+D20 -> 797108.26 | E21: =E19+E20 -> 759206.66 | F21: =F19+F20 -> 357325.97 | G21: =SUM(B21:F21) -> 2921514.9
A23: D. COSTOS DEL FONDO
A24: Honorarios Soc. Gerente (1.2%) | B24: =B44*SUPUESTOS!$B$28 -> 36000 | C24: =C44*SUPUESTOS!$B$28 -> 39099.078 | D24: =D44*SUPUESTOS!$B$28 -> 40655.359 | E24: =E44*SUPUESTOS!$B$28 -> 43789.45 | F24: =F44*SUPUESTOS!$B$28 -> 46641.596 | G24: =SUM(B24:F24) -> 206185.48
A25: Honorarios Soc. Depositaria (0.2%, mín $21,600/yr + $10K inicial Y1) | B25: =MAX(B44*SUPUESTOS!$B$29,SUPUESTOS!$B$40)+10000 -> 31600 | C25: =MAX(C44*SUPUESTOS!$B$29,SUPUESTOS!$B$40) -> 21600 | D25: =MAX(D44*SUPUESTOS!$B$29,SUPUESTOS!$B$40) -> 21600 | E25: =MAX(E44*SUPUESTOS!$B$29,SUPUESTOS!$B$40) -> 21600 | F25: =MAX(F44*SUPUESTOS!$B$29,SUPUESTOS!$B$40) -> 21600 | G25: =SUM(B25:F25) -> 118000
A26: Honorarios Asesor Inversión (0% PN — eliminado) | B26: =B44*SUPUESTOS!$B$30 -> 0 | C26: =C44*SUPUESTOS!$B$30 -> 0 | D26: =D44*SUPUESTOS!$B$30 -> 0 | E26: =E44*SUPUESTOS!$B$30 -> 0 | F26: =F44*SUPUESTOS!$B$30 -> 0 | G26: =SUM(B26:F26) -> 0
A27: Fee Asesor (Originación + Adquisición) | B27: =B10*(SUPUESTOS!$B$31) -> 47566.552 | C27: =C10*(SUPUESTOS!$B$31) -> 18840.647 | D27: =D10*(SUPUESTOS!$B$31) -> 43824.426 | E27: =E10*(SUPUESTOS!$B$31) -> 25374.034 | F27: =F10*(SUPUESTOS!$B$31) -> 2970.9854 | G27: =SUM(B27:F27) -> 138576.64
A28: Costos Fijos Operativos | B28: =SUPUESTOS!$B$42+SUPUESTOS!$B$43+SUPUESTOS!$B$44+SUPUESTOS!$B$45+SUPUESTOS!$B$46+SUPUESTOS!$B$47+SUPUESTOS!$B$48 -> 68100 | C28: =SUPUESTOS!$B$42+SUPUESTOS!$B$43+SUPUESTOS!$B$45+SUPUESTOS!$B$46+SUPUESTOS!$B$47+SUPUESTOS!$B$48 -> 56000 | D28: =SUPUESTOS!$B$42+SUPUESTOS!$B$43+SUPUESTOS!$B$45+SUPUESTOS!$B$46+SUPUESTOS!$B$47+SUPUESTOS!$B$48 -> 56000 | E28: =SUPUESTOS!$B$42+SUPUESTOS!$B$43+SUPUESTOS!$B$45+SUPUESTOS!$B$46+SUPUESTOS!$B$47+SUPUESTOS!$B$48 -> 56000 | F28: =SUPUESTOS!$B$42+SUPUESTOS!$B$43+SUPUESTOS!$B$45+SUPUESTOS!$B$46+SUPUESTOS!$B$47+SUPUESTOS!$B$48 -> 56000 | G28: =SUM(B28:F28) -> 292100
A29: Comisiones (Colocador+Org) sobre capital | B29: =(SUPUESTOS!$B$6+B42)*(SUPUESTOS!$B$36+SUPUESTOS!$B$37) -> 52500 | C29: =C42*(SUPUESTOS!$B$36+SUPUESTOS!$B$37) -> 0 | D29: =D42*(SUPUESTOS!$B$36+SUPUESTOS!$B$37) -> 0 | E29: =E42*(SUPUESTOS!$B$36+SUPUESTOS!$B$37) -> 0 | F29: =F42*(SUPUESTOS!$B$36+SUPUESTOS!$B$37) -> 0 | G29: =SUM(B29:F29) -> 52500
A30: IVA sobre Upfront Fee (REVISAR: ¿lo paga el fondo o el tomador?) | B30: =B20*SUPUESTOS!$B$39 -> 38053.241 | C30: =C20*SUPUESTOS!$B$39 -> 15072.518 | D30: =D20*SUPUESTOS!$B$39 -> 35059.541 | E30: =E20*SUPUESTOS!$B$39 -> 20299.227 | F30: =F20*SUPUESTOS!$B$39 -> 2376.7883 | G30: =SUM(B30:F30) -> 110861.32
A31: Intereses Deuda Senior | B31: =B14*SUPUESTOS!$B$54 -> 0 | C31: =C14*SUPUESTOS!$B$54 -> 0 | D31: =D14*SUPUESTOS!$B$54 -> 135517.86 | E31: =E14*SUPUESTOS!$B$54 -> 135517.86 | F31: =F14*SUPUESTOS!$B$54 -> 135517.86 | G31: =SUM(B31:F31) -> 406553.59
A32: TOTAL COSTOS | B32: =B24+B25+B26+B27+B28+B29+B30+B31+B34 -> 273819.79 | C32: =C24+C25+C26+C27+C28+C29+C30+C31+C34 -> 150612.24 | D32: =D24+D25+D26+D27+D28+D29+D30+D31+D34 -> 332657.19 | E32: =E24+E25+E26+E27+E28+E29+E30+E31+E34 -> 302580.57 | F32: =F24+F25+F26+F27+F28+F29+F30+F31+F34 -> 338976.23 | G32: =SUM(B32:F32) -> 1398646
A33: Carry devengado del período | B33: ='RESULTADOS ASESOR TCMC (5Y)'!B14 -> 6030.9873 | C33: ='RESULTADOS ASESOR TCMC (5Y)'!C14 -> 11803.445 | D33: ='RESULTADOS ASESOR TCMC (5Y)'!D14 -> 25273.052 | E33: ='RESULTADOS ASESOR TCMC (5Y)'!E14 -> 22926.582 | F33: ='RESULTADOS ASESOR TCMC (5Y)'!F14 -> 7834.9265 | G33: ='RESULTADOS ASESOR TCMC (5Y)'!G14 -> 73868.993
A34: Carry COBRADO (Success Fee: sólo al cierre Y6, tope 5% Cl.10.5) | B34: ='RESULTADOS ASESOR TCMC (5Y)'!B18 -> 0 | C34: ='RESULTADOS ASESOR TCMC (5Y)'!C18 -> 0 | D34: ='RESULTADOS ASESOR TCMC (5Y)'!D18 -> 0 | E34: ='RESULTADOS ASESOR TCMC (5Y)'!E18 -> 0 | F34: ='RESULTADOS ASESOR TCMC (5Y)'!F18 -> 73868.993 | G34: ='RESULTADOS ASESOR TCMC (5Y)'!G18 -> 73868.993
A35: E. RESULTADO
A36: EBITDA Fondo (neto de carry) | B36: =B21-B32 -> 258256.52 | C36: =C21-C32 -> 325185.46 | D36: =D21-D32 -> 464451.07 | E36: =E21-E32 -> 456626.09 | F36: =F21-F32 -> 18349.739 | G36: =SUM(B36:F36) -> 1522868.9
A37: EBITDA / Equity (%) | B37: =IF(B44>0,B36/B44,0) -> 0.086085506 | C37: =IF(C44>0,C36/C44,0) -> 0.099803517 | D37: =IF(D44>0,D36/D44,0) -> 0.13708925 | E37: =IF(E44>0,E36/E44,0) -> 0.12513318 | F37: =IF(F44>0,F36/F44,0) -> 0.0047210404
A38: Retiros Parciales Inversores (detalle filas 69-80) | B38: =B76 -> 0 | C38: =C76 -> 195495.39 | D38: =D76 -> 203276.8 | E38: =E76 -> 218947.25 | F38: =F76 -> 0 | G38: =SUM(B38:F38) -> 617719.44
A39: Neto Reinvertido / Acumulado | B39: =B36-B38 -> 258256.52 | C39: =C36-C38 -> 129690.07 | D39: =D36-D38 -> 261174.27 | E39: =E36-E38 -> 237678.83 | F39: =F36-F38 -> 18349.739 | G39: =SUM(B39:F39) -> 905149.43
A41: F. PATRIMONIO NETO
A42: Captaciones Nuevas (ingreso capital por año) | B42: 0 | C42: 0 | D42: 0 | E42: 0 | F42: 0 | G42: =SUM(B42:F42) -> 0
A43: Nota: Captaciones editable por año. Comisiones se cobran sobre capital nuevo.
A44: PN Inicio | B44: =SUPUESTOS!$B$6+B42 -> 3000000 | C44: =B45-B38+C42 -> 3258256.5 | D44: =C45-C38+D42 -> 3387946.6 | E44: =D45-D38+E42 -> 3649120.9 | F44: =E45-E38+F42 -> 3886799.7
...

Sheet RESULTADOS ASESOR TCMC (5Y)
A1: RESULTADOS ASESOR — MODELO TCMC 5 AÑOS (Propuesta ConoSur Mar-2026)
A2: Escenario ácido: USD 5M, sin captaciones. Fee 1% originación, hurdle 6%, carry 10%.
A4: I. MANAGEMENT FEE (Honorarios Asesor)
A5: Concepto | B5: 2026 | C5: 2027 | D5: 2028 | E5: 2029 | F5: 2030 | G5: TOTAL
A6: PN Inicio | B6: ='FLUJO 5 AÑOS (5Y)'!B47 -> 3000000 | C6: ='FLUJO 5 AÑOS (5Y)'!C47 -> 3240309.9 | D6: ='FLUJO 5 AÑOS (5Y)'!D47 -> 3358344.3 | E6: ='FLUJO 5 AÑOS (5Y)'!E47 -> 3611074.8 | F6: ='FLUJO 5 AÑOS (5Y)'!F47 -> 3840340.7 | G6: =SUM(B6:F6) -> 17050070
A7: Management Fee (0% — eliminado, modelo Lendar) | B7: ='FLUJO 5 AÑOS (5Y)'!B26 -> 0 | C7: ='FLUJO 5 AÑOS (5Y)'!C26 -> 0 | D7: ='FLUJO 5 AÑOS (5Y)'!D26 -> 0 | E7: ='FLUJO 5 AÑOS (5Y)'!E26 -> 0 | F7: ='FLUJO 5 AÑOS (5Y)'!F26 -> 0 | G7: =SUM(B7:F7) -> 0
A8: Fee por Crédito: 1% Orig + 1% Adq (ver SUPUESTOS B31/B32) | B8: ='FLUJO 5 AÑOS (5Y)'!B27 -> 49548.491 | C8: ='FLUJO 5 AÑOS (5Y)'!C27 -> 16744.433 | D8: ='FLUJO 5 AÑOS (5Y)'!D27 -> 43952.223 | E8: ='FLUJO 5 AÑOS (5Y)'!E27 -> 25735.627 | F8: ='FLUJO 5 AÑOS (5Y)'!F27 -> 2865.8228 | G8: =SUM(B8:F8) -> 138846.6
A9: TOTAL FEES ASESOR (dentro del fondo) | B9: =B7+B8 -> 49548.491 | C9: =C7+C8 -> 16744.433 | D9: =D7+D8 -> 43952.223 | E9: =E7+E8 -> 25735.627 | F9: =F7+F8 -> 2865.8228 | G9: =G7+G8 -> 138846.6
A11: II. CARRY WATERFALL (con tope 5.4% — Cl. 10.5)
A12: Concepto | B12: 2026 | C12: 2027 | D12: 2028 | E12: 2029 | F12: 2030 | G12: TOTAL
A13: EBITDA pre-carry | B13: ='FLUJO 5 AÑOS (5Y)'!B21-'FLUJO 5 AÑOS (5Y)'!B24-'FLUJO 5 AÑOS (5Y)'!B25-'FLUJO 5 AÑOS (5Y)'!B26-'FLUJO 5 AÑOS (5Y)'!B27-'FLUJO 5 AÑOS (5Y)'!B28-'FLUJO 5 AÑOS (5Y)'!B29-'FLUJO 5 AÑOS (5Y)'!B30-'FLUJO 5 AÑOS (5Y)'!B31 -> 240309.87 | C13: ='FLUJO 5 AÑOS (5Y)'!C21-'FLUJO 5 AÑOS (5Y)'!C24-'FLUJO 5 AÑOS (5Y)'!C25-'FLUJO 5 AÑOS (5Y)'!C26-'FLUJO 5 AÑOS (5Y)'!C27-'FLUJO 5 AÑOS (5Y)'!C28-'FLUJO 5 AÑOS (5Y)'!C29-'FLUJO 5 AÑOS (5Y)'!C30-'FLUJO 5 AÑOS (5Y)'!C31 -> 312453.04 | D13: ='FLUJO 5 AÑOS (5Y)'!D21-'FLUJO 5 AÑOS (5Y)'!D24-'FLUJO 5 AÑOS (5Y)'!D25-'FLUJO 5 AÑOS (5Y)'!D26-'FLUJO 5 AÑOS (5Y)'!D27-'FLUJO 5 AÑOS (5Y)'!D28-'FLUJO 5 AÑOS (5Y)'!D29-'FLUJO 5 AÑOS (5Y)'!D30-'FLUJO 5 AÑOS (5Y)'!D31 -> 454231.18 | E13: ='FLUJO 5 AÑOS (5Y)'!E21-'FLUJO 5 AÑOS (5Y)'!E24-'FLUJO 5 AÑOS (5Y)'!E25-'FLUJO 5 AÑOS (5Y)'!E26-'FLUJO 5 AÑOS (5Y)'!E27-'FLUJO 5 AÑOS (5Y)'!E28-'FLUJO 5 AÑOS (5Y)'!E29-'FLUJO 5 AÑOS (5Y)'!E30-'FLUJO 5 AÑOS (5Y)'!E31 -> 445930.31 | F13: ='FLUJO 5 AÑOS (5Y)'!F21-'FLUJO 5 AÑOS (5Y)'!F24-'FLUJO 5 AÑOS (5Y)'!F25-'FLUJO 5 AÑOS (5Y)'!F26-'FLUJO 5 AÑOS (5Y)'!F27-'FLUJO 5 AÑOS (5Y)'!F28-'FLUJO 5 AÑOS (5Y)'!F29-'FLUJO 5 AÑOS (5Y)'!F30-'FLUJO 5 AÑOS (5Y)'!F31 -> 308769.7 | G13: =SUM(B13:F13) -> 1761694.1
A14: Carry Devengado del Período | B14: =MAX(0,B13-'FLUJO 5 AÑOS (5Y)'!B47*SUPUESTOS!$B$34)*SUPUESTOS!$B$33 -> 6030.9873 | C14: =MAX(0,C13-'FLUJO 5 AÑOS (5Y)'!C47*SUPUESTOS!$B$34)*SUPUESTOS!$B$33 -> 11803.445 | D14: =MAX(0,D13-'FLUJO 5 AÑOS (5Y)'!D47*SUPUESTOS!$B$34)*SUPUESTOS!$B$33 -> 25273.052 | E14: =MAX(0,E13-'FLUJO 5 AÑOS (5Y)'!E47*SUPUESTOS!$B$34)*SUPUESTOS!$B$33 -> 22926.582 | F14: =MAX(0,F13-'FLUJO 5 AÑOS (5Y)'!F47*SUPUESTOS!$B$34)*SUPUESTOS!$B$33 -> 7834.9265 | G14: =SUM(B14:F14) -> 73868.993
A15: Carry Diferido Acum. (entrada) | B15: 0 | C15: =B19 -> 6030.9873 | D15: =C19 -> 17834.432 | E15: =D19 -> 43107.484 | F15: =E19 -> 66034.066
A16: Total Carry Pendiente (devengado + diferido) | B16: =B14+B15 -> 6030.9873 | C16: =C14+C15 -> 17834.432 | D16: =D14+D15 -> 43107.484 | E16: =E14+E15 -> 66034.066 | F16: =F14+F15 -> 73868.993 | G16: =SUM(B14:F14)+B15 -> 73868.993
A17: Espacio Disponible (5.4%*PN − costos cubiertos por tope) | B17: =MAX(0, SUPUESTOS!$B$35*'FLUJO 5 AÑOS (5Y)'!B47-('FLUJO 5 AÑOS (5Y)'!B24+'FLUJO 5 AÑOS (5Y)'!B25+'FLUJO 5 AÑOS (5Y)'!B26+'FLUJO 5 AÑOS (5Y)'!B27+'FLUJO 5 AÑOS (5Y)'!B28)) -> 0 | C17: =MAX(0, SUPUESTOS!$B$35*'FLUJO 5 AÑOS (5Y)'!C47-('FLUJO 5 AÑOS (5Y)'!C24+'FLUJO 5 AÑOS (5Y)'!C25+'FLUJO 5 AÑOS (5Y)'!C26+'FLUJO 5 AÑOS (5Y)'!C27+'FLUJO 5 AÑOS (5Y)'!C28)) -> 41748.581 | D17: =MAX(0, SUPUESTOS!$B$35*'FLUJO 5 AÑOS (5Y)'!D47-('FLUJO 5 AÑOS (5Y)'!D24+'FLUJO 5 AÑOS (5Y)'!D25+'FLUJO 5 AÑOS (5Y)'!D26+'FLUJO 5 AÑOS (5Y)'!D27+'FLUJO 5 AÑOS (5Y)'!D28)) -> 19498.239 | E17: =MAX(0, SUPUESTOS!$B$35*'FLUJO 5 AÑOS (5Y)'!E47-('FLUJO 5 AÑOS (5Y)'!E24+'FLUJO 5 AÑOS (5Y)'!E25+'FLUJO 5 AÑOS (5Y)'!E26+'FLUJO 5 AÑOS (5Y)'!E27+'FLUJO 5 AÑOS (5Y)'!E28)) -> 48329.516 | F17: =MAX(0, SUPUESTOS!$B$35*'FLUJO 5 AÑOS (5Y)'!F47-('FLUJO 5 AÑOS (5Y)'!F24+'FLUJO 5 AÑOS (5Y)'!F25+'FLUJO 5 AÑOS (5Y)'!F26+'FLUJO 5 AÑOS (5Y)'!F27+'FLUJO 5 AÑOS (5Y)'!F28)) -> 80828.485 | G17: =SUM(B17:F17) -> 190404.82
A18: Carry COBRADO (limitado por tope) | B18: 0 | C18: 0 | D18: 0 | E18: 0 | F18: =MIN(F16,F17) -> 73868.993 | G18: =SUM(B18:F18) -> 73868.993
A19: Carry Diferido Acum. (salida → pasa al año sig.) | B19: =B16-B18 -> 6030.9873 | C19: =C16-C18 -> 17834.432 | D19: =D16-D18 -> 43107.484 | E19: =E16-E18 -> 66034.066 | F19: =F16-F18 -> 0 | G19: =G16-G18 -> 0
A20: Nota: excluidos del tope 5.4%: comisiones colocador (row29), IVA upfront (row30), intereses deuda (row31)
A21: III. UPFRONT FEE EXTRACTION (pre-fondo)
A22: Concepto | B22: 2026 | C22: 2027 | D22: 2028 | E22: 2029 | F22: 2030 | G22: TOTAL
A23: Volumen Total Originado | B23: ='FLUJO 5 AÑOS (5Y)'!B10 -> 3963879.3 | C23: ='FLUJO 5 AÑOS (5Y)'!C10 -> 1339554.7 | D23: ='FLUJO 5 AÑOS (5Y)'!D10 -> 3516177.8 | E23: ='FLUJO 5 AÑOS (5Y)'!E10 -> 2058850.2 | F23: ='FLUJO 5 AÑOS (5Y)'!F10 -> 229265.82 | G23: =SUM(B23:F23) -> 11107728
A24: Upfront Total (5% del otorgado neto) | B24: =(B23/(1+SUPUESTOS!$B$73))*SUPUESTOS!$B$73 -> 188756.16 | C24: =(C23/(1+SUPUESTOS!$B$73))*SUPUESTOS!$B$73 -> 63788.317 | D24: =(D23/(1+SUPUESTOS!$B$73))*SUPUESTOS!$B$73 -> 167437.04 | E24: =(E23/(1+SUPUESTOS!$B$73))*SUPUESTOS!$B$73 -> 98040.484 | F24: =(F23/(1+SUPUESTOS!$B$73))*SUPUESTOS!$B$73 -> 10917.42 | G24: =SUM(B24:F24) -> 528939.42
A25: Porción al Fondo (4%) | B25: =(B23/(1+SUPUESTOS!$B$73))*SUPUESTOS!$B$74 -> 188756.16 | C25: =(C23/(1+SUPUESTOS!$B$73))*SUPUESTOS!$B$74 -> 63788.317 | D25: =(D23/(1+SUPUESTOS!$B$73))*SUPUESTOS!$B$74 -> 167437.04 | E25: =(E23/(1+SUPUESTOS!$B$73))*SUPUESTOS!$B$74 -> 98040.484 | F25: =(F23/(1+SUPUESTOS!$B$73))*SUPUESTOS!$B$74 -> 10917.42 | G25: =SUM(B25:F25) -> 528939.42
A26: Extracción Asesor Pre-Fondo (1%) | B26: =(B23/(1+SUPUESTOS!$B$73))*SUPUESTOS!$B$75 -> 0 | C26: =(C23/(1+SUPUESTOS!$B$73))*SUPUESTOS!$B$75 -> 0 | D26: =(D23/(1+SUPUESTOS!$B$73))*SUPUESTOS!$B$75 -> 0 | E26: =(E23/(1+SUPUESTOS!$B$73))*SUPUESTOS!$B$75 -> 0 | F26: =(F23/(1+SUPUESTOS!$B$73))*SUPUESTOS!$B$75 -> 0 | G26: =SUM(B26:F26) -> 0
A27: IVA sobre Extracción (21%) | B27: =B26*SUPUESTOS!$B$76 -> 0 | C27: =C26*SUPUESTOS!$B$76 -> 0 | D27: =D26*SUPUESTOS!$B$76 -> 0 | E27: =E26*SUPUESTOS!$B$76 -> 0 | F27: =F26*SUPUESTOS!$B$76 -> 0 | G27: =SUM(B27:F27) -> 0
A28: Neto Extracción (sin IVA) | B28: =B26 -> 0 | C28: =C26 -> 0 | D28: =D26 -> 0 | E28: =E26 -> 0 | F28: =F26 -> 0 | G28: =G26 -> 0
A29: Fee por Retiros de Liquidez (5% default) | B29: ='FLUJO 5 AÑOS (5Y)'!B81 -> 0 | C29: ='FLUJO 5 AÑOS (5Y)'!C81 -> 0 | D29: ='FLUJO 5 AÑOS (5Y)'!D81 -> 0 | E29: ='FLUJO 5 AÑOS (5Y)'!E81 -> 0 | F29: ='FLUJO 5 AÑOS (5Y)'!F81 -> 0 | G29: =SUM(B29:F29) -> 0
A30: TOTAL A COBRAR ASESOR TCMC (año por año) | B30: =B9+B18+B28+B29 -> 49548.491 | C30: =C9+C18+C28+C29+B32 -> 39992.925 | D30: =D9+D18+D28+D29+C32 -> 43952.223 | E30: =E9+E18+E28+E29+D32 -> 25735.627 | F30: =F9+F18+F28+F29+E32 -> 76734.816 | G30: =SUM(B30:F30) -> 235964.08
A31: TOTAL ACUMULADO (sumador) | B31: =B30 -> 49548.491 | C31: =B31+C30 -> 89541.416 | D31: =C31+D30 -> 133493.64 | E31: =D31+E30 -> 159229.27 | F31: =E31+F30 -> 235964.08
A32: SPONSOR (exceso >5.4% PN → pago fuera del fondo) | B32: =MAX(0, ('FLUJO 5 AÑOS (5Y)'!B24+'FLUJO 5 AÑOS (5Y)'!B25+'FLUJO 5 AÑOS (5Y)'!B26+'FLUJO 5 AÑOS (5Y)'!B27+'FLUJO 5 AÑOS (5Y)'!B28) - SUPUESTOS!$B$35*'FLUJO 5 AÑOS (5Y)'!B47) -> 23248.491 | C32: =MAX(0, ('FLUJO 5 AÑOS (5Y)'!C24+'FLUJO 5 AÑOS (5Y)'!C25+'FLUJO 5 AÑOS (5Y)'!C26+'FLUJO 5 AÑOS (5Y)'!C27+'FLUJO 5 AÑOS (5Y)'!C28) - SUPUESTOS!$B$35*'FLUJO 5 AÑOS (5Y)'!C47) -> 0 | D32: =MAX(0, ('FLUJO 5 AÑOS (5Y)'!D24+'FLUJO 5 AÑOS (5Y)'!D25+'FLUJO 5 AÑOS (5Y)'!D26+'FLUJO 5 AÑOS (5Y)'!D27+'FLUJO 5 AÑOS (5Y)'!D28) - SUPUESTOS!$B$35*'FLUJO 5 AÑOS (5Y)'!D47) -> 0 | E32: =MAX(0, ('FLUJO 5 AÑOS (5Y)'!E24+'FLUJO 5 AÑOS (5Y)'!E25+'FLUJO 5 AÑOS (5Y)'!E26+'FLUJO 5 AÑOS (5Y)'!E27+'FLUJO 5 AÑOS (5Y)'!E28) - SUPUESTOS!$B$35*'FLUJO 5 AÑOS (5Y)'!E47) -> 0 | F32: =MAX(0, ('FLUJO 5 AÑOS (5Y)'!F24+'FLUJO 5 AÑOS (5Y)'!F25+'FLUJO 5 AÑOS (5Y)'!F26+'FLUJO 5 AÑOS (5Y)'!F27+'FLUJO 5 AÑOS (5Y)'!F28) - SUPUESTOS!$B$35*'FLUJO 5 AÑOS (5Y)'!F47) -> 0 | G32: =SUM(B32:F32) -> 23248.491 | I32: Se cobra el año siguiente si hay lugar
A33: IV. RESUMEN TOTAL ASESOR — ESCENARIOS
A35: Escenario | B35: Total 5Y (USD) | C35: Promedio Anual
A36: A. Solo Fee por Crédito (1%/0.7%) | B36: =G8 -> 138846.6 | C36: =B36/5 -> 27769.319
A37: B. Fee Crédito + Carry | B37: =G8+G18 -> 212715.59 | C37: =B37/5 -> 42543.118
A38: C. Full (Fee Crédito + Carry + Extracción 1%) | B38: =G8+G18+G26 -> 212715.59 | C38: =B38/5 -> 42543.118
A39: D. Full + Fee Retiros Liquidez | B39: =G8+G18+G26+G29 -> 212715.59 | C39: =B39/5 -> 42543.118
A41: V. MÉTRICAS CLAVE
A42: TIR Inversor (post all fees) | B42: ='FLUJO 5 AÑOS (5Y)'!B65 -> 0.088919693
A43: MOIC | B43: ='FLUJO 5 AÑOS (5Y)'!B66 -> 1.3682255
A44: Total EBITDA Acumulado (6Y) | B44: =G13 -> 1761694.1
...

Sheet FLUJO 11 AÑOS
A1: FLUJO DEL FONDO — MODELO TCMC 11 AÑOS (Cono Sur / Capital Token Group, con captaciones)
A3: AÑO | B3: 2026 | C3: 2027 | D3: 2028 | E3: 2029 | F3: 2030 | G3: 2031 | H3: 2032 | I3: 2033 | J3: 2034 | K3: 2035 | L3: 2036 | M3: TOTAL
A4: A. CAPITAL Y ORIGINACIÓN
A5: Cartera Total Desplegada Inicio | B5: =B44*(1-SUPUESTOS!$B$36-SUPUESTOS!$B$37)+B14 -> 2947500 | C5: =C44+C14 -> 8276858.9 | D5: =D44+D14 -> 13582179 | E5: =E44+E14 -> 19097054 | F5: =F44+F14 -> 27830408 | G5: =G44+G14 -> 36929753 | H5: =H44+H14 -> 46390089 | I5: =I44+I14 -> 56225245 | J5: =J44+J14 -> 58450061 | ... L5: =L44+L14 -> 63057631
A6: Capital Liberado (Amortización) | B6: =B5*SUPUESTOS!$B$22 -> 1016379.3 | C6: =C5*SUPUESTOS!$B$22 -> 2854089.3 | D6: =D5*SUPUESTOS!$B$22 -> 4683509.9 | E6: =E5*SUPUESTOS!$B$22 -> 6585191 | F6: =F5*SUPUESTOS!$B$22 -> 9596692.3 | G6: =G5*SUPUESTOS!$B$22 -> 12734398 | H6: =H5*SUPUESTOS!$B$22 -> 15996582 | I6: =I5*SUPUESTOS!$B$22 -> 19388016 | ... L6: =L5*SUPUESTOS!$B$22 -> 21744011
A7: ¿Año de Originación Activa? | B7: 1 | C7: 1 | D7: 1 | E7: 1 | F7: 1 | G7: 1 | H7: 1 | I7: 1 | J7: 1 | K7: 1 | L7: 0
A8: Nuevos Créditos (re-originación) | B8: =IF(B7=1,B6*SUPUESTOS!$B$23,0) -> 1016379.3 | C8: =IF(C7=1,C6*SUPUESTOS!$B$23,0) -> 2854089.3 | D8: =IF(D7=1,D6*SUPUESTOS!$B$23,0) -> 4683509.9 | E8: =IF(E7=1,E6*SUPUESTOS!$B$23,0) -> 6585191 | F8: =IF(F7=1,F6*SUPUESTOS!$B$23,0) -> 9596692.3 | G8: =IF(G7=1,G6*SUPUESTOS!$B$23,0) -> 12734398 | H8: =IF(H7=1,H6*SUPUESTOS!$B$23,0) -> 15996582 | I8: =IF(I7=1,I6*SUPUESTOS!$B$23,0) -> 19388016 | ... L8: =IF(L7=1,L6*SUPUESTOS!$B$23,0) -> 0
A9: Stock de Capital Fin Año | B9: =B5-B6+B8 -> 2947500 | C9: =C5-C6+C8 -> 8276858.9 | D9: =D5-D6+D8 -> 13582179 | E9: =E5-E6+E8 -> 19097054 | F9: =F5-F6+F8 -> 27830408 | G9: =G5-G6+G8 -> 36929753 | H9: =H5-H6+H8 -> 46390089 | I9: =I5-I6+I8 -> 56225245 | ... L9: =L5-L6+L8 -> 41313620
A10: Volumen Total Originado | B10: =B5+B8 -> 3963879.3 | C10: =C8+MAX(0,C5-B9) -> 8183448.1 | D10: =D8+MAX(0,D5-C9) -> 9988829.8 | E10: =E8+MAX(0,E5-D9) -> 12100066 | F10: =F8+MAX(0,F5-E9) -> 18330046 | G10: =G8+MAX(0,G5-F9) -> 21833743 | H10: =H8+MAX(0,H5-G9) -> 25456918 | I10: =I8+MAX(0,I5-H9) -> 29223172 | J10: =J8+MAX(0,J5-I9) -> 22380009 | ... L10: =L8+MAX(0,L5-K9) -> 2347904.4 | M10: =SUM(B10:L10) -> 1.7700207e+08
B11: =ROUND(B10/SUPUESTOS!$B$8,0) -> 99 | C11: =ROUND(C10/SUPUESTOS!$B$8,0) -> 205 | D11: =ROUND(D10/SUPUESTOS!$B$8,0) -> 250 | E11: =ROUND(E10/SUPUESTOS!$B$8,0) -> 303 | F11: =ROUND(F10/SUPUESTOS!$B$8,0) -> 458 | G11: =ROUND(G10/SUPUESTOS!$B$8,0) -> 546 | H11: =ROUND(H10/SUPUESTOS!$B$8,0) -> 636 | I11: =ROUND(I10/SUPUESTOS!$B$8,0) -> 731 | ... L11: =ROUND(L10/SUPUESTOS!$B$8,0) -> 59
A12: B. APALANCAMIENTO (editar fila 13: 1=ajustar deuda al 50% PN, 0=mantener nivel anterior)
A13: ¿Ajustar deuda? (1=reset a 0.5x PN, 0=mantener) | B13: 0 | C13: 0 | D13: 0 | E13: 0 | F13: 0 | G13: 0 | H13: 0 | I13: 0 | J13: 0 | K13: 0 | L13: 0
A14: Deuda Senior (monto) | B14: =IF(B13=1, B44*SUPUESTOS!$B$52, 0) -> 0 | C14: =IF(C13=1, C44*SUPUESTOS!$B$52, B14) -> 0 | D14: =IF(D13=1, D44*SUPUESTOS!$B$52, C14) -> 0 | E14: =IF(E13=1, E44*SUPUESTOS!$B$52, D14) -> 0 | F14: =IF(F13=1, F44*SUPUESTOS!$B$52, E14) -> 0 | G14: =IF(G13=1, G44*SUPUESTOS!$B$52, F14) -> 0 | H14: =IF(H13=1, H44*SUPUESTOS!$B$52, G14) -> 0 | I14: =IF(I13=1, I44*SUPUESTOS!$B$52, H14) -> 0 | J14: =IF(J13=1, J44*SUPUESTOS!$B$52, I14) -> 0 | ... L14: =IF(L13=1, L44*SUPUESTOS!$B$52, K14) -> 0
A15: Capital Total Desplegado (Equity + Deuda) | B15: =B5 -> 2947500 | C15: =C5 -> 8276858.9 | D15: =D5 -> 13582179 | E15: =E5 -> 19097054 | F15: =F5 -> 27830408 | G15: =G5 -> 36929753 | H15: =H5 -> 46390089 | I15: =I5 -> 56225245 | ... L15: =L5 -> 63057631
A16: Leverage Ratio (Deuda / PN Inicio) | B16: =IF(B5>0,B14/B5,0) -> 0 | C16: =IF(C5>0,C14/C5,0) -> 0 | D16: =IF(D5>0,D14/D5,0) -> 0 | E16: =IF(E5>0,E14/E5,0) -> 0 | F16: =IF(F5>0,F14/F5,0) -> 0 | G16: =IF(G5>0,G14/G5,0) -> 0 | H16: =IF(H5>0,H14/H5,0) -> 0 | I16: =IF(I5>0,I14/I5,0) -> 0 | ... L16: =IF(L5>0,L14/L5,0) -> 0
A18: C. INGRESOS
A19: Interés Ganado (sobre capital total desplegado) | B19: =IF(B7=1,B5*SUPUESTOS!$B$24,B5*SUPUESTOS!$B$24/2) -> 365490 | C19: =IF(C7=1,C5*SUPUESTOS!$B$24,C5*SUPUESTOS!$B$24/2) -> 1026330.5 | D19: =IF(D7=1,D5*SUPUESTOS!$B$24,D5*SUPUESTOS!$B$24/2) -> 1684190.2 | E19: =IF(E7=1,E5*SUPUESTOS!$B$24,E5*SUPUESTOS!$B$24/2) -> 2368034.7 | F19: =IF(F7=1,F5*SUPUESTOS!$B$24,F5*SUPUESTOS!$B$24/2) -> 3450970.6 | G19: =IF(G7=1,G5*SUPUESTOS!$B$24,G5*SUPUESTOS!$B$24/2) -> 4579289.4 | H19: =IF(H7=1,H5*SUPUESTOS!$B$24,H5*SUPUESTOS!$B$24/2) -> 5752371 | I19: =IF(I7=1,I5*SUPUESTOS!$B$24,I5*SUPUESTOS!$B$24/2) -> 6971930.4 | ... L19: =IF(L7=1,L5*SUPUESTOS!$B$24,L5*SUPUESTOS!$B$24/2) -> 3909573.1 | M19: =SUM(B19:L19) -> 44883994
A20: Upfront Fee (% al Fondo) | B20: =(B10/(1+SUPUESTOS!$B$38))*SUPUESTOS!$B$38 -> 188756.16 | C20: =(C10/(1+SUPUESTOS!$B$38))*SUPUESTOS!$B$38 -> 389688.01 | D20: =(D10/(1+SUPUESTOS!$B$38))*SUPUESTOS!$B$38 -> 475658.56 | E20: =(E10/(1+SUPUESTOS!$B$38))*SUPUESTOS!$B$38 -> 576193.63 | F20: =(F10/(1+SUPUESTOS!$B$38))*SUPUESTOS!$B$38 -> 872859.34 | G20: =(G10/(1+SUPUESTOS!$B$38))*SUPUESTOS!$B$38 -> 1039702.1 | H20: =(H10/(1+SUPUESTOS!$B$38))*SUPUESTOS!$B$38 -> 1212234.2 | I20: =(I10/(1+SUPUESTOS!$B$38))*SUPUESTOS!$B$38 -> 1391579.6 | ... L20: =(L10/(1+SUPUESTOS!$B$38))*SUPUESTOS!$B$38 -> 111804.97 | M20: =SUM(B20:L20) -> 8428670
A21: TOTAL INGRESOS FONDO | B21: =B19+B20 -> 554246.16 | C21: =C19+C20 -> 1416018.5 | D21: =D19+D20 -> 2159848.7 | E21: =E19+E20 -> 2944228.3 | F21: =F19+F20 -> 4323829.9 | G21: =G19+G20 -> 5618991.5 | H21: =H19+H20 -> 6964605.2 | I21: =I19+I20 -> 8363510 | ... L21: =L19+L20 -> 4021378.1 | M21: =SUM(B21:L21) -> 53312664
A23: D. COSTOS DEL FONDO
A24: Honorarios Soc. Gerente (1.2%) | B24: =B44*SUPUESTOS!$B$28 -> 36000 | C24: =C44*SUPUESTOS!$B$28 -> 99322.306 | D24: =D44*SUPUESTOS!$B$28 -> 162986.15 | E24: =E44*SUPUESTOS!$B$28 -> 229164.65 | F24: =F44*SUPUESTOS!$B$28 -> 333964.89 | G24: =G44*SUPUESTOS!$B$28 -> 443157.04 | H24: =H44*SUPUESTOS!$B$28 -> 556681.07 | I24: =I44*SUPUESTOS!$B$28 -> 674702.94 | ... L24: =L44*SUPUESTOS!$B$28 -> 756691.58 | M24: =SUM(B24:L24) -> 4722588.1
A25: Honorarios Soc. Depositaria (0.2%, mín $21,600/yr + $10K inicial Y1) | B25: =MAX(B44*SUPUESTOS!$B$29,SUPUESTOS!$B$40)+10000 -> 31600 | C25: =MAX(C44*SUPUESTOS!$B$29,SUPUESTOS!$B$40) -> 21600 | D25: =MAX(D44*SUPUESTOS!$B$29,SUPUESTOS!$B$40) -> 27164.358 | E25: =MAX(E44*SUPUESTOS!$B$29,SUPUESTOS!$B$40) -> 38194.108 | F25: =MAX(F44*SUPUESTOS!$B$29,SUPUESTOS!$B$40) -> 55660.816 | G25: =MAX(G44*SUPUESTOS!$B$29,SUPUESTOS!$B$40) -> 73859.507 | H25: =MAX(H44*SUPUESTOS!$B$29,SUPUESTOS!$B$40) -> 92780.178 | I25: =MAX(I44*SUPUESTOS!$B$29,SUPUESTOS!$B$40) -> 112450.49 | J25: =MAX(J44*SUPUESTOS!$B$29,SUPUESTOS!$B$40) -> 116900.12 | ... L25: =MAX(L44*SUPUESTOS!$B$29,SUPUESTOS!$B$40) -> 126115.26 | M25: =SUM(B25:L25) -> 817744.29
A26: Honorarios Asesor Inversión (0% PN — eliminado) | B26: =B44*SUPUESTOS!$B$30 -> 0 | C26: =C44*SUPUESTOS!$B$30 -> 0 | D26: =D44*SUPUESTOS!$B$30 -> 0 | E26: =E44*SUPUESTOS!$B$30 -> 0 | F26: =F44*SUPUESTOS!$B$30 -> 0 | G26: =G44*SUPUESTOS!$B$30 -> 0 | H26: =H44*SUPUESTOS!$B$30 -> 0 | I26: =I44*SUPUESTOS!$B$30 -> 0 | ... L26: =L44*SUPUESTOS!$B$30 -> 0 | M26: =SUM(B26:L26) -> 0
A27: Fee Asesor (Originación + Adquisición) | B27: =B10*(SUPUESTOS!$B$31) -> 49548.491 | C27: =C10*(SUPUESTOS!$B$31) -> 102293.1 | D27: =D10*(SUPUESTOS!$B$31) -> 124860.37 | E27: =E10*(SUPUESTOS!$B$31) -> 151250.83 | F27: =F10*(SUPUESTOS!$B$31) -> 229125.58 | G27: =G10*(SUPUESTOS!$B$31) -> 272921.79 | H27: =H10*(SUPUESTOS!$B$31) -> 318211.47 | I27: =I10*(SUPUESTOS!$B$31) -> 365289.65 | ... L27: =L10*(SUPUESTOS!$B$31) -> 29348.805 | M27: =SUM(B27:L27) -> 2212525.9
A28: Costos Fijos Operativos | B28: =SUPUESTOS!$B$42+SUPUESTOS!$B$43+SUPUESTOS!$B$44+SUPUESTOS!$B$45+SUPUESTOS!$B$46+SUPUESTOS!$B$47+SUPUESTOS!$B$48 -> 68100 | C28: =SUPUESTOS!$B$42+SUPUESTOS!$B$43+SUPUESTOS!$B$45+SUPUESTOS!$B$46+SUPUESTOS!$B$47+SUPUESTOS!$B$48 -> 56000 | D28: =SUPUESTOS!$B$42+SUPUESTOS!$B$43+SUPUESTOS!$B$45+SUPUESTOS!$B$46+SUPUESTOS!$B$47+SUPUESTOS!$B$48 -> 56000 | E28: =SUPUESTOS!$B$42+SUPUESTOS!$B$43+SUPUESTOS!$B$45+SUPUESTOS!$B$46+SUPUESTOS!$B$47+SUPUESTOS!$B$48 -> 56000 | F28: =SUPUESTOS!$B$42+SUPUESTOS!$B$43+SUPUESTOS!$B$45+SUPUESTOS!$B$46+SUPUESTOS!$B$47+SUPUESTOS!$B$48 -> 56000 | G28: =SUPUESTOS!$B$42+SUPUESTOS!$B$43+SUPUESTOS!$B$45+SUPUESTOS!$B$46+SUPUESTOS!$B$47+SUPUESTOS!$B$48 -> 56000 | H28: =SUPUESTOS!$B$42+SUPUESTOS!$B$43+SUPUESTOS!$B$45+SUPUESTOS!$B$46+SUPUESTOS!$B$47+SUPUESTOS!$B$48 -> 56000 | I28: =SUPUESTOS!$B$42+SUPUESTOS!$B$43+SUPUESTOS!$B$45+SUPUESTOS!$B$46+SUPUESTOS!$B$47+SUPUESTOS!$B$48 -> 56000 | J28: =SUPUESTOS!$B$42+SUPUESTOS!$B$43+SUPUESTOS!$B$45+SUPUESTOS!$B$46+SUPUESTOS!$B$47+SUPUESTOS!$B$48 -> 56000 | ... L28: =SUPUESTOS!$B$42+SUPUESTOS!$B$43+SUPUESTOS!$B$45+SUPUESTOS!$B$46+SUPUESTOS!$B$47+SUPUESTOS!$B$48 -> 56000 | M28: =SUM(B28:L28) -> 628100
A29: Comisiones (Colocador+Org) sobre capital | B29: =(SUPUESTOS!$B$6+B42)*(SUPUESTOS!$B$36+SUPUESTOS!$B$37) -> 52500 | C29: =C42*(SUPUESTOS!$B$36+SUPUESTOS!$B$37) -> 87500 | D29: =D42*(SUPUESTOS!$B$36+SUPUESTOS!$B$37) -> 87500 | E29: =E42*(SUPUESTOS!$B$36+SUPUESTOS!$B$37) -> 87500 | F29: =F42*(SUPUESTOS!$B$36+SUPUESTOS!$B$37) -> 140000 | G29: =G42*(SUPUESTOS!$B$36+SUPUESTOS!$B$37) -> 140000 | H29: =H42*(SUPUESTOS!$B$36+SUPUESTOS!$B$37) -> 140000 | I29: =I42*(SUPUESTOS!$B$36+SUPUESTOS!$B$37) -> 140000 | J29: =J42*(SUPUESTOS!$B$36+SUPUESTOS!$B$37) -> 0 | ... L29: =L42*(SUPUESTOS!$B$36+SUPUESTOS!$B$37) -> 0 | M29: =SUM(B29:L29) -> 875000
A30: IVA sobre Upfront Fee (REVISAR: ¿lo paga el fondo o el tomador?) | B30: =B20*SUPUESTOS!$B$39 -> 39638.793 | C30: =C20*SUPUESTOS!$B$39 -> 81834.481 | D30: =D20*SUPUESTOS!$B$39 -> 99888.298 | E30: =E20*SUPUESTOS!$B$39 -> 121000.66 | F30: =F20*SUPUESTOS!$B$39 -> 183300.46 | G30: =G20*SUPUESTOS!$B$39 -> 218337.43 | H30: =H20*SUPUESTOS!$B$39 -> 254569.18 | I30: =I20*SUPUESTOS!$B$39 -> 292231.72 | ... L30: =L20*SUPUESTOS!$B$39 -> 23479.044 | M30: =SUM(B30:L30) -> 1770020.7
A31: Intereses Deuda Senior | B31: =B14*SUPUESTOS!$B$54 -> 0 | C31: =C14*SUPUESTOS!$B$54 -> 0 | D31: =D14*SUPUESTOS!$B$54 -> 0 | E31: =E14*SUPUESTOS!$B$54 -> 0 | F31: =F14*SUPUESTOS!$B$54 -> 0 | G31: =G14*SUPUESTOS!$B$54 -> 0 | H31: =H14*SUPUESTOS!$B$54 -> 0 | I31: =I14*SUPUESTOS!$B$54 -> 0 | ... L31: =L14*SUPUESTOS!$B$54 -> 0 | M31: =SUM(B31:L31) -> 0
A32: TOTAL COSTOS | B32: =B24+B25+B26+B27+B28+B29+B30+B31+B34 -> 277387.28 | C32: =C24+C25+C26+C27+C28+C29+C30+C31+C34 -> 448549.89 | D32: =D24+D25+D26+D27+D28+D29+D30+D31+D34 -> 558399.17 | E32: =E24+E25+E26+E27+E28+E29+E30+E31+E34 -> 683110.25 | F32: =F24+F25+F26+F27+F28+F29+F30+F31+F34 -> 998051.75 | G32: =G24+G25+G26+G27+G28+G29+G30+G31+G34 -> 1204275.8 | H32: =H24+H25+H26+H27+H28+H29+H30+H31+H34 -> 1418241.9 | I32: =I24+I25+I26+I27+I28+I29+I30+I31+I34 -> 1640674.8 | ... L32: =L24+L25+L26+L27+L28+L29+L30+L31+L34 -> 2934380.6 | M32: =SUM(B32:L32) -> 12968725
A33: Carry devengado del período | B33: ='RESULTADOS ASESOR TCMC'!B14 -> 9685.8873 | C33: ='RESULTADOS ASESOR TCMC'!C14 -> 47085.708 | D33: ='RESULTADOS ASESOR TCMC'!D14 -> 78651.883 | E33: ='RESULTADOS ASESOR TCMC'!E14 -> 111529.48 | F33: ='RESULTADOS ASESOR TCMC'!F14 -> 165595.37 | G33: ='RESULTADOS ASESOR TCMC'!G14 -> 219893.05 | H33: ='RESULTADOS ASESOR TCMC'!H14 -> 276295.8 | I33: ='RESULTADOS ASESOR TCMC'!I14 -> 334932.05 | ... M33: ='RESULTADOS ASESOR TCMC'!M14 -> 1942745.9
A34: Carry COBRADO (tope 5.4% Cl.10.5) | B34: ='RESULTADOS ASESOR TCMC'!B18 -> 0 | C34: ='RESULTADOS ASESOR TCMC'!C18 -> 0 | D34: 0 | E34: 0 | F34: 0 | G34: 0 | H34: 0 | I34: 0 | J34: 0 | K34: 0 | L34: ='RESULTADOS ASESOR TCMC'!L18 -> 1942745.9 | M34: ='RESULTADOS ASESOR TCMC'!M18 -> 1942745.9
A35: E. RESULTADO
A36: EBITDA Fondo (neto de carry) | B36: =B21-B32 -> 276858.87 | C36: =C21-C32 -> 967468.62 | D36: =D21-D32 -> 1601449.6 | E36: =E21-E32 -> 2261118.1 | F36: =F21-F32 -> 3325778.2 | G36: =G21-G32 -> 4414715.7 | H36: =H21-H32 -> 5546363.3 | I36: =I21-I32 -> 6722835.2 | ... L36: =L21-L32 -> 1086997.5 | M36: =SUM(B36:L36) -> 40343939
